Workbook
Name _: #REF!,#REF!,#REF!,#REF!
Name _: #REF!,#REF!,#REF!,#REF!
Name _: #REF!,#REF!,#REF!,#REF!
Name _: #REF!,#REF!,#REF!,#REF!
Name _: #REF!,#REF!,#REF!,#REF!
Name __: #REF!,#REF!,#REF!,#REF!
Name __: #REF!,#REF!,#REF!,#REF!
Name __: #REF!,#REF!,#REF!,#REF!
Name _1W_一: #REF!,#REF!,#REF!,#REF!
Name _1W_一: #REF!,#REF!,#REF!,#REF!
Name _1W_一: #REF!,#REF!,#REF!,#REF!
Name _1W_一: #REF!,#REF!,#REF!,#REF!
Name _1W_一: #REF!,#REF!,#REF!,#REF!
Name A: #REF!
Name A: #REF!
Name A: #REF!
Name A: #REF!
Name A: #REF!
Name Pa: #REF!
Name Pa: #REF!
Name Pa: #REF!
Name Pa: #REF!
Name Pa: #REF!
Name あ: [1]水蒸気圧!$M$2:$M$9,[1]水蒸気圧!$S$1:$S$3,[1]水蒸気圧!$I$22:$I$28,[1]水蒸気圧!$M$1
Name 一般入力: [1]水蒸気圧!$M$2:$M$9,[1]水蒸気圧!$S$1:$S$3,[1]水蒸気圧!$I$22:$I$28,[1]水蒸気圧!$M$1
Name 図案2: [2]水蒸気圧!$M$2:$M$9,[2]水蒸気圧!$S$1:$S$3,[2]水蒸気圧!$I$22:$I$28,[2]水蒸気圧!$M$1
Name 水蒸気圧表: #REF!
Name 水蒸気圧表: #REF!
Name 水蒸気圧表: 'Measurement Act'!$A$1:$C$204
Name 水蒸気圧表: #REF!
Name 水蒸気圧表: #REF!
Name 水蒸気圧表: #REF!
Name 測定者: #REF!
Name 測定者: #REF!
Name 測定者: #REF!
Name 測定者: #REF!
Name 測定者: #REF!
Name 計量法１: #REF!
Name 計量法１: #REF!
Name 計量法１: 'Measurement Act'!$E$1:$H$100
Name 計量法１: #REF!
Name 計量法１: #REF!
Name 計量法１: #REF!
Name 金属入力: [1]水蒸気圧!$T$102:$T$106,[1]水蒸気圧!$T$101

Sheet Flow rate
A2: MEASURING DATA SHEET (1) | X2: Customer | AN2: THAI BINH 1 THERMAL POWER PLANT
A3: Measuring date | AD3: Measuring condition
A4: Measuring position | AD4: Measuring person
V6: Calculated by | Z6: Checked by | AD6: PC Input | AH6: Collated by | BD6: Customer
B8: MOISTURE CONTENT IN FLUE GAS | AL8: Atmospheric pressure | AX8: Pa | BB8: kPa
B9: Measuring point | I9: Measuring time | P9: U - tube No. | V9: Gas meter | AO9: Mass of moisture | AV9: Moisture content
V10: Suction volume | AE10: Temp. | AI10: Pressure | AV10: Value | BC10: Average
V11: V | AE11: θm | AI11: Pm | AO11: m | AV11: Xw | BC11: Xw
V12: L | AE12: ℃ | AI12: kPa | AO12: g | AV12: vol% | BC12: vol%
BK13: =ROUND(VLOOKUP(AE13,'Measurement Act'!$A$4:$C$207,3),2) -> #N/A
BK14: =ROUND(VLOOKUP(AE14,'Measurement Act'!$A$4:$C$207,3),2) -> #N/A
AV15: =IF(V15="","",ROUND(AO15/18.02*2447/(AO15/18.02*24.47+V15*298.15/101.32*($BF$8+AI15-BK15)/(273.15+AE15)),1)) | BK15: =ROUND(VLOOKUP(AE15,'Measurement Act'!$A$4:$C$207,3),2) -> #N/A
B16: Equipment No. | I16: Gas meter | P16: D －013 － | AI16: Suction pump | AS16: DVM － 027 －
I17: Barometer | P17: DVM －016 －
B19: COMPOSITION AND DENSITY OF FLUE GAS | AR19: Density of wet flue gas in standard condition
B20: Measuring point | I20: Measuring time | P20: Gas composition
P21: CO2 | W21: O2 | AD21: CO | AK21: N2 | AR21: ρ0
P22: vol% | W22: vol% | AD22: vol% | AK22: vol% | AR22: kg/m3N
I25: Average
B26: Equipment No. | I26: Orsat apparatus | P26: DVM －045 －
B28: VELOCITY AND FLOW RATE OF FLUE GAS
B29: Measuring point | H29: Measuring time | P29: Dynamic pressure | X29: Temperature | AF29: Static pressure | AN29: Velocity | AV29: Gas density
P30: Pd | X30: θs | AF30: Ps | AN30: v | AV30: ρ
P31: Pa | X31: ℃ | AF31: kPa | AN31: m/s | AV31: kg/m3
H32: ① | L32: ② | P32: ① | T32: ② | X32: ① | AB32: ② | AF32: ① | AJ32: ② | AN32: ① | AR32: ② | AV32: ① | BC32: ②
AR33: =IF(T33="","",ROUND($S$50*SQRT(2*T33/$BC$33),1)) | BC33: =IFROUND($AR$25*298.15/101.32*($BF$8+AJ33)/(273.15+AB49),3) -> #NAME?
AR34: =IF(T34="","",ROUND($S$50*SQRT(2*T34/$BC$33),1)) | AV34: Gas flow rate
AR35: =IF(T35="","",ROUND($S$50*SQRT(2*T35/$BC$33),1)) | BA35: QA
AR36: =IF(T36="","",ROUND($S$50*SQRT(2*T36/$BC$33),1)) | BA36: m3/h
AR37: =IF(T37="","",ROUND($S$50*SQRT(2*T37/$BC$33),1)) | AV37: ①
AR38: =IF(T38="","",ROUND($S$50*SQRT(2*T38/$BC$33),1)) | AV38: ② | BA38: =ROUND($AR$49*$AX$50*3600,-3) -> #DIV/0!
AR39: =IF(T39="","",ROUND($S$50*SQRT(2*T39/$BC$33),1)) | AV39: Average | BA39: =AVERAGE(BA37:BI38) -> #DIV/0!
AR40: =IF(T40="","",ROUND($S$50*SQRT(2*T40/$BC$33),1)) | AV40: Wet | BA40: QN
AR41: =IF(T41="","",ROUND($S$50*SQRT(2*T41/$BC$33),1)) | BA41: m3N/h
AN42: =IF(P42="","",ROUND($S$50*SQRT(2*P42/$AV$33),1)) | AR42: =IF(T42="","",ROUND($S$50*SQRT(2*T42/$BC$33),1)) | AV42: ①
AN43: =IF(P43="","",ROUND($S$50*SQRT(2*P43/$AV$33),1)) | AR43: =IF(T43="","",ROUND($S$50*SQRT(2*T43/$BC$33),1)) | AV43: ② | BA43: =ROUND($AR$49*$AX$50*3600*298.15/101.32*($BF$8+$AJ$33)/(273.15+$AB$49),-3) -> #DIV/0!
AN44: =IF(P44="","",ROUND($S$50*SQRT(2*P44/$AV$33),1)) | AR44: =IF(T44="","",ROUND($S$50*SQRT(2*T44/$BC$33),1)) | AV44: Average | BA44: =AVERAGE(BA42:BI43) -> #DIV/0!
AN45: =IF(P45="","",ROUND($S$50*SQRT(2*P45/$AV$33),1)) | AR45: =IF(T45="","",ROUND($S$50*SQRT(2*T45/$BC$33),1)) | AV45: Dry | BA45: Q'N
AN46: =IF(P46="","",ROUND($S$50*SQRT(2*P46/$AV$33),1)) | AR46: =IF(T46="","",ROUND($S$50*SQRT(2*T46/$BC$33),1)) | BA46: m3N/h
AN47: =IF(P47="","",ROUND($S$50*SQRT(2*P47/$AV$33),1)) | AR47: =IF(T47="","",ROUND($S$50*SQRT(2*T47/$BC$33),1)) | AV47: ①
...

Sheet Flow rate A side
A2: MEASURING DATA SHEET (1) | X2: Customer | AN2: THAI BINH 1 THERMAL POWER PLANT
A3: Measuring date | AD3: Measuring condition
A4: Measuring position | AD4: Measuring person
V6: Calculated by | Z6: Checked by | AD6: PC Input | AH6: Collated by | BD6: Customer
B8: MOISTURE CONTENT IN FLUE GAS | AL8: Atmospheric pressure | AX8: Pa | BB8: kPa
B9: Measuring point | I9: Measuring time | P9: U - tube No. | V9: Gas meter | AO9: Mass of moisture | AV9: Moisture content
V10: Suction volume | AE10: Temp. | AI10: Pressure | AV10: Value | BC10: Average
V11: V | AE11: θm | AI11: Pm | AO11: m | AV11: Xw | BC11: Xw
V12: L | AE12: ℃ | AI12: kPa | AO12: g | AV12: vol% | BC12: vol%
BK13: =ROUND(VLOOKUP(AE13,'Measurement Act'!$A$4:$C$207,3),2) -> #N/A
BK14: =ROUND(VLOOKUP(AE14,'Measurement Act'!$A$4:$C$207,3),2) -> #N/A
BK15: =ROUND(VLOOKUP(AE15,'Measurement Act'!$A$4:$C$207,3),2) -> #N/A
B16: Equipment No. | I16: Gas meter | P16: D －013 － | AI16: Suction pump | AS16: DVM － 027 －
I17: Barometer | P17: DVM －016 －
B19: COMPOSITION AND DENSITY OF FLUE GAS | AR19: Density of wet flue gas in standard condition
B20: Measuring point | I20: Measuring time | P20: Gas composition
P21: CO2 | W21: O2 | AD21: CO | AK21: N2 | AR21: ρ0
P22: vol% | W22: vol% | AD22: vol% | AK22: vol% | AR22: kg/m3N
I25: Average
B26: Equipment No. | I26: Orsat apparatus | P26: DVM －045 －
B28: VELOCITY AND FLOW RATE OF FLUE GAS
B29: Measuring point | H29: Measuring time | P29: Dynamic pressure | X29: Temperature | AF29: Static pressure | AN29: Velocity | AV29: Gas density
P30: Pd | X30: θs | AF30: Ps | AN30: v | AV30: ρ
P31: Pa | X31: ℃ | AF31: kPa | AN31: m/s | AV31: kg/m3
H32: ① | L32: ② | P32: ① | T32: ② | X32: ① | AB32: ② | AF32: ① | AJ32: ② | AN32: ① | AR32: ② | AV32: ① | BC32: ②
AV34: Gas flow rate
BA35: QA
BA36: m3/h
AV37: ①
AV38: ②
AV39: Average
AV40: Wet | BA40: QN
BA41: m3N/h
AV42: ①
AV43: ②
AV44: Average
AV45: Dry | BA45: Q'N
BA46: m3N/h
AV47: ①
AV48: ②
...

Sheet Flow rate B side
A2: MEASURING DATA SHEET (1) | X2: Customer | AN2: THAI BINH 1 THERMAL POWER PLANT
A3: Measuring date | AD3: Measuring condition
A4: Measuring position | M4: B | AD4: Measuring person
V6: Calculated by | Z6: Checked by | AD6: PC Input | AH6: Collated by
B8: MOISTURE CONTENT IN FLUE GAS | AL8: Atmospheric pressure | AX8: Pa | BB8: kPa
B9: Measuring point | I9: Measuring time | P9: U - tube No. | V9: Gas meter | AO9: Mass of moisture | AV9: Moisture content
V10: Suction volume | AE10: Temp. | AI10: Pressure | AV10: Value | BC10: Average
V11: V | AE11: θm | AI11: Pm | AO11: m | AV11: Xw | BC11: Xw
V12: L | AE12: ℃ | AI12: kPa | AO12: g | AV12: vol% | BC12: vol%
V13: 10 | BC13: 8.8 | BK13: =ROUND(VLOOKUP(AE13,'Measurement Act'!$A$4:$C$207,3),2) -> #N/A
V14: 10 | BK14: =ROUND(VLOOKUP(AE14,'Measurement Act'!$A$4:$C$207,3),2) -> #N/A
AV15: =IF(V15="","",ROUND(AO15/18.02*2447/(AO15/18.02*24.47+V15*298.15/101.32*($BF$8+AI15-BK15)/(273.15+AE15)),1)) | BK15: =ROUND(VLOOKUP(AE15,'Measurement Act'!$A$4:$C$207,3),2) -> #N/A
B16: Equipment No. | I16: Gas meter | P16: DVM －013 － | AI16: Suction pump | AS16: DVM － 027 －
I17: Barometer | P17: DVM －016 －
B19: COMPOSITION AND DENSITY OF FLUE GAS | AR19: Density of wet flue gas in standard condition
B20: Measuring point | I20: Measuring time | P20: Gas composition
P21: CO2 | W21: O2 | AD21: CO | AK21: N2 | AR21: ρ0
P22: vol% | W22: vol% | AD22: vol% | AK22: vol% | AR22: kg/m3N
I25: Average | AR25: 1.2
B26: Equipment No. | I26: Orsat apparatus | P26: DVM －045 －
B28: VELOCITY AND FLOW RATE OF FLUE GAS
B29: Measuring point | H29: Measuring time | P29: Dynamic pressure | X29: Temperature | AF29: Static pressure | AN29: Velocity | AV29: Gas density
P30: Pd | X30: θs | AF30: Ps | AN30: v | AV30: ρ
P31: Pa | X31: ℃ | AF31: kPa | AN31: m/s | AV31: kg/m3
H32: ① | L32: ② | P32: ① | T32: ② | X32: ① | AB32: ② | AF32: ① | AJ32: ② | AN32: ① | AR32: ② | AV32: ① | BC32: ②
P33: 93 | X33: 128 | AF33: -2.7 | AR33: =IF(T33="","",ROUND($S$50*SQRT(2*T33/$BC$33),1)) | AV33: 0.883 | BC33: =IFROUND($AR$25*298.15/101.32*($BF$8+AJ33)/(273.15+AB49),3) -> #NAME?
P34: 126 | X34: 124 | AR34: =IF(T34="","",ROUND($S$50*SQRT(2*T34/$BC$33),1)) | AV34: Gas flow rate
P35: 93 | X35: 123 | AR35: =IF(T35="","",ROUND($S$50*SQRT(2*T35/$BC$33),1)) | BA35: QA
P36: 90 | X36: 129 | AR36: =IF(T36="","",ROUND($S$50*SQRT(2*T36/$BC$33),1)) | BA36: m3/h
P37: 90 | X37: 123 | AR37: =IF(T37="","",ROUND($S$50*SQRT(2*T37/$BC$33),1)) | AV37: ① | BA37: 719000
P38: 94 | X38: 119 | AR38: =IF(T38="","",ROUND($S$50*SQRT(2*T38/$BC$33),1)) | AV38: ② | BA38: =ROUND($AR$49*$AX$50*3600,-3) -> #DIV/0!
P39: 88 | X39: 131 | AR39: =IF(T39="","",ROUND($S$50*SQRT(2*T39/$BC$33),1)) | AV39: Average | BA39: =AVERAGE(BA37:BI38) -> #DIV/0!
P40: 116 | X40: 126 | AR40: =IF(T40="","",ROUND($S$50*SQRT(2*T40/$BC$33),1)) | AV40: Wet | BA40: QN
P41: 84 | X41: 119 | AR41: =IF(T41="","",ROUND($S$50*SQRT(2*T41/$BC$33),1)) | BA41: m3N/h
AN42: =IF(P42="","",ROUND($S$50*SQRT(2*P42/$AV$33),1)) | AR42: =IF(T42="","",ROUND($S$50*SQRT(2*T42/$BC$33),1)) | AV42: ① | BA42: 529000
AN43: =IF(P43="","",ROUND($S$50*SQRT(2*P43/$AV$33),1)) | AR43: =IF(T43="","",ROUND($S$50*SQRT(2*T43/$BC$33),1)) | AV43: ② | BA43: =ROUND($AR$49*$AX$50*3600*298.15/101.32*($BF$8+$AJ$33)/(273.15+$AB$49),-3) -> #DIV/0!
AN44: =IF(P44="","",ROUND($S$50*SQRT(2*P44/$AV$33),1)) | AR44: =IF(T44="","",ROUND($S$50*SQRT(2*T44/$BC$33),1)) | AV44: Average | BA44: =AVERAGE(BA42:BI43) -> #DIV/0!
AN45: =IF(P45="","",ROUND($S$50*SQRT(2*P45/$AV$33),1)) | AR45: =IF(T45="","",ROUND($S$50*SQRT(2*T45/$BC$33),1)) | AV45: Dry | BA45: Q'N
AN46: =IF(P46="","",ROUND($S$50*SQRT(2*P46/$AV$33),1)) | AR46: =IF(T46="","",ROUND($S$50*SQRT(2*T46/$BC$33),1)) | BA46: m3N/h
AN47: =IF(P47="","",ROUND($S$50*SQRT(2*P47/$AV$33),1)) | AR47: =IF(T47="","",ROUND($S$50*SQRT(2*T47/$BC$33),1)) | AV47: ① | BA47: 483000
...

Sheet Dust A side
A2: MEASURING DATA SHEET (2) | X2: Customer | AN2: THAI BINH 1 THERMAL POWER PLANT
A3: Measuring date | AD3: Measuring condition
A4: Measuring position | AD4: Measuring person
B6: DUST CONCENTRATION IN FLUE GAS | AK6: Calculated by | AP6: Checked by | AU6: PC Input | AZ6: Collated by | BE6: Customer
B7: Circular filter paper | P7: Cylindrical filter paper
B8: □ | D8: Form 1 | I8: □ | K8: Form 2 | P8: □ | R8: Form 1 | W8: □ | Y8: Form 2
B9: □ | D9: QMA | I9: □ | K9: PF-020 | P9: □ | R9: Whatman | W9: □ | Y9: 89 | AD9: Atmospheric pressure | AU9: Pa | AZ9: kPa
P10: □ | R10: 89S | AD10: Oxygen standard concentration | AU10: On | AZ10: %
B11: Measuring points | F11: Measuring time | J11: Number of points | M11: Diameter of nozzle | P11: Filter paper No. | T11: Suction duration | X11: Gas meter | AK11: Suction volume at standard condition | AP11: Mass of collected dust | AU11: Dust concentration | BE11: Oxygen concentration
X12: Suction volume | AC12: Temp. | AG12: Pressure | AU12: Measured value | AZ12: Conversion value
M13: d | T13: t | X13: V | AC13: θm | AG13: Pm | AK13: Vs | AP13: m | AU13: Cs | AZ13: C | BE13: Os
M14: mm | T14: min | X14: L | AC14: ℃ | AG14: kPa | AK14: m3N | AP14: g | AU14: g/m3N | AZ14: g/m3N | BE14: %
AZ15: =IF(AU15="","",AU15*(20.9-$BE$10)/(20.9-BE15)) | BK15: =ROUND(VLOOKUP(AC15,'Measurement Act'!$A$4:$C$207,3),2) -> #N/A
AZ16: =IF(AU16="","",AU16*(20.9-$BE$10)/(20.9-BE16)) | BK16: =ROUND(VLOOKUP(AC16,'Measurement Act'!$A$4:$C$207,3),2) -> #N/A
AZ17: =IF(AU17="","",AU17*(20.9-$BE$10)/(20.9-BE17)) | BK17: =ROUND(VLOOKUP(AC17,'Measurement Act'!$A$4:$C$207,3),2) -> #N/A
AK18: =IF(X18="","",ROUND(X18*298.15/101.32*($BE$9+AG18-BK18)/(273.15+AC18)/1000,3)) | AU18: =IF(AP18="","",AP18/AK18) | AZ18: =IF(AU18="","",AU18*(20.9-$BE$10)/(20.9-BE18)) | BK18: =ROUND(VLOOKUP(AC18,'Measurement Act'!$A$4:$C$207,3),2) -> #N/A
AK19: =IF(X19="","",ROUND(X19*298.15/101.32*($BE$9+AG19-BK19)/(273.15+AC19)/1000,3)) | AU19: =IF(AP19="","",AP19/AK19) | AZ19: =IF(AU19="","",AU19*(20.9-$BE$10)/(20.9-BE19)) | BK19: =ROUND(VLOOKUP(AC19,'Measurement Act'!$A$4:$C$207,3),2) -> #N/A
AP20: Average | AZ20: =AVERAGE(AZ15:BD19) -> #DIV/0! | BE20: =AVERAGE(BE15:BI19) -> #DIV/0!
B21: Equipment No. | I21: Gas meter | T21: D － 013 － | AK21: Suction pump | AU21: DVM － 027 －
I22: Orsat apparatus | T22: DVM － 045 －
AK24: Calculated by | AP24: Checked by | AU24: PC Input | AZ24: Collated by
B26: NITROGEN OXIDE CONCENTRATION IN FLUE GAS
B27: Measuring point | Z27: Oxygen standard concentration | AR27: On | AV27: %
B28: Measuring time | F28: NOx flask | AL28: Suction volume at standard condition | AP28: Ion concentration determined from the working curve | AX28: Nitrogen oxide concentration | BF28: Oxygen concentration
F29: No. | J29: Before sampling | V29: After sampling | AH29: Volume
J30: Absolute pressure | N30: Temp. | R30: Saturated vapor pressure | V30: Absolute pressure | Z30: Temp. | AD30: Saturated vapor pressure | AP30: NO3 | AT30: NO2 | AX30: Measured value | BB30: Conversion value
J31: Pi | N31: ti | R31: Pni | V31: Pf | Z31: tf | AD31: Pnf | AH31: V-20 | AL31: Vs | AP31: a | AT31: b | AX31: Cs | BB31: C | BF31: Os
J32: kPa | N32: ℃ | R32: kPa | V32: kPa | Z32: ℃ | AD32: kPa | AH32: mL | AL32: mL | AP32: mg/L | AT32: mg/L | AX32: ppm | BB32: ppm | BF32: %
AP36: Average
P37: Flask (After collecting)
P38: No. | S38: Atmospheric pressure | Z38: Residual pressure
S39: kPa | Z39: kPa
B44: Equipment No. | I44: Manometer | T44: DVM － － | AI44: Mighty pump | AS44: DVM－ 029 －
I45: Orsat apparatus | T45: DVM － 016 －
B49: Retention period | K49: 5 years | R49: Storage department | Z49: Technical room | AI49: TEC-G-QT-001-003 (01) | AR49: Revised (Enacted) date | BB49: 42095

Sheet Summary Temp. Pressure
B2: THAI BINH 1 THERMAL POWER PLANT | AH2: DATE:
AH3: CONDITION:
D7: ESP INLET FLUE GAS MEASUREMENT DATA SHEET
D8: FLOW RATE
W13: Gas direction
D30: Duct A | AC30: Duct B
D32: Average | AC32: Average
D33: Velocity | AC33: Velocity
D34: Temperature | T34: v: Velocity | AC34: Temperature
D35: Flow rate (wet) | T35: θ: Temperature | AC35: Flow rate (wet)
D36: Flow rate (dry) | AC36: Flow rate (dry)

Sheet Summary dust concecntration
B2: THAI BINH 1 THERMAL POWER PLANT | AH2: DATE: | AN2: 5-Dec-2017
AH3: CONDITION: | AN3: 300 MW
D7: ESP OUTLET FLUE GAS MEASUREMENT DATA SHEET
D8: DUST CONCENTRATION
W13: Gas direction
D30: Duct A | AC30: Duct B - T1
D32: Average | P32: g/m3N | AC32: Average | AO32: g/m3N
W41: Gas direction
D58: Duct B - T2 | AC58: Duct B - T3
D60: Average | P60: g/m3N | AC60: Average | AO60: g/m3N

Sheet Summary result
B2: THAI BINH 1 THERMAL POWER PLANT | AH2: DATE:
AH3: CONDITION:
D7: FLUE GAS MEASUREMENT DATA SHEET
D11: Item | P11: ESP INLET | AF11: ESP OUTLET
P12: DUCT A | X12: DUCT B | AF12: DUCT A | AN12: DUCT B
D13: Moisture | N13: %
D14: Gas temperature | N14: ℃
D15: Gas static pressure | N15: Pa
D16: Flow rate (wet) | N16: m3N/h
D17: Flow rate (dry) | N17: m3N/h
D18: Gas composition | J18: CO2 | N18: %
J19: O2 | N19: %
J20: CO | N20: %
J21: N2 | N21: %
D22: Dust concentration | N22: g/m3N

Sheet Measurement Act
A1: 0 | B1: 611.21 | C1: =B1/1000 -> 0.61121 | F1: Measuring objects | G1: Measuring method 1,JIS number | H1: Measuring method 2
E2: 0 | G2: blank as below
A3: 1 | B3: 657.08 | C3: =B3/1000 -> 0.65708 | E3: 1 | F3: Dust concentration | G3: JIS Z 8808(2013) | H3: (Circular filter paper)
E4: 2 | F4: Dust concentration | G4: JIS Z 8808(2013) | H4: (Cylinder filter paper)
A5: 2 | B5: 705.97 | C5: =B5/1000 -> 0.70597 | E5: 3 | F5: Sulfur oxides concentration | G5: JIS K 0103(2011)-7.1 | H5: Ion chromatography
E6: 4 | F6: Sulfur oxides concentration | G6: JIS K 0103(2011)-7.2 | H6: Precipitation titrimetry (arsenazoⅢmethod)
A7: 3 | B7: 758.06 | C7: =B7/1000 -> 0.75806 | E7: 5 | F7: Sulfur oxides concentration | G7: JIS K 0103(2011)-8 | H7: Automated measuring method
E8: 6 | F8: Sulfur oxides concentration | G8: JIS K 0103(2011)-Annex JA (normative) | H8: Turbidimetry (light scattering method)
A9: 4 | B9: 813.52 | C9: =B9/1000 -> 0.81352 | E9: 7 | F9: Nitrogen oxides concentration | G9: JIS K 0104(2011)-7.1 | H9: Zinc reduction naphthyethylenediamine absorptiometry (Zn-NEDA method)
E10: 8 | F10: Nitrogen oxides concentration | G10: JIS K 0104(2011)-7.3 | H10: Ion chromatography
A11: 5 | B11: 872.54 | C11: =B11/1000 -> 0.87254 | E11: 9 | F11: Nitrogen oxides concentration | G11: JIS K 0104(2011)-7.4 | H11: Phenol disulfonic acid absorptiometry (PDS method)
E12: 10 | F12: Nitrogen oxides concentration | G12: JIS K 0104(2011)-7.5 | H12: Saltzman absorptiometry
A13: 6 | B13: 935.31 | C13: =B13/1000 -> 0.93531 | E13: 11 | F13: Nitrogen oxides concentration | G13: JIS K 0104(2011)-8 | H13: Automated measuring method：Chemiluminescence method
E14: 12 | F14: Oxygen concentration | G14: JIS K 0301(1998)-5.1 | H14: Chemical analysis：Orsat
A15: 7 | B15: 1002 | C15: =B15/1000 -> 1.002 | E15: 13 | F15: Oxygen concentration | G15: JIS K 0301(1998)-6 | H15: Automated measuring method：Zirconia
E16: 14 | F16: Oxygen concentration | G16: JIS K 0301(1998)-6 | H16: Automated measuring method：Magnetic force
A17: 8 | B17: 1072.9 | C17: =B17/1000 -> 1.0729 | E17: 15 | F17: Ammonia concentration | G17: JIS K 0099(2004)-7.1 | H17: Indophenol blue absorption spectrophotometry
E18: 16 | F18: Ammonia concentration | G18: JIS K 0099(2004)-7.2 | H18: Gas chromatography
A19: 9 | B19: 1148.2 | C19: =B19/1000 -> 1.1482 | E19: 17 | F19: Fluorine concentration | G19: JIS K 0105(1998)-6.1 | H19: Lanthanum-Alizarin complexone absorptiometry
E20: 18 | F20: Hydrogen fluoride concentration | G20: JIS K 0105(1998)-6.1 | H20: Lanthanum-Alizarin complexone absorptiometry
A21: 10 | B21: 1228.1 | C21: =B21/1000 -> 1.2281 | E21: 19 | F21: Chlorine concentration | G21: JIS K 0106(2010)-7.1 | H21: ABTS
E22: 20 | F22: Chlorine concentration | G22: JIS K 0106(2010)-7.2 | H22: PCP
A23: 11 | B23: 1312.9 | C23: =B23/1000 -> 1.3129 | E23: 21 | F23: Chlorine concentration | G23: JIS K 0106(2010)-7.3 | H23: Ion chromatography
E24: 22 | F24: Chlorine concentration | G24: JIS K 0106(2010)-Annex A (normative) | H24: o－Tolidine colorimetry
A25: 12 | B25: 1402.8 | C25: =B25/1000 -> 1.4028 | E25: 23 | F25: Hydrogen chloride concentration | G25: JIS K 0107(2002)-7.1 | H25: Ion chromatography
E26: 24 | F26: Hydrogen chloride concentration | G26: JIS K 0107(2002)-7.2 | H26: Silver-nitrate titration method
A27: 13 | B27: 1498 | C27: =B27/1000 -> 1.498 | E27: 25 | F27: Hydrogen chloride concentration | G27: JIS K 0107(2002)-Annex D (normative) | H27: Mercury (Ⅱ) thiocyanate absorptiometry
E28: 26 | F28: Carbon monoxide concentration | G28: JIS K 0098(1998)-5 | H28: Gas chromatography
A29: 14 | B29: 1598.9 | C29: =B29/1000 -> 1.5989 | E29: 27 | F29: Carbon monoxide concentration | G29: JIS K 0098(1998)-6 | H29: Detection tube
E30: 28 | F30: Carbon monoxide concentration | G30: JIS K 0098(1998)-7 | H30: Infrared absorption spectrophotometry
A31: 15 | B31: 1705.7 | C31: =B31/1000 -> 1.7057 | E31: 29 | F31: Hydrogen sulfide concentration | G31: JIS K 0108(2010)-8 | H31: Gas chromatography
E32: 30 | F32: Hydrogen sulfide concentration | G32: JIS K 0108(2010)-9 | H32: Methylene blue absorptiometry
A33: 16 | B33: 1818.7 | C33: =B33/1000 -> 1.8187 | E33: 31 | F33: Hydrogen cyanide concentration | G33: JIS K 0109(1998)-6 | H33: Gas chromatography
E34: 32 | F34: Hydrogen cyanide concentration | G34: JIS K 0109(1998)-7 | H34: 4-Pyridinecarboxylate-pyrazolone absorptiometry
A35: 17 | B35: 1938.3 | C35: =B35/1000 -> 1.9383 | E35: 33 | F35: Cadmium concentration | G35: JIS K 0083(2006)-7.1 | H35: Flame atomic absorption spectrometry
E36: 34 | F36: Cadmium concentration | G36: JIS K 0083(2006)-7.3 | H36: ICP atomic emission spectroscopy
A37: 18 | B37: 2064.7 | C37: =B37/1000 -> 2.0647 | E37: 35 | F37: Cadmium concentration | G37: JIS K 0083(2006)-7.4 | H37: ICP mass spectrometry
E38: 36 | F38: Lead concentration | G38: JIS K 0083(2006)-8.1 | H38: Flame atomic absorption spectrometry
A39: 19 | B39: 2198.2 | C39: =B39/1000 -> 2.1982 | E39: 37 | F39: Lead concentration | G39: JIS K 0083(2006)-8.3 | H39: ICP atomic emission spectroscopy
E40: 38 | F40: Lead concentration | G40: JIS K 0083(2006)-8.4 | H40: ICP mass spectrometry
...
