Workbook
Name _: #REF!,#REF!,#REF!,#REF!
Name _: #REF!,#REF!,#REF!,#REF!
Name _: #REF!,#REF!,#REF!,#REF!
Name _: #REF!,#REF!,#REF!,#REF!
Name _: #REF!,#REF!,#REF!,#REF!
Name _: #REF!,#REF!,#REF!,#REF!
Name _: #REF!,#REF!,#REF!,#REF!
Name _: #REF!,#REF!,#REF!,#REF!
Name _: #REF!,#REF!,#REF!,#REF!
Name _: #REF!,#REF!,#REF!,#REF!
Name _: #REF!,#REF!,#REF!,#REF!
Name __: #REF!,#REF!,#REF!,#REF!
Name __: #REF!,#REF!,#REF!,#REF!
Name __: #REF!,#REF!,#REF!,#REF!
Name __: #REF!,#REF!,#REF!,#REF!
Name __: #REF!,#REF!,#REF!,#REF!
Name __: #REF!,#REF!,#REF!,#REF!
Name __: #REF!,#REF!,#REF!,#REF!
Name __: #REF!,#REF!,#REF!,#REF!
Name _1W_一: #REF!,#REF!,#REF!,#REF!
Name _1W_一: #REF!,#REF!,#REF!,#REF!
Name _1W_一: #REF!,#REF!,#REF!,#REF!
Name _1W_一: #REF!,#REF!,#REF!,#REF!
Name _1W_一: #REF!,#REF!,#REF!,#REF!
Name _1W_一: #REF!,#REF!,#REF!,#REF!
Name _1W_一: #REF!,#REF!,#REF!,#REF!
Name _1W_一: #REF!,#REF!,#REF!,#REF!
Name _1W_一: #REF!,#REF!,#REF!,#REF!
Name _1W_一: #REF!,#REF!,#REF!,#REF!
Name A: #REF!
Name A: #REF!
Name A: #REF!
Name A: #REF!
Name A: #REF!
Name A: #REF!
Name A: #REF!
Name A: #REF!
Name A: #REF!
Name A: #REF!
Name Pa: #REF!
Name Pa: #REF!
Name Pa: #REF!
Name Pa: #REF!
Name Pa: #REF!
Name Pa: #REF!
Name Pa: #REF!
Name Pa: #REF!
Name Pa: #REF!
Name Pa: #REF!
Name あ: [1]水蒸気圧!$M$2:$M$9,[1]水蒸気圧!$S$1:$S$3,[1]水蒸気圧!$I$22:$I$28,[1]水蒸気圧!$M$1
Name 一般入力: [1]水蒸気圧!$M$2:$M$9,[1]水蒸気圧!$S$1:$S$3,[1]水蒸気圧!$I$22:$I$28,[1]水蒸気圧!$M$1
Name 図案2: [2]水蒸気圧!$M$2:$M$9,[2]水蒸気圧!$S$1:$S$3,[2]水蒸気圧!$I$22:$I$28,[2]水蒸気圧!$M$1
Name 水蒸気圧表: #REF!
Name 水蒸気圧表: #REF!
Name 水蒸気圧表: #REF!
Name 水蒸気圧表: #REF!
Name 水蒸気圧表: #REF!
Name 水蒸気圧表: #REF!
Name 水蒸気圧表: 'Measurement Act'!$A$1:$C$204
Name 水蒸気圧表: #REF!

Sheet Input
B2: Job.No. | G2: Pitot tube coefficient | H2: C | I2: 1 | J2: Filter paper | K2: Cylindrical filter paper (Silica fiber filter type 1)
B3: Receipt number | G3: Determination of SOx | H3: Precipitation titrimetry f:factor of 5 mmol/L barium acetate solution | J3: Turbidimetry k value:the inclination of a calibration curve
B4: Atmospheric pressure | G4: Determination of NOx | H4: PDS method k value:the inclination of a calibration curve | J4: NEDA method k value:the inclination of a calibration curve
B5: Date of measurement | C5: 43074 | G5: Determination of HCl | H5: Silver nitrate titrimetry f:factor of 0.1 mol/L ammonium thiocyanate solution | J5: Mercury (Ⅱ) thiocyanate absorptiometry k value:the inclination of a calibration curve
B6: Certificate number
B7: Date of issue | C7: -
B8: Responsibility of measurement | C8: 1 | D8: Kazuyoshi Morimoto
B9: Responsibility of the site | D9: Kazuyoshi Morimoto
B10: Fuel consumption | C10: －
B17: Addressee of a report 1 | D17: THAI BINH 1 THERMAL POWER PLANT
B18: Addressee of a report 2 | D18: THAI BINH 1 THERMAL POWER PLANT
B19: Place of measurement | D19: ESP Inlet
B20: Facility | D20: ESP
B21: Title of measurement | D21: Measuring exhaust gas
B23: Place of measurement (The first column) | D23: My Loc Commune, Thai Thuy District, Thai Binh Province, Viet Nam
B24: (The second column)
B26: Facility name (Data sheet) | D26: ESP
B27: Site name of list | D27: THAI BINH 1 THERMAL POWER PLANT
B28: Type of facility | D28: ESP
B29: Measuring position | D29: ESP Inlet
B30: Sectional area of duct at measuring position m2 | D30: 13.5 | F30: 4.5m x 3.0m
B31: Height of stack (m)
B32: Sectional area of discharge port m2 | F32: 4.5m x 3.0m
B34: Date of installation
B35: Type of fuel | D35: Coal
B36: Scale of the facility
B38: Dust (g/m3N)
B39: Dust On(%) | D39: -
B40: SOx On (%) | D40: -
B41: NOx (ppm)
B42: NOx On(%) | D42: -
B43: HCl (mg/m3N)
B44: HCL On(%)
B46: Precauyions

Sheet Certificate
A4: CERTIFICATE OF MEASUREMENT RESULT
AE6: Certificate number | AN6: ： | AO6: =(Input!C6) -> 0
AE7: Receipt number | AN7: ： | AO7: =Input!C3 -> 0
AE8: Date of issue | AN8: ： | AO8: =Input!C7 -> -
C9: To: | E9: =Input!D18 -> THAI BINH 1 THERMAL POWER PLANT
AF10: Company | AL10: ： | AM10: CHUGAI TECHNOS VIETNAM CO., LTD
C11: Title of measurement: | N11: =Input!D21 -> Measuring exhaust gas | AF11: Address | AL11: ： | AM11: 66 Cao Trieu Phat, Hung Gia 4 Area, Tan Phong Ward, District 7, Ho Chi Minh City
N12: ="("&Input!D20&")" -> (ESP)
N13: =Input!D29 -> ESP Inlet | AF13: Telephone | AL13: ： | AM13: +84-28-541 09111
AF14: Fax | AL14: ： | AM14: +84-28-541 09222
AH16: VIMCERTS No. | AT16: ： | AU16: 086
AF18: Responsibility of measurement | AT18: ： | AU18: =Input!D8 -> Kazuyoshi Morimoto
AF20: Responsibility of the site | AT20: ： | AU20: =Input!D9 -> Kazuyoshi Morimoto
A22: We would like to certify measurement result which you requested as follows.
A24: Type of samples | L24: Flue gas | AC24: Type of facility | AN24: =Input!D28 -> ESP
A25: Place of measurement | L25: =Input!D23 -> My Loc Commune, Thai Thuy District, Thai Binh Province, Viet Nam
L26: -
A27: Date of measurement | L27: =Input!C5 -> 43074
A29: Measuring objects | L29: Unit | Q29: Result of measurement | AE29: LOQ | AL29: Methods for measurement | BG29: LOQ
A30: Dust concentration | L30: mg/Nm3 | Q30: Actual value | AL30: JIS Z 8808:2013 Cylindrical filter paper method | BF30: Vs = 0.141 | BG30: Dust (Circular filter paper) | BJ30: 1mg/Corrected volume | BM30: Unit:g/m3N
L31: mg/Nm3 | Q31: Conversion value | V31: =IF(Table!E20<AE31,AE31,Table!E20) -> - | AE31: - | BG31: Dust (Cyrinder filter paper) | BJ31: 5mg/Corrected volume | BM31: 3 digits after the decimal point
A32: Sulfur oxides concentration | L32: mg/Nm3 | Q32: Actual value | V32: =IF(Table!E21<AE32,AE32,Table!E21) -> 1.31 | AE32: =0.5*2.62 -> 1.31 | AL32: JIS K 0103:2011 -7.1 Ion chromatography method | BG32: HCl | BJ32: 0.6mg/m3N
L33: mg/Nm3 | Q33: Conversion value | V33: =IF(Table!E22<AE33,AE33,Table!E22) -> - | AE33: - | BJ33: 0.4ppm
A34: Sulfur dioxide concentration | L34: mg/Nm3 | Q34: Average value | V34: =IF(Table!E23<AE34,AE34,Table!E23) -> 26.2 | AE34: =10*2.62 -> 26.2 | AL34: JIS B 7981:2002 Non-dispersive infrared absorption method | BG34: SOx | BJ34: 0.5ppm
L35: mg/Nm3 | Q35: Conversion value | V35: =IF(Table!E24<AE35,AE35,Table!E24) -> - | AE35: - | BG35: NOx | BJ35: 4ppm
A36: Nitrogen oxides concentration | L36: mg/Nm3 | Q36: Actual value | V36: =IF(Table!E26<AE36,AE36,Table!E26) -> 7.52 | AE36: =4*1.88 -> 7.52 | AL36: JIS K 0104:2011 -7.3 Ion chromatography method
L37: mg/Nm3 | Q37: Conversion value | V37: =IF(Table!E27<AE37,AE37,Table!E27) -> - | AE37: -
A38: Nitrogen oxides concentration | L38: mg/Nm3 | Q38: Average value | V38: =IF(Table!E28<AE38,AE38,Table!E28) -> 9.4 | AE38: =5*1.88 -> 9.4 | AL38: JIS B 7982:2002 Chemiluminescence method
L39: mg/Nm3 | Q39: Conversion value | V39: =IF(Table!E29<AE39,AE39,Table!E29) -> - | AE39: -
A40: Carbon monoxide concentration | L40: mg/Nm3 | Q40: Average value | V40: =IF(Table!E30<AE40,AE40,Table!E30) -> 11.4 | AE40: =10*1.14 -> 11.4 | AL40: JIS B 7987:2006 Non-dispersive infrared absorption method
L41: mg/Nm3 | Q41: Conversion value | V41: =IF(Table!E31<AE41,AE41,Table!E31) -> - | AE41: -
A42: Carbon dioxide concentration | L42: vol% | Q42: Average value | V42: =Table!E32 -> 0 | AE42: - | AL42: JIS B 7986:2006 Non-dispersive infrared absorption method
A43: Oxygen concentration | L43: vol% | Q43: Average value | V43: =Table!E33 -> 0 | AE43: - | AL43: JIS B 7983:1994 Magnetic method
A44: Special note:
A45: (1) Units of volume are under standard condition (25℃,101.32kPa). (2) Refer to table of measurement result in next page relating to general items such as flow rate etc which show flue gas property.
A48: Address and name of company that carried out specific processes or some parts of measuring process.
A49: ―――
A52: The items not covered by Measurement Certification under Article 107 of Japanese Measurement Act.
A53: ――― | BG53: Conversion value is not covered by Measurement Certification under Article 107 of Japanese Measurement Act.
BE55: Please do not reprint a part of this certificate without permission.

Sheet Table
A2: TABLE OF MEASUREMENT RESULT
A5: Place of measurement | E5: =Input!D18 -> THAI BINH 1 THERMAL POWER PLANT
A6: Facility and measuring position | E6: =Input!D26&" "&Input!D29 -> ESP ESP Inlet
A7: Measuring date and Measuring time | E7: =Input!C5 -> 43074 | H7: 09:25～14:15
A8: Items | C8: Mark | D8: Unit | E8: Measurement result | H8: Emission standard
A9: Flow rate of wet flue gas | C9: Q | D9: m3/h | H9: -
A10: Flow rate of dry flue gas | C10: Q' | D10: m3/h | H10: -
A11: Flow velocity | C11: ｖ | D11: m/s | H11: -
A12: Temperature of flue gas | C12: θs | D12: ℃ | H12: -
A13: Static pressure of flue gas | C13: Ps | D13: Pa | H13: -
A14: Gas composition | C14: CO2 | D14: vol％ | H14: -
C15: O2 | D15: vol％ | H15: -
C16: CO | D16: vol％ | H16: -
C17: N2 | D17: vol％ | H17: -
A18: Moisture content | C18: Xw | D18: vol％ | H18: -
A19: Dust concentration | B19: Actual value | C19: Cs | D19: mg/Nm3 | H19: 200
B20: Conversion value | C20: C | D20: mg/Nm3
A21: Sulfur oxides concentration | B21: Actual value | C21: Cs | D21: mg/Nm3 | H21: 500
B22: Conversion value | C22: C | D22: mg/Nm3
A23: Sulfur dioxide concentration (Continuous measuring method) | B23: Average value | C23: Cs | D23: mg/Nm3
B24: Conversion value | C24: C | D24: mg/Nm3
A25: Sulfur oxides emission amount | C25: Cs | D25: mg/Nm3 | H25: 850
A26: Nitrogen oxides concentration | B26: Actual value | C26: Cs | D26: mg/Nm3 | H26: 850
B27: Conversion value | C27: C | D27: mg/Nm3
A28: Nitrogen oxides concentration (Continuous measuring method) | B28: Average value | C28: Cs | D28: mg/Nm3
B29: Conversion value | C29: C | D29: mg/Nm3
A30: Carbon monoxide concentration (Continuous measuring method) | B30: Average value | C30: Cs | D30: mg/Nm3 | H30: 1000
B31: Conversion value | C31: C | D31: mg/Nm3
A32: Carbon dioxide concentration (Continuous analysis method) | B32: Conversion value | C32: Cs | D32: vol% | H32: -
A33: Oxygen concentration (Continuous analysis method) | B33: Conversion value | C33: Os | D33: vol% | H33: -
A34: Type of facility： | C34: =Input!D28 -> ESP
A37: Note: The unit represent the standard condition (25℃,101.32kPa).

Sheet Fig
M2: DRAWING OF MEASURING POINT MEASURING LOCATION
B5: Diagram 1: Measuring position
B37: Diagram 2: Detailed measurement point drawing
R61: Gas direction
N78: Diameter of duct 2R (m): | AD78: 1.3
N80: Distance from center of duct to measuring point (m)
N82: r1( 0.500R)= | AD82: =ROUND(0.5*0.5*AD78,3) -> 0.325
N84: r2 (0.866R)= | AD84: =ROUND(0.866*0.5*AD78,3) -> 0.563
N86: Sectional area of duct at measuring position A (m) | AM86: =ROUND(AD78/2*AD78/2*PI(),2) -> 1.33

Sheet Drawing
B2: THAI BINH 1 THERMAL POWER PLANT
D10: DRAWING OF MEASURING POINT
D11: ESP
W16: Gas direction
D33: INLET - Duct A | AC33: INLET - Duct B
W42: Gas direction
D59: OUTLET - Duct A | AC59: OUTLET - Duct B

Sheet IN-A
A2: MEASURING DATA SHEET (1) | X2: Customer | AN2: THAI BINH 1 THERMAL POWER PLANT
A3: Measuring date | M3: 43143 | AD3: Measuring condition | AN3: 300MW
A4: Measuring position | M4: Unit 2 ESP Inlet Duct A | AD4: Measuring person | AN4: Dung, Tuyen
R6: Recorded by | V6: Calculated by | Z6: Checked by | AD6: PC Input | AH6: Collated by
B8: MOISTURE CONTENT IN FLUE GAS | AL8: Atmospheric pressure | AX8: Pa | BB8: kPa | BF8: 102.8
B9: Measuring point | I9: Measuring time | P9: U - tube No. | V9: Gas meter | AO9: Mass of moisture | AV9: Moisture content
V10: Suction volume | AE10: Temp. | AI10: Pressure | AV10: Value | BC10: Average
V11: V | AE11: θm | AI11: Pm | AO11: m | AV11: Xw | BC11: Xw
V12: L | AE12: ℃ | AI12: kPa | AO12: g | AV12: vol% | BC12: vol%
B13: C-2 | I13: 0.47916667 | P13: 1 | V13: 10 | AE13: 20 | AI13: 0 | AO13: 0.5304 | AV13: =IF(V13="","",ROUND(AO13/18.02*2447/(AO13/18.02*24.47+V13*298.15/101.32*($BF$8+AI13-BK13)/(273.15+AE13)),1)) -> 6.7 | BC13: =ROUND(AVERAGE(AV13:BB15),1) -> 6.8 | BK13: =ROUND(VLOOKUP(AE13,'Measurement Act'!$A$4:$C$207,3),2) -> 2.34
I14: 0.48472222 | P14: 2 | V14: 10 | AE14: 20 | AI14: 0 | AO14: 0.5379 | AV14: =IF(V14="","",ROUND(AO14/18.02*2447/(AO14/18.02*24.47+V14*298.15/101.32*($BF$8+AI14-BK14)/(273.15+AE14)),1)) -> 6.8 | BK14: =ROUND(VLOOKUP(AE14,'Measurement Act'!$A$4:$C$207,3),2) -> 2.34
AV15: =IF(V15="","",ROUND(AO15/18.02*2447/(AO15/18.02*24.47+V15*298.15/101.32*($BF$8+AI15-BK15)/(273.15+AE15)),1)) | BK15: =ROUND(VLOOKUP(AE15,'Measurement Act'!$A$4:$C$207,3),2) -> #N/A
B16: Equipment No. | I16: Gas meter | P16: D2 －013 －090 | AI16: Suction pump | AS16: DVM － 027 －002
I17: Barometer | P17: DVM －016 －004
B19: COMPOSITION AND DENSITY OF FLUE GAS | AR19: Density of wet flue gas in standard condition
B20: Measuring point | I20: Measuring time | P20: Gas composition
P21: CO2 | W21: O2 | AD21: CO | AK21: N2 | AR21: ρ0
P22: vol% | W22: vol% | AD22: vol% | AK22: vol% | AR22: kg/Nm3
B23: C-2 | I23: 0.47777778 | P23: 14 | W23: 5.6 | AD23: - | AK23: =100-P23-W23 -> 80.4 | AR23: =((44*P23+32*W23+28*AK23)*(1-$BC$13/100)+18.02*$BC$13)/2447 -> 1.2103722
I24: 0.49166667 | P24: 14 | W24: 5.6 | AD24: - | AK24: =100-P24-W24 -> 80.4 | AR24: =((44*P24+32*W24+28*AK24)*(1-$BC$13/100)+18.02*$BC$13)/2447 -> 1.2103722
I25: Average | P25: =ROUND(AVERAGE(P23:V24),1) -> 14 | W25: =ROUND(AVERAGE(W23:AC24),1) -> 5.6 | AD25: - | AK25: =100-P25-W25 -> 80.4 | AR25: =ROUND(AVERAGE(AR23:BI24),2) -> 1.21
B26: Equipment No. | I26: Orsat apparatus | P26: DVM －045 －001
B28: VELOCITY AND FLOW RATE OF FLUE GAS
B29: Measuring point | H29: Measuring time | P29: Dynamic pressure | X29: Temperature | AF29: Static pressure | AN29: Velocity | AV29: Gas density
P30: Pd | X30: θs | AF30: Ps | AN30: v | AV30: ρ
P31: Pa | X31: ℃ | AF31: kPa | AN31: m/s | AV31: kg/m3
H32: ① | L32: ② | P32: ① | T32: ② | X32: ① | AB32: ② | AF32: ① | AJ32: ② | AN32: ① | AR32: ② | AV32: ① | BC32: ②
B33: A-1 | H33: 0.45833333 | P33: 162 | X33: 132 | AF33: -2 | AN33: =IF(P33="","",ROUND($S$50*SQRT(2*P33/$AV$33),1)) -> 18.9 | AR33: =IF(T33="","",ROUND($S$50*SQRT(2*T33/$BC$33),1)) | AV33: =ROUND($AR$25*298.15/101.32*($BF$8+AF33)/(273.15+X49),3) -> 0.906 | BC33: =IFROUND($AR$25*298.15/101.32*($BF$8+AJ33)/(273.15+AB49),3) -> #NAME?
B34: A-2 | P34: 92 | X34: 132 | AN34: =IF(P34="","",ROUND($S$50*SQRT(2*P34/$AV$33),1)) -> 14.3 | AR34: =IF(T34="","",ROUND($S$50*SQRT(2*T34/$BC$33),1)) | AV34: Gas flow rate
B35: A-3 | P35: 156 | X35: 130 | AN35: =IF(P35="","",ROUND($S$50*SQRT(2*P35/$AV$33),1)) -> 18.6 | AR35: =IF(T35="","",ROUND($S$50*SQRT(2*T35/$BC$33),1)) | BA35: QA
B36: B-1 | P36: 66 | X36: 130 | AN36: =IF(P36="","",ROUND($S$50*SQRT(2*P36/$AV$33),1)) -> 12.1 | AR36: =IF(T36="","",ROUND($S$50*SQRT(2*T36/$BC$33),1)) | BA36: m3/h
B37: B-2 | P37: 194 | X37: 131 | AN37: =IF(P37="","",ROUND($S$50*SQRT(2*P37/$AV$33),1)) -> 20.7 | AR37: =IF(T37="","",ROUND($S$50*SQRT(2*T37/$BC$33),1)) | AV37: ① | BA37: =ROUND($AN$49*$AX$50*3600,-3) -> 739000
B38: B-3 | P38: 64 | X38: 127 | AN38: =IF(P38="","",ROUND($S$50*SQRT(2*P38/$AV$33),1)) -> 11.9 | AR38: =IF(T38="","",ROUND($S$50*SQRT(2*T38/$BC$33),1)) | AV38: ② | BA38: =ROUND($AR$49*$AX$50*3600,-3) -> #DIV/0!
B39: C-1 | P39: 68 | X39: 125 | AN39: =IF(P39="","",ROUND($S$50*SQRT(2*P39/$AV$33),1)) -> 12.3 | AR39: =IF(T39="","",ROUND($S$50*SQRT(2*T39/$BC$33),1)) | AV39: Average | BA39: =AVERAGE(BA37:BI38) -> #DIV/0!
B40: C-2 | P40: 82 | X40: 124 | AN40: =IF(P40="","",ROUND($S$50*SQRT(2*P40/$AV$33),1)) -> 13.5 | AR40: =IF(T40="","",ROUND($S$50*SQRT(2*T40/$BC$33),1)) | AV40: Wet | BA40: QN
B41: C-3 | P41: 78 | X41: 124 | AN41: =IF(P41="","",ROUND($S$50*SQRT(2*P41/$AV$33),1)) -> 13.1 | AR41: =IF(T41="","",ROUND($S$50*SQRT(2*T41/$BC$33),1)) | BA41: Nm3/h
B42: D-1 | P42: 52 | X42: 118 | AN42: =IF(P42="","",ROUND($S$50*SQRT(2*P42/$AV$33),1)) -> 10.7 | AR42: =IF(T42="","",ROUND($S$50*SQRT(2*T42/$BC$33),1)) | AV42: ① | BA42: =ROUND($AN$49*$AX$50*3600*298.15/101.32*($BF$8+$AF$33)/(273.15+$X$49),-3) -> 553000
B43: D-2 | P43: 166 | X43: 116 | AN43: =IF(P43="","",ROUND($S$50*SQRT(2*P43/$AV$33),1)) -> 19.1 | AR43: =IF(T43="","",ROUND($S$50*SQRT(2*T43/$BC$33),1)) | AV43: ② | BA43: =ROUND($AR$49*$AX$50*3600*298.15/101.32*($BF$8+$AJ$33)/(273.15+$AB$49),-3) -> #DIV/0!
B44: D-3 | P44: 62 | X44: 116 | AN44: =IF(P44="","",ROUND($S$50*SQRT(2*P44/$AV$33),1)) -> 11.7 | AR44: =IF(T44="","",ROUND($S$50*SQRT(2*T44/$BC$33),1)) | AV44: Average | BA44: =AVERAGE(BA42:BI43) -> #DIV/0!
B45: E-1 | P45: 134 | X45: 115 | AN45: =IF(P45="","",ROUND($S$50*SQRT(2*P45/$AV$33),1)) -> 17.2 | AR45: =IF(T45="","",ROUND($S$50*SQRT(2*T45/$BC$33),1)) | AV45: Dry | BA45: Q'N
...

Sheet IN-B
A2: MEASURING DATA SHEET (1) | X2: Customer | AN2: THAI BINH 1 THERMAL POWER PLANT
A3: Measuring date | M3: 43143 | AD3: Measuring condition | AN3: 300MW
A4: Measuring position | M4: Unit 2 ESP Inlet Duct B | AD4: Measuring person | AN4: Dung, Tuyen
R6: Recorded by | V6: Calculated by | Z6: Checked by | AD6: PC Input | AH6: Collated by
B8: MOISTURE CONTENT IN FLUE GAS | AL8: Atmospheric pressure | AX8: Pa | BB8: kPa | BF8: 102.8
B9: Measuring point | I9: Measuring time | P9: U - tube No. | V9: Gas meter | AO9: Mass of moisture | AV9: Moisture content
V10: Suction volume | AE10: Temp. | AI10: Pressure | AV10: Value | BC10: Average
V11: V | AE11: θm | AI11: Pm | AO11: m | AV11: Xw | BC11: Xw
V12: L | AE12: ℃ | AI12: kPa | AO12: g | AV12: vol% | BC12: vol%
B13: C-2 | I13: 0.51388889 | P13: 3 | V13: 10 | AE13: 20 | AI13: 0 | AO13: 0.5397 | AV13: =IF(V13="","",ROUND(AO13/18.02*2447/(AO13/18.02*24.47+V13*298.15/101.32*($BF$8+AI13-BK13)/(273.15+AE13)),1)) -> 6.8 | BC13: =ROUND(AVERAGE(AV13:BB15),1) -> 6.8 | BK13: =ROUND(VLOOKUP(AE13,'Measurement Act'!$A$4:$C$207,3),2) -> 2.34
I14: 0.51875 | P14: 7 | V14: 10 | AE14: 20 | AI14: 0 | AO14: 0.5355 | AV14: =IF(V14="","",ROUND(AO14/18.02*2447/(AO14/18.02*24.47+V14*298.15/101.32*($BF$8+AI14-BK14)/(273.15+AE14)),1)) -> 6.7 | BK14: =ROUND(VLOOKUP(AE14,'Measurement Act'!$A$4:$C$207,3),2) -> 2.34
AV15: =IF(V15="","",ROUND(AO15/18.02*2447/(AO15/18.02*24.47+V15*298.15/101.32*($BF$8+AI15-BK15)/(273.15+AE15)),1)) | BK15: =ROUND(VLOOKUP(AE15,'Measurement Act'!$A$4:$C$207,3),2) -> #N/A
B16: Equipment No. | I16: Gas meter | P16: D2 －013 －085 | AI16: Suction pump | AS16: DVM － 027 －007
I17: Barometer | P17: DVM －016 －004
B19: COMPOSITION AND DENSITY OF FLUE GAS | AR19: Density of wet flue gas in standard condition
B20: Measuring point | I20: Measuring time | P20: Gas composition
P21: CO2 | W21: O2 | AD21: CO | AK21: N2 | AR21: ρ0
P22: vol% | W22: vol% | AD22: vol% | AK22: vol% | AR22: kg/Nm3
B23: C-2 | I23: 0.51319444 | P23: 14.2 | W23: 5.4 | AD23: - | AK23: =100-P23-W23 -> 80.4 | AR23: =((44*P23+32*W23+28*AK23)*(1-$BC$13/100)+18.02*$BC$13)/2447 -> 1.2112863
I24: 0.52361111 | P24: 14.2 | W24: 5.4 | AD24: - | AK24: =100-P24-W24 -> 80.4 | AR24: =((44*P24+32*W24+28*AK24)*(1-$BC$13/100)+18.02*$BC$13)/2447 -> 1.2112863
I25: Average | P25: =ROUND(AVERAGE(P23:V24),1) -> 14.2 | W25: =ROUND(AVERAGE(W23:AC24),1) -> 5.4 | AD25: - | AK25: =100-P25-W25 -> 80.4 | AR25: =ROUND(AVERAGE(AR23:BI24),2) -> 1.21
B26: Equipment No. | I26: Orsat apparatus | P26: DVM －045 －001
B28: VELOCITY AND FLOW RATE OF FLUE GAS
B29: Measuring point | H29: Measuring time | P29: Dynamic pressure | X29: Temperature | AF29: Static pressure | AN29: Velocity | AV29: Gas density
P30: Pd | X30: θs | AF30: Ps | AN30: v | AV30: ρ
P31: Pa | X31: ℃ | AF31: kPa | AN31: m/s | AV31: kg/m3
H32: ① | L32: ② | P32: ① | T32: ② | X32: ① | AB32: ② | AF32: ① | AJ32: ② | AN32: ① | AR32: ② | AV32: ① | BC32: ②
B33: A-1 | H33: 0.5 | P33: 144 | X33: 115 | AF33: -2.2 | AN33: =IF(P33="","",ROUND($S$50*SQRT(2*P33/$AV$33),1)) -> 17.9 | AR33: =IF(T33="","",ROUND($S$50*SQRT(2*T33/$BC$33),1)) | AV33: =ROUND($AR$25*298.15/101.32*($BF$8+AF33)/(273.15+X49),3) -> 0.9 | BC33: =IFROUND($AR$25*298.15/101.32*($BF$8+AJ33)/(273.15+AB49),3) -> #NAME?
B34: A-2 | P34: 86 | X34: 115 | AN34: =IF(P34="","",ROUND($S$50*SQRT(2*P34/$AV$33),1)) -> 13.8 | AR34: =IF(T34="","",ROUND($S$50*SQRT(2*T34/$BC$33),1)) | AV34: Gas flow rate
B35: A-3 | P35: 152 | X35: 115 | AN35: =IF(P35="","",ROUND($S$50*SQRT(2*P35/$AV$33),1)) -> 18.4 | AR35: =IF(T35="","",ROUND($S$50*SQRT(2*T35/$BC$33),1)) | BA35: QA
B36: B-1 | P36: 48 | X36: 119 | AN36: =IF(P36="","",ROUND($S$50*SQRT(2*P36/$AV$33),1)) -> 10.3 | AR36: =IF(T36="","",ROUND($S$50*SQRT(2*T36/$BC$33),1)) | BA36: m3/h
B37: B-2 | P37: 182 | X37: 118 | AN37: =IF(P37="","",ROUND($S$50*SQRT(2*P37/$AV$33),1)) -> 20.1 | AR37: =IF(T37="","",ROUND($S$50*SQRT(2*T37/$BC$33),1)) | AV37: ① | BA37: =ROUND($AN$49*$AX$50*3600,-3) -> 700000
B38: B-3 | P38: 58 | X38: 121 | AN38: =IF(P38="","",ROUND($S$50*SQRT(2*P38/$AV$33),1)) -> 11.4 | AR38: =IF(T38="","",ROUND($S$50*SQRT(2*T38/$BC$33),1)) | AV38: ② | BA38: =ROUND($AR$49*$AX$50*3600,-3) -> #DIV/0!
B39: C-1 | P39: 64 | X39: 125 | AN39: =IF(P39="","",ROUND($S$50*SQRT(2*P39/$AV$33),1)) -> 11.9 | AR39: =IF(T39="","",ROUND($S$50*SQRT(2*T39/$BC$33),1)) | AV39: Average | BA39: =AVERAGE(BA37:BI38) -> #DIV/0!
B40: C-2 | P40: 76 | X40: 125 | AN40: =IF(P40="","",ROUND($S$50*SQRT(2*P40/$AV$33),1)) -> 13 | AR40: =IF(T40="","",ROUND($S$50*SQRT(2*T40/$BC$33),1)) | AV40: Wet | BA40: QN
B41: C-3 | P41: 54 | X41: 127 | AN41: =IF(P41="","",ROUND($S$50*SQRT(2*P41/$AV$33),1)) -> 11 | AR41: =IF(T41="","",ROUND($S$50*SQRT(2*T41/$BC$33),1)) | BA41: Nm3/h
B42: D-1 | P42: 58 | X42: 132 | AN42: =IF(P42="","",ROUND($S$50*SQRT(2*P42/$AV$33),1)) -> 11.4 | AR42: =IF(T42="","",ROUND($S$50*SQRT(2*T42/$BC$33),1)) | AV42: ① | BA42: =ROUND($AN$49*$AX$50*3600*298.15/101.32*($BF$8+$AF$33)/(273.15+$X$49),-3) -> 520000
B43: D-2 | P43: 166 | X43: 132 | AN43: =IF(P43="","",ROUND($S$50*SQRT(2*P43/$AV$33),1)) -> 19.2 | AR43: =IF(T43="","",ROUND($S$50*SQRT(2*T43/$BC$33),1)) | AV43: ② | BA43: =ROUND($AR$49*$AX$50*3600*298.15/101.32*($BF$8+$AJ$33)/(273.15+$AB$49),-3) -> #DIV/0!
B44: D-3 | P44: 68 | X44: 128 | AN44: =IF(P44="","",ROUND($S$50*SQRT(2*P44/$AV$33),1)) -> 12.3 | AR44: =IF(T44="","",ROUND($S$50*SQRT(2*T44/$BC$33),1)) | AV44: Average | BA44: =AVERAGE(BA42:BI43) -> #DIV/0!
B45: E-1 | P45: 94 | X45: 135 | AN45: =IF(P45="","",ROUND($S$50*SQRT(2*P45/$AV$33),1)) -> 14.5 | AR45: =IF(T45="","",ROUND($S$50*SQRT(2*T45/$BC$33),1)) | AV45: Dry | BA45: Q'N
...

Sheet OUT-A 
A2: MEASURING DATA SHEET (1) | X2: Customer | AN2: THAI BINH 1 THERMAL POWER PLANT
A3: Measuring date | M3: 43143 | AD3: Measuring condition | AN3: 300MW
A4: Measuring position | M4: Unit 2 ESP Outlet Duct A | AD4: Measuring person | AN4: Hoai, Khanh, Anh
R6: Recorded by | V6: Calculated by | Z6: Checked by | AD6: PC Input | AH6: Collated by
B8: MOISTURE CONTENT IN FLUE GAS | AL8: Atmospheric pressure | AX8: Pa | BB8: kPa | BF8: 102.8
B9: Measuring point | I9: Measuring time | P9: U - tube No. | V9: Gas meter | AO9: Mass of moisture | AV9: Moisture content
V10: Suction volume | AE10: Temp. | AI10: Pressure | AV10: Value | BC10: Average
V11: V | AE11: θm | AI11: Pm | AO11: m | AV11: Xw | BC11: Xw
V12: L | AE12: ℃ | AI12: kPa | AO12: g | AV12: vol% | BC12: vol%
B13: C-2 | I13: 0.47083333 | P13: 11 | V13: 10 | AE13: 20 | AI13: 0 | AO13: 0.5627 | AV13: =IF(V13="","",ROUND(AO13/18.02*2447/(AO13/18.02*24.47+V13*298.15/101.32*($BF$8+AI13-BK13)/(273.15+AE13)),1)) -> 7 | BC13: =ROUND(AVERAGE(AV13:BB15),1) -> 7 | BK13: =ROUND(VLOOKUP(AE13,'Measurement Act'!$A$4:$C$207,3),2) -> 2.34
I14: 0.47638889 | P14: 12 | V14: 10 | AE14: 20 | AI14: 0 | AO14: 0.5602 | AV14: =IF(V14="","",ROUND(AO14/18.02*2447/(AO14/18.02*24.47+V14*298.15/101.32*($BF$8+AI14-BK14)/(273.15+AE14)),1)) -> 7 | BK14: =ROUND(VLOOKUP(AE14,'Measurement Act'!$A$4:$C$207,3),2) -> 2.34
AV15: =IF(V15="","",ROUND(AO15/18.02*2447/(AO15/18.02*24.47+V15*298.15/101.32*($BF$8+AI15-BK15)/(273.15+AE15)),1)) | BK15: =ROUND(VLOOKUP(AE15,'Measurement Act'!$A$4:$C$207,3),2) -> #N/A
B16: Equipment No. | I16: Gas meter | P16: DVM －013 －004 | AI16: Suction pump | AS16: DVM － 027 －010
I17: Barometer | P17: DVM －016 －004
B19: COMPOSITION AND DENSITY OF FLUE GAS | AR19: Density of wet flue gas in standard condition
B20: Measuring point | I20: Measuring time | P20: Gas composition
P21: CO2 | W21: O2 | AD21: CO | AK21: N2 | AR21: ρ0
P22: vol% | W22: vol% | AD22: vol% | AK22: vol% | AR22: kg/Nm3
B23: C-2 | I23: 0.46805556 | P23: 14.2 | W23: 5.4 | AD23: - | AK23: =100-P23-W23 -> 80.4 | AR23: =((44*P23+32*W23+28*AK23)*(1-$BC$13/100)+18.02*$BC$13)/2447 -> 1.2102673
I24: 0.48194444 | P24: 14.2 | W24: 5.4 | AD24: - | AK24: =100-P24-W24 -> 80.4 | AR24: =((44*P24+32*W24+28*AK24)*(1-$BC$13/100)+18.02*$BC$13)/2447 -> 1.2102673
I25: Average | P25: =ROUND(AVERAGE(P23:V24),1) -> 14.2 | W25: =ROUND(AVERAGE(W23:AC24),1) -> 5.4 | AD25: - | AK25: =100-P25-W25 -> 80.4 | AR25: =ROUND(AVERAGE(AR23:BI24),2) -> 1.21
B26: Equipment No. | I26: Orsat apparatus | P26: DVM －045 －003
B28: VELOCITY AND FLOW RATE OF FLUE GAS
B29: Measuring point | H29: Measuring time | P29: Dynamic pressure | X29: Temperature | AF29: Static pressure | AN29: Velocity | AV29: Gas density
P30: Pd | X30: θs | AF30: Ps | AN30: v | AV30: ρ
P31: Pa | X31: ℃ | AF31: kPa | AN31: m/s | AV31: kg/m3
H32: ① | L32: ② | P32: ① | T32: ② | X32: ① | AB32: ② | AF32: ① | AJ32: ② | AN32: ① | AR32: ② | AV32: ① | BC32: ②
B33: A-1 | H33: 0.45833333 | P33: 102 | X33: 129 | AF33: -2.3 | AN33: =IF(P33="","",ROUND($S$50*SQRT(2*P33/$AV$33),1)) -> 15 | AR33: =IF(T33="","",ROUND($S$50*SQRT(2*T33/$BC$33),1)) | AV33: =ROUND($AR$25*298.15/101.32*($BF$8+AF33)/(273.15+X49),3) -> 0.901 | BC33: =IFROUND($AR$25*298.15/101.32*($BF$8+AJ33)/(273.15+AB49),3) -> #NAME?
B34: A-2 | P34: 95 | X34: 128 | AN34: =IF(P34="","",ROUND($S$50*SQRT(2*P34/$AV$33),1)) -> 14.5 | AR34: =IF(T34="","",ROUND($S$50*SQRT(2*T34/$BC$33),1)) | AV34: Gas flow rate
B35: A-3 | P35: 105 | X35: 124 | AN35: =IF(P35="","",ROUND($S$50*SQRT(2*P35/$AV$33),1)) -> 15.3 | AR35: =IF(T35="","",ROUND($S$50*SQRT(2*T35/$BC$33),1)) | BA35: QA
B36: B-1 | P36: 94 | X36: 130 | AN36: =IF(P36="","",ROUND($S$50*SQRT(2*P36/$AV$33),1)) -> 14.4 | AR36: =IF(T36="","",ROUND($S$50*SQRT(2*T36/$BC$33),1)) | BA36: m3/h
B37: B-2 | P37: 126 | X37: 125 | AN37: =IF(P37="","",ROUND($S$50*SQRT(2*P37/$AV$33),1)) -> 16.7 | AR37: =IF(T37="","",ROUND($S$50*SQRT(2*T37/$BC$33),1)) | AV37: ① | BA37: =ROUND($AN$49*$AX$50*3600,-3) -> 719000
B38: B-3 | P38: 94 | X38: 119 | AN38: =IF(P38="","",ROUND($S$50*SQRT(2*P38/$AV$33),1)) -> 14.4 | AR38: =IF(T38="","",ROUND($S$50*SQRT(2*T38/$BC$33),1)) | AV38: ② | BA38: =ROUND($AR$49*$AX$50*3600,-3) -> #DIV/0!
B39: C-1 | P39: 100 | X39: 129 | AN39: =IF(P39="","",ROUND($S$50*SQRT(2*P39/$AV$33),1)) -> 14.9 | AR39: =IF(T39="","",ROUND($S$50*SQRT(2*T39/$BC$33),1)) | AV39: Average | BA39: =AVERAGE(BA37:BI38) -> #DIV/0!
B40: C-2 | P40: 96 | X40: 125 | AN40: =IF(P40="","",ROUND($S$50*SQRT(2*P40/$AV$33),1)) -> 14.6 | AR40: =IF(T40="","",ROUND($S$50*SQRT(2*T40/$BC$33),1)) | AV40: Wet | BA40: QN
B41: C-3 | P41: 101 | X41: 118 | AN41: =IF(P41="","",ROUND($S$50*SQRT(2*P41/$AV$33),1)) -> 15 | AR41: =IF(T41="","",ROUND($S$50*SQRT(2*T41/$BC$33),1)) | BA41: Nm3/h
B42: D-1 | P42: 94 | X42: 126 | AN42: =IF(P42="","",ROUND($S$50*SQRT(2*P42/$AV$33),1)) -> 14.4 | AR42: =IF(T42="","",ROUND($S$50*SQRT(2*T42/$BC$33),1)) | AV42: ① | BA42: =ROUND($AN$49*$AX$50*3600*298.15/101.32*($BF$8+$AF$33)/(273.15+$X$49),-3) -> 536000
B43: D-2 | P43: 119 | X43: 122 | AN43: =IF(P43="","",ROUND($S$50*SQRT(2*P43/$AV$33),1)) -> 16.3 | AR43: =IF(T43="","",ROUND($S$50*SQRT(2*T43/$BC$33),1)) | AV43: ② | BA43: =ROUND($AR$49*$AX$50*3600*298.15/101.32*($BF$8+$AJ$33)/(273.15+$AB$49),-3) -> #DIV/0!
B44: D-3 | P44: 95 | X44: 119 | AN44: =IF(P44="","",ROUND($S$50*SQRT(2*P44/$AV$33),1)) -> 14.5 | AR44: =IF(T44="","",ROUND($S$50*SQRT(2*T44/$BC$33),1)) | AV44: Average | BA44: =AVERAGE(BA42:BI43) -> #DIV/0!
B45: E-1 | P45: 102 | X45: 123 | AN45: =IF(P45="","",ROUND($S$50*SQRT(2*P45/$AV$33),1)) -> 15 | AR45: =IF(T45="","",ROUND($S$50*SQRT(2*T45/$BC$33),1)) | AV45: Dry | BA45: Q'N
...

Sheet OUT-B
A2: MEASURING DATA SHEET (1) | X2: Customer | AN2: THAI BINH 1 THERMAL POWER PLANT
A3: Measuring date | M3: 43143 | AD3: Measuring condition | AN3: 300MW
A4: Measuring position | M4: Unit 2 ESP Outlet Duct B | AD4: Measuring person | AN4: Hoai, Khanh, Anh
R6: Recorded by | V6: Calculated by | Z6: Checked by | AD6: PC Input | AH6: Collated by
B8: MOISTURE CONTENT IN FLUE GAS | AL8: Atmospheric pressure | AX8: Pa | BB8: kPa | BF8: 102.8
B9: Measuring point | I9: Measuring time | P9: U - tube No. | V9: Gas meter | AO9: Mass of moisture | AV9: Moisture content
V10: Suction volume | AE10: Temp. | AI10: Pressure | AV10: Value | BC10: Average
V11: V | AE11: θm | AI11: Pm | AO11: m | AV11: Xw | BC11: Xw
V12: L | AE12: ℃ | AI12: kPa | AO12: g | AV12: vol% | BC12: vol%
B13: C-2 | I13: 0.50138889 | P13: 13 | V13: 10 | AE13: 20 | AI13: 0 | AO13: 0.5485 | AV13: =IF(V13="","",ROUND(AO13/18.02*2447/(AO13/18.02*24.47+V13*298.15/101.32*($BF$8+AI13-BK13)/(273.15+AE13)),1)) -> 6.9 | BC13: =ROUND(AVERAGE(AV13:BB15),1) -> 6.8 | BK13: =ROUND(VLOOKUP(AE13,'Measurement Act'!$A$4:$C$207,3),2) -> 2.34
I14: 0.50625 | P14: 14 | V14: 10 | AE14: 20 | AI14: 0 | AO14: 0.5369 | AV14: =IF(V14="","",ROUND(AO14/18.02*2447/(AO14/18.02*24.47+V14*298.15/101.32*($BF$8+AI14-BK14)/(273.15+AE14)),1)) -> 6.7 | BK14: =ROUND(VLOOKUP(AE14,'Measurement Act'!$A$4:$C$207,3),2) -> 2.34
AV15: =IF(V15="","",ROUND(AO15/18.02*2447/(AO15/18.02*24.47+V15*298.15/101.32*($BF$8+AI15-BK15)/(273.15+AE15)),1)) | BK15: =ROUND(VLOOKUP(AE15,'Measurement Act'!$A$4:$C$207,3),2) -> #N/A
B16: Equipment No. | I16: Gas meter | P16: DVM －013 －003 | AI16: Suction pump | AS16: DVM － 027 －009
I17: Barometer | P17: DVM －016 －004
B19: COMPOSITION AND DENSITY OF FLUE GAS | AR19: Density of wet flue gas in standard condition
B20: Measuring point | I20: Measuring time | P20: Gas composition
P21: CO2 | W21: O2 | AD21: CO | AK21: N2 | AR21: ρ0
P22: vol% | W22: vol% | AD22: vol% | AK22: vol% | AR22: kg/Nm3
B23: C-2 | I23: 0.5 | P23: 14 | W23: 5.6 | AD23: - | AK23: =100-P23-W23 -> 80.4 | AR23: =((44*P23+32*W23+28*AK23)*(1-$BC$13/100)+18.02*$BC$13)/2447 -> 1.2103722
I24: 0.5125 | P24: 14.2 | W24: 5.4 | AD24: - | AK24: =100-P24-W24 -> 80.4 | AR24: =((44*P24+32*W24+28*AK24)*(1-$BC$13/100)+18.02*$BC$13)/2447 -> 1.2112863
I25: Average | P25: =ROUND(AVERAGE(P23:V24),1) -> 14.1 | W25: =ROUND(AVERAGE(W23:AC24),1) -> 5.5 | AD25: - | AK25: =100-P25-W25 -> 80.4 | AR25: =ROUND(AVERAGE(AR23:BI24),2) -> 1.21
B26: Equipment No. | I26: Orsat apparatus | P26: DVM －045 －003
B28: VELOCITY AND FLOW RATE OF FLUE GAS
B29: Measuring point | H29: Measuring time | P29: Dynamic pressure | X29: Temperature | AF29: Static pressure | AN29: Velocity | AV29: Gas density
P30: Pd | X30: θs | AF30: Ps | AN30: v | AV30: ρ
P31: Pa | X31: ℃ | AF31: kPa | AN31: m/s | AV31: kg/m3
H32: ① | L32: ② | P32: ① | T32: ② | X32: ① | AB32: ② | AF32: ① | AJ32: ② | AN32: ① | AR32: ② | AV32: ① | BC32: ②
B33: A-1 | H33: 0.48958333 | P33: 110 | X33: 123 | AF33: -2.5 | AN33: =IF(P33="","",ROUND($S$50*SQRT(2*P33/$AV$33),1)) -> 15.6 | AR33: =IF(T33="","",ROUND($S$50*SQRT(2*T33/$BC$33),1)) | AV33: =ROUND($AR$25*298.15/101.32*($BF$8+AF33)/(273.15+X49),3) -> 0.899 | BC33: =IFROUND($AR$25*298.15/101.32*($BF$8+AJ33)/(273.15+AB49),3) -> #NAME?
B34: A-2 | P34: 97 | X34: 120 | AN34: =IF(P34="","",ROUND($S$50*SQRT(2*P34/$AV$33),1)) -> 14.7 | AR34: =IF(T34="","",ROUND($S$50*SQRT(2*T34/$BC$33),1)) | AV34: Gas flow rate
B35: A-3 | P35: 110 | X35: 119 | AN35: =IF(P35="","",ROUND($S$50*SQRT(2*P35/$AV$33),1)) -> 15.6 | AR35: =IF(T35="","",ROUND($S$50*SQRT(2*T35/$BC$33),1)) | BA35: QA
B36: B-1 | P36: 105 | X36: 126 | AN36: =IF(P36="","",ROUND($S$50*SQRT(2*P36/$AV$33),1)) -> 15.3 | AR36: =IF(T36="","",ROUND($S$50*SQRT(2*T36/$BC$33),1)) | BA36: m3/h
B37: B-2 | P37: 125 | X37: 122 | AN37: =IF(P37="","",ROUND($S$50*SQRT(2*P37/$AV$33),1)) -> 16.7 | AR37: =IF(T37="","",ROUND($S$50*SQRT(2*T37/$BC$33),1)) | AV37: ① | BA37: =ROUND($AN$49*$AX$50*3600,-3) -> 748000
B38: B-3 | P38: 98 | X38: 119 | AN38: =IF(P38="","",ROUND($S$50*SQRT(2*P38/$AV$33),1)) -> 14.8 | AR38: =IF(T38="","",ROUND($S$50*SQRT(2*T38/$BC$33),1)) | AV38: ② | BA38: =ROUND($AR$49*$AX$50*3600,-3) -> #DIV/0!
B39: C-1 | P39: 109 | X39: 129 | AN39: =IF(P39="","",ROUND($S$50*SQRT(2*P39/$AV$33),1)) -> 15.6 | AR39: =IF(T39="","",ROUND($S$50*SQRT(2*T39/$BC$33),1)) | AV39: Average | BA39: =AVERAGE(BA37:BI38) -> #DIV/0!
B40: C-2 | P40: 96 | X40: 125 | AN40: =IF(P40="","",ROUND($S$50*SQRT(2*P40/$AV$33),1)) -> 14.6 | AR40: =IF(T40="","",ROUND($S$50*SQRT(2*T40/$BC$33),1)) | AV40: Wet | BA40: QN
B41: C-3 | P41: 103 | X41: 119 | AN41: =IF(P41="","",ROUND($S$50*SQRT(2*P41/$AV$33),1)) -> 15.1 | AR41: =IF(T41="","",ROUND($S$50*SQRT(2*T41/$BC$33),1)) | BA41: Nm3/h
B42: D-1 | P42: 91 | X42: 130 | AN42: =IF(P42="","",ROUND($S$50*SQRT(2*P42/$AV$33),1)) -> 14.2 | AR42: =IF(T42="","",ROUND($S$50*SQRT(2*T42/$BC$33),1)) | AV42: ① | BA42: =ROUND($AN$49*$AX$50*3600*298.15/101.32*($BF$8+$AF$33)/(273.15+$X$49),-3) -> 556000
B43: D-2 | P43: 125 | X43: 127 | AN43: =IF(P43="","",ROUND($S$50*SQRT(2*P43/$AV$33),1)) -> 16.7 | AR43: =IF(T43="","",ROUND($S$50*SQRT(2*T43/$BC$33),1)) | AV43: ② | BA43: =ROUND($AR$49*$AX$50*3600*298.15/101.32*($BF$8+$AJ$33)/(273.15+$AB$49),-3) -> #DIV/0!
B44: D-3 | P44: 90 | X44: 121 | AN44: =IF(P44="","",ROUND($S$50*SQRT(2*P44/$AV$33),1)) -> 14.1 | AR44: =IF(T44="","",ROUND($S$50*SQRT(2*T44/$BC$33),1)) | AV44: Average | BA44: =AVERAGE(BA42:BI43) -> #DIV/0!
B45: E-1 | P45: 123 | X45: 129 | AN45: =IF(P45="","",ROUND($S$50*SQRT(2*P45/$AV$33),1)) -> 16.5 | AR45: =IF(T45="","",ROUND($S$50*SQRT(2*T45/$BC$33),1)) | AV45: Dry | BA45: Q'N
...

Sheet Dust IN-A
A2: MEASURING DATA SHEET (2) | X2: Customer | AN2: THAI BINH 1 THERMAL POWER PLANT
A3: Measuring date | M3: 43143 | AD3: Measuring condition | AN3: 300MW
A4: Measuring position | M4: Unit 2 ESP Inlet Duct A | AD4: Measuring person | AN4: Dung
B6: DUST CONCENTRATION IN FLUE GAS | AF6: Recorded by | AK6: Calculated by | AP6: Checked by | AU6: PC Input | AZ6: Collated by
B7: Circular filter paper | P7: Cylindrical filter paper
B8: □ | D8: Form 1 | I8: □ | K8: Form 2 | P8: ■ | R8: Form 1 | W8: □ | Y8: Form 2
B9: □ | D9: QMA | I9: □ | K9: PF-020 | P9: ■ | R9: Whatman | W9: □ | Y9: 89 | AD9: Atmospheric pressure | AU9: Pa | AZ9: kPa | BE9: 102.8
P10: □ | R10: 89S | AD10: Oxygen standard concentration | AU10: On | AZ10: %
B11: Measuring points | F11: Measuring time | J11: Number of points | M11: Diameter of nozzle | P11: Filter paper No. | T11: Suction duration | X11: Gas meter | AK11: Suction volume at standard condition | AP11: Mass of collected dust | AU11: Dust concentration | BE11: Oxygen concentration
X12: Suction volume | AC12: Temp. | AG12: Pressure | AU12: Measured value | AZ12: Conversion value
M13: d | T13: t | X13: V | AC13: θm | AG13: Pm | AK13: Vs | AP13: m | AU13: Cs | AZ13: C | BE13: Os
M14: mm | T14: min | X14: L | AC14: ℃ | AG14: kPa | AK14: Nm3 | AP14: g | AU14: g/Nm3 | AZ14: g/Nm3 | BE14: %
B15: A-1~3 | F15: 0.65833333 | J15: 3 | M15: 5 | P15: 3 | T15: 9 | X15: 124 | AC15: 21 | AG15: 0.1 | AK15: =IF(X15="","",ROUND(X15*298.15/101.32*($BE$9+AG15-BK15)/(273.15+AC15)/1000,3)) -> 0.125 | AP15: 3.0059 | AU15: =IF(AP15="","",ROUND(AP15/AK15,1)) -> 24 | AZ15: - | BE15: - | BK15: =ROUND(VLOOKUP(AC15,'Measurement Act'!$A$4:$C$207,3),2) -> 2.49
B16: B-1~3 | F16: 0.70277778 | J16: 3 | M16: 5 | P16: 4 | T16: 9 | X16: 107 | AC16: 21 | AG16: 0.1 | AK16: =IF(X16="","",ROUND(X16*298.15/101.32*($BE$9+AG16-BK16)/(273.15+AC16)/1000,3)) -> 0.107 | AP16: 2.53337 | AU16: =IF(AP16="","",ROUND(AP16/AK16,1)) -> 23.7 | AZ16: - | BE16: - | BK16: =ROUND(VLOOKUP(AC16,'Measurement Act'!$A$4:$C$207,3),2) -> 2.49
B17: C-1~3 | F17: 0.71388889 | J17: 3 | M17: 5 | P17: 6 | T17: 9 | X17: 95 | AC17: 21 | AG17: 0.1 | AK17: =IF(X17="","",ROUND(X17*298.15/101.32*($BE$9+AG17-BK17)/(273.15+AC17)/1000,3)) -> 0.095 | AP17: 2.42034 | AU17: =IF(AP17="","",ROUND(AP17/AK17,1)) -> 25.5 | AZ17: - | BE17: - | BK17: =ROUND(VLOOKUP(AC17,'Measurement Act'!$A$4:$C$207,3),2) -> 2.49
B18: D-1~3 | F18: 0.72430556 | J18: 3 | M18: 5 | P18: 7 | T18: 9 | X18: 103 | AC18: 21 | AG18: 0.1 | AK18: =IF(X18="","",ROUND(X18*298.15/101.32*($BE$9+AG18-BK18)/(273.15+AC18)/1000,3)) -> 0.103 | AP18: 2.7461 | AU18: =IF(AP18="","",ROUND(AP18/AK18,1)) -> 26.7 | AZ18: - | BE18: - | BK18: =ROUND(VLOOKUP(AC18,'Measurement Act'!$A$4:$C$207,3),2) -> 2.49
B19: E-1~3 | F19: 0.73541667 | J19: 3 | M19: 5 | P19: 8 | T19: 9 | X19: 126 | AC19: 21 | AG19: 0.1 | AK19: =IF(X19="","",ROUND(X19*298.15/101.32*($BE$9+AG19-BK19)/(273.15+AC19)/1000,3)) -> 0.127 | AP19: 3.34658 | AU19: =IF(AP19="","",ROUND(AP19/AK19,1)) -> 26.4 | AZ19: - | BE19: - | BK19: =ROUND(VLOOKUP(AC19,'Measurement Act'!$A$4:$C$207,3),2) -> 2.49
AP20: Average | AU20: =ROUND(AVERAGE(AU15:AY19),1) -> 25.3 | AZ20: - | BE20: -
B21: Equipment No. | I21: Gas meter | T21: D2 － 013 －090 | AK21: Suction pump | AU21: DVM － 027 －002
I22: Orsat apparatus | T22: DVM － 045 －
AK24: Calculated by | AP24: Checked by | AU24: PC Input | AZ24: Collated by
B26: NITROGEN OXIDE CONCENTRATION IN FLUE GAS
B27: Measuring point | Z27: Oxygen standard concentration | AR27: On | AV27: %
B28: Measuring time | F28: NOx flask | AL28: Suction volume at standard condition | AP28: Ion concentration determined from the working curve | AX28: Nitrogen oxide concentration | BF28: Oxygen concentration
F29: No. | J29: Before sampling | V29: After sampling | AH29: Volume
J30: Absolute pressure | N30: Temp. | R30: Saturated vapor pressure | V30: Absolute pressure | Z30: Temp. | AD30: Saturated vapor pressure | AP30: NO3 | AT30: NO2 | AX30: Measured value | BB30: Conversion value
J31: Pi | N31: ti | R31: Pni | V31: Pf | Z31: tf | AD31: Pnf | AH31: V-20 | AL31: Vs | AP31: a | AT31: b | AX31: Cs | BB31: C | BF31: Os
J32: kPa | N32: ℃ | R32: kPa | V32: kPa | Z32: ℃ | AD32: kPa | AH32: mL | AL32: mL | AP32: mg/L | AT32: mg/L | AX32: ppm | BB32: ppm | BF32: %
AP36: Average
P37: Flask (After collecting)
P38: No. | S38: Atmospheric pressure | Z38: Residual pressure
S39: kPa | Z39: kPa
B44: Equipment No. | I44: Manometer | T44: DVM － － | AI44: Mighty pump | AS44: DVM－ 029 －
I45: Orsat apparatus | T45: DVM － 016 －
B49: Retention period | K49: 5 years | R49: Storage department | Z49: Technical department | AI49: MM-G-02.01 | AR49: Enacted date | BB49: 43117

Sheet Dust IN-B
A2: MEASURING DATA SHEET (2) | X2: Customer | AN2: THAI BINH 1 THERMAL POWER PLANT
A3: Measuring date | M3: 43143 | AD3: Measuring condition | AN3: 300MW
A4: Measuring position | M4: Unit 2 ESP Inlet Duct B | AD4: Measuring person | AN4: Tuyen
B6: DUST CONCENTRATION IN FLUE GAS | AF6: Recorded by | AK6: Calculated by | AP6: Checked by | AU6: PC Input | AZ6: Collated by
B7: Circular filter paper | P7: Cylindrical filter paper
B8: □ | D8: Form 1 | I8: □ | K8: Form 2 | P8: ■ | R8: Form 1 | W8: □ | Y8: Form 2
B9: □ | D9: QMA | I9: □ | K9: PF-020 | P9: ■ | R9: Whatman | W9: □ | Y9: 89 | AD9: Atmospheric pressure | AU9: Pa | AZ9: kPa | BE9: 102.8
P10: □ | R10: 89S | AD10: Oxygen standard concentration | AU10: On | AZ10: %
B11: Measuring points | F11: Measuring time | J11: Number of points | M11: Diameter of nozzle | P11: Filter paper No. | T11: Suction duration | X11: Gas meter | AK11: Suction volume at standard condition | AP11: Mass of collected dust | AU11: Dust concentration | BE11: Oxygen concentration
X12: Suction volume | AC12: Temp. | AG12: Pressure | AU12: Measured value | AZ12: Conversion value
M13: d | T13: t | X13: V | AC13: θm | AG13: Pm | AK13: Vs | AP13: m | AU13: Cs | AZ13: C | BE13: Os
M14: mm | T14: min | X14: L | AC14: ℃ | AG14: kPa | AK14: Nm3 | AP14: g | AU14: g/Nm3 | AZ14: g/Nm3 | BE14: %
B15: A-1~3 | F15: 0.65833333 | J15: 3 | M15: 5 | P15: 33 | T15: 9 | X15: 122 | AC15: 20 | AG15: 0.1 | AK15: =IF(X15="","",ROUND(X15*298.15/101.32*($BE$9+AG15-BK15)/(273.15+AC15)/1000,3)) -> 0.123 | AP15: 3.95491 | AU15: =IF(AP15="","",ROUND(AP15/AK15,1)) -> 32.2 | AZ15: - | BE15: - | BK15: =ROUND(VLOOKUP(AC15,'Measurement Act'!$A$4:$C$207,3),2) -> 2.34
B16: B-1~3 | F16: 0.70347222 | J16: 3 | M16: 5 | P16: 34 | T16: 9 | X16: 106 | AC16: 20 | AG16: 0.1 | AK16: =IF(X16="","",ROUND(X16*298.15/101.32*($BE$9+AG16-BK16)/(273.15+AC16)/1000,3)) -> 0.107 | AP16: 2.64969 | AU16: =IF(AP16="","",ROUND(AP16/AK16,1)) -> 24.8 | AZ16: - | BE16: - | BK16: =ROUND(VLOOKUP(AC16,'Measurement Act'!$A$4:$C$207,3),2) -> 2.34
B17: C-1~3 | F17: 0.71458333 | J17: 3 | M17: 6 | P17: 35 | T17: 9 | X17: 128 | AC17: 20 | AG17: 0.1 | AK17: =IF(X17="","",ROUND(X17*298.15/101.32*($BE$9+AG17-BK17)/(273.15+AC17)/1000,3)) -> 0.129 | AP17: 3.06318 | AU17: =IF(AP17="","",ROUND(AP17/AK17,1)) -> 23.7 | AZ17: - | BE17: - | BK17: =ROUND(VLOOKUP(AC17,'Measurement Act'!$A$4:$C$207,3),2) -> 2.34
B18: D-1~3 | F18: 0.72430556 | J18: 3 | M18: 5 | P18: 36 | T18: 9 | X18: 106 | AC18: 20 | AG18: 0.1 | AK18: =IF(X18="","",ROUND(X18*298.15/101.32*($BE$9+AG18-BK18)/(273.15+AC18)/1000,3)) -> 0.107 | AP18: 2.53899 | AU18: =IF(AP18="","",ROUND(AP18/AK18,1)) -> 23.7 | AZ18: - | BE18: - | BK18: =ROUND(VLOOKUP(AC18,'Measurement Act'!$A$4:$C$207,3),2) -> 2.34
B19: E-1~3 | F19: 0.73125 | J19: 3 | M19: 5 | P19: 37 | T19: 9 | X19: 108 | AC19: 20 | AG19: 0.1 | AK19: =IF(X19="","",ROUND(X19*298.15/101.32*($BE$9+AG19-BK19)/(273.15+AC19)/1000,3)) -> 0.109 | AP19: 2.56558 | AU19: =IF(AP19="","",ROUND(AP19/AK19,1)) -> 23.5 | AZ19: - | BE19: - | BK19: =ROUND(VLOOKUP(AC19,'Measurement Act'!$A$4:$C$207,3),2) -> 2.34
AP20: Average | AU20: =ROUND(AVERAGE(AU15:AY19),1) -> 25.6 | AZ20: - | BE20: -
B21: Equipment No. | I21: Gas meter | T21: D2 － 013 －085 | AK21: Suction pump | AU21: DVM － 027 －007
I22: Orsat apparatus | T22: DVM － 045 －
AK24: Calculated by | AP24: Checked by | AU24: PC Input | AZ24: Collated by
B26: NITROGEN OXIDE CONCENTRATION IN FLUE GAS
B27: Measuring point | Z27: Oxygen standard concentration | AR27: On | AV27: %
B28: Measuring time | F28: NOx flask | AL28: Suction volume at standard condition | AP28: Ion concentration determined from the working curve | AX28: Nitrogen oxide concentration | BF28: Oxygen concentration
F29: No. | J29: Before sampling | V29: After sampling | AH29: Volume
J30: Absolute pressure | N30: Temp. | R30: Saturated vapor pressure | V30: Absolute pressure | Z30: Temp. | AD30: Saturated vapor pressure | AP30: NO3 | AT30: NO2 | AX30: Measured value | BB30: Conversion value
J31: Pi | N31: ti | R31: Pni | V31: Pf | Z31: tf | AD31: Pnf | AH31: V-20 | AL31: Vs | AP31: a | AT31: b | AX31: Cs | BB31: C | BF31: Os
J32: kPa | N32: ℃ | R32: kPa | V32: kPa | Z32: ℃ | AD32: kPa | AH32: mL | AL32: mL | AP32: mg/L | AT32: mg/L | AX32: ppm | BB32: ppm | BF32: %
AP36: Average
P37: Flask (After collecting)
P38: No. | S38: Atmospheric pressure | Z38: Residual pressure
S39: kPa | Z39: kPa
B44: Equipment No. | I44: Manometer | T44: DVM － － | AI44: Mighty pump | AS44: DVM－ 029 －
I45: Orsat apparatus | T45: DVM － 016 －
B49: Retention period | K49: 5 years | R49: Storage department | Z49: Technical department | AI49: MM-G-02.01 | AR49: Enacted date | BB49: 43117

Sheet Dust OUT-A
A2: MEASURING DATA SHEET (2) | X2: Customer | AN2: THAI BINH 1 THERMAL POWER PLANT
A3: Measuring date | M3: 43165 | AD3: Measuring condition | AN3: 300MW
A4: Measuring position | M4: Unit 2 ESP Outlet Duct A | AD4: Measuring person | AN4: Dung, Tuyen
B6: DUST CONCENTRATION IN FLUE GAS | AF6: Recorded by | AK6: Calculated by | AP6: Checked by | AU6: PC Input | AZ6: Collated by
B7: Circular filter paper | P7: Cylindrical filter paper
B8: ■ | D8: Form 1 | I8: □ | K8: Form 2 | P8: □ | R8: Form 1 | W8: □ | Y8: Form 2
B9: ■ | D9: QMA | I9: □ | K9: PF-020 | P9: □ | R9: Whatman | W9: □ | Y9: 89 | AD9: Atmospheric pressure | AU9: Pa | AZ9: kPa | BE9: 101.4
P10: □ | R10: 89S | AD10: Oxygen standard concentration | AU10: On | AZ10: %
B11: Measuring points | F11: Measuring time | J11: Number of points | M11: Diameter of nozzle | P11: Filter paper No. | T11: Suction duration | X11: Gas meter | AK11: Suction volume at standard condition | AP11: Mass of collected dust | AU11: Dust concentration | BE11: Oxygen concentration
X12: Suction volume | AC12: Temp. | AG12: Pressure | AU12: Measured value | AZ12: Conversion value
M13: d | T13: t | X13: V | AC13: θm | AG13: Pm | AK13: Vs | AP13: m | AU13: Cs | AZ13: C | BE13: Os
M14: mm | T14: min | X14: L | AC14: ℃ | AG14: kPa | AK14: Nm3 | AP14: g | AU14: g/Nm3 | AZ14: g/Nm3 | BE14: %
B15: A-1~3 | F15: 0.5875 | J15: 3 | M15: 5 | P15: 571 | T15: 15 | X15: 199 | AC15: 36 | AG15: 0.1 | AK15: =IF(X15="","",ROUND(X15*298.15/101.32*($BE$9+AG15-BK15)/(273.15+AC15)/1000,3)) -> 0.181 | AP15: 0.01314 | AU15: =IF(AP15="","",ROUND(AP15/AK15,4)) -> 0.0726 | AZ15: - | BE15: - | BK15: =ROUND(VLOOKUP(AC15,'Measurement Act'!$A$4:$C$207,3),2) -> 5.95
B16: B-1~3 | F16: 0.60277778 | J16: 3 | M16: 5 | P16: 690 | T16: 15 | X16: 200 | AC16: 35 | AG16: 0.1 | AK16: =IF(X16="","",ROUND(X16*298.15/101.32*($BE$9+AG16-BK16)/(273.15+AC16)/1000,3)) -> 0.183 | AP16: 0.00998 | AU16: =IF(AP16="","",ROUND(AP16/AK16,4)) -> 0.0545 | AZ16: - | BE16: - | BK16: =ROUND(VLOOKUP(AC16,'Measurement Act'!$A$4:$C$207,3),2) -> 5.63
B17: C-1~3 | F17: 0.59305556 | J17: 3 | M17: 5 | P17: 572 | T17: 15 | X17: 190 | AC17: 32 | AG17: 0.1 | AK17: =IF(X17="","",ROUND(X17*298.15/101.32*($BE$9+AG17-BK17)/(273.15+AC17)/1000,3)) -> 0.177 | AP17: 0.00977 | AU17: =IF(AP17="","",ROUND(AP17/AK17,4)) -> 0.0552 | AZ17: - | BE17: - | BK17: =ROUND(VLOOKUP(AC17,'Measurement Act'!$A$4:$C$207,3),2) -> 4.76
B18: D-1~3 | F18: 0.60277778 | J18: 3 | M18: 5 | P18: 580 | T18: 15 | X18: 203 | AC18: 32 | AG18: 0.1 | AK18: =IF(X18="","",ROUND(X18*298.15/101.32*($BE$9+AG18-BK18)/(273.15+AC18)/1000,3)) -> 0.189 | AP18: 0.01363 | AU18: =IF(AP18="","",ROUND(AP18/AK18,4)) -> 0.0721 | AZ18: - | BE18: - | BK18: =ROUND(VLOOKUP(AC18,'Measurement Act'!$A$4:$C$207,3),2) -> 4.76
B19: E-1~3 | F19: 0.58680556 | J19: 3 | M19: 5 | P19: 18 | T19: 15 | X19: 190 | AC19: 32 | AG19: 0.1 | AK19: =IF(X19="","",ROUND(X19*298.15/101.32*($BE$9+AG19-BK19)/(273.15+AC19)/1000,3)) -> 0.177 | AP19: 0.01477 | AU19: =IF(AP19="","",ROUND(AP19/AK19,4)) -> 0.0834 | AZ19: - | BE19: - | BK19: =ROUND(VLOOKUP(AC19,'Measurement Act'!$A$4:$C$207,3),2) -> 4.76
AP20: Average | AU20: =ROUND(AVERAGE(AU15:AY19),4) -> 0.0676 | AZ20: - | BE20: -
B21: Equipment No. | I21: Gas meter | T21: DVM － 013 －003,004,090 | AK21: Suction pump | AU21: DVM － 027 －002,008,009
I22: Orsat apparatus | T22: DVM － 045 －
AK24: Calculated by | AP24: Checked by | AU24: PC Input | AZ24: Collated by
B26: NITROGEN OXIDE CONCENTRATION IN FLUE GAS
B27: Measuring point | Z27: Oxygen standard concentration | AR27: On | AV27: %
B28: Measuring time | F28: NOx flask | AL28: Suction volume at standard condition | AP28: Ion concentration determined from the working curve | AX28: Nitrogen oxide concentration | BF28: Oxygen concentration
F29: No. | J29: Before sampling | V29: After sampling | AH29: Volume
J30: Absolute pressure | N30: Temp. | R30: Saturated vapor pressure | V30: Absolute pressure | Z30: Temp. | AD30: Saturated vapor pressure | AP30: NO3 | AT30: NO2 | AX30: Measured value | BB30: Conversion value
J31: Pi | N31: ti | R31: Pni | V31: Pf | Z31: tf | AD31: Pnf | AH31: V-20 | AL31: Vs | AP31: a | AT31: b | AX31: Cs | BB31: C | BF31: Os
J32: kPa | N32: ℃ | R32: kPa | V32: kPa | Z32: ℃ | AD32: kPa | AH32: mL | AL32: mL | AP32: mg/L | AT32: mg/L | AX32: ppm | BB32: ppm | BF32: %
AP36: Average
P37: Flask (After collecting)
P38: No. | S38: Atmospheric pressure | Z38: Residual pressure
S39: kPa | Z39: kPa
B44: Equipment No. | I44: Manometer | T44: DVM － － | AI44: Mighty pump | AS44: DVM－ 029 －
I45: Orsat apparatus | T45: DVM － 016 －
B49: Retention period | K49: 5 years | R49: Storage department | Z49: Technical department | AI49: MM-G-02.01 | AR49: Enacted date | BB49: 43117

Sheet Dust OUT-B
A2: MEASURING DATA SHEET (2) | X2: Customer | AN2: THAI BINH 1 THERMAL POWER PLANT
A3: Measuring date | M3: 43143 | AD3: Measuring condition | AN3: 300MW
A4: Measuring position | M4: Unit 2 ESP Outlet Duct B | AD4: Measuring person | AN4: Khanh, Anh
B6: DUST CONCENTRATION IN FLUE GAS | AF6: Recorded by | AK6: Calculated by | AP6: Checked by | AU6: PC Input | AZ6: Collated by
B7: Circular filter paper | P7: Cylindrical filter paper
B8: ■ | D8: Form 1 | I8: □ | K8: Form 2 | P8: □ | R8: Form 1 | W8: □ | Y8: Form 2
B9: ■ | D9: QMA | I9: □ | K9: PF-020 | P9: □ | R9: Whatman | W9: □ | Y9: 89 | AD9: Atmospheric pressure | AU9: Pa | AZ9: kPa | BE9: 102.8
P10: □ | R10: 89S | AD10: Oxygen standard concentration | AU10: On | AZ10: %
B11: Measuring points | F11: Measuring time | J11: Number of points | M11: Diameter of nozzle | P11: Filter paper No. | T11: Suction duration | X11: Gas meter | AK11: Suction volume at standard condition | AP11: Mass of collected dust | AU11: Dust concentration | BE11: Oxygen concentration
X12: Suction volume | AC12: Temp. | AG12: Pressure | AU12: Measured value | AZ12: Conversion value
M13: d | T13: t | X13: V | AC13: θm | AG13: Pm | AK13: Vs | AP13: m | AU13: Cs | AZ13: C | BE13: Os
M14: mm | T14: min | X14: L | AC14: ℃ | AG14: kPa | AK14: Nm3 | AP14: g | AU14: g/Nm3 | AZ14: g/Nm3 | BE14: %
B15: A-1~3 | F15: 0.70416667 | J15: 3 | M15: 5 | P15: 665 | T15: 15 | X15: 190 | AC15: 18 | AG15: 0.1 | AK15: =IF(X15="","",ROUND(X15*298.15/101.32*($BE$9+AG15-BK15)/(273.15+AC15)/1000,3)) -> 0.194 | AP15: 0.01273 | AU15: =IF(AP15="","",ROUND(AP15/AK15,4)) -> 0.0656 | AZ15: - | BE15: - | BK15: =ROUND(VLOOKUP(AC15,'Measurement Act'!$A$4:$C$207,3),2) -> 2.06
B16: B-1~3 | F16: 0.71736111 | J16: 3 | M16: 5 | P16: 666 | T16: 15 | X16: 190 | AC16: 18 | AG16: 0.1 | AK16: =IF(X16="","",ROUND(X16*298.15/101.32*($BE$9+AG16-BK16)/(273.15+AC16)/1000,3)) -> 0.194 | AP16: 0.0106 | AU16: =IF(AP16="","",ROUND(AP16/AK16,4)) -> 0.0546 | AZ16: - | BE16: - | BK16: =ROUND(VLOOKUP(AC16,'Measurement Act'!$A$4:$C$207,3),2) -> 2.06
B17: C-1~3 | F17: 0.73055556 | J17: 3 | M17: 5 | P17: 667 | T17: 15 | X17: 180 | AC17: 18 | AG17: 0.1 | AK17: =IF(X17="","",ROUND(X17*298.15/101.32*($BE$9+AG17-BK17)/(273.15+AC17)/1000,3)) -> 0.183 | AP17: 0.00871 | AU17: =IF(AP17="","",ROUND(AP17/AK17,4)) -> 0.0476 | AZ17: - | BE17: - | BK17: =ROUND(VLOOKUP(AC17,'Measurement Act'!$A$4:$C$207,3),2) -> 2.06
B18: D-1~3 | F18: 0.74305556 | J18: 3 | M18: 5 | P18: 668 | T18: 15 | X18: 187 | AC18: 19 | AG18: 0.1 | AK18: =IF(X18="","",ROUND(X18*298.15/101.32*($BE$9+AG18-BK18)/(273.15+AC18)/1000,3)) -> 0.19 | AP18: 0.01135 | AU18: =IF(AP18="","",ROUND(AP18/AK18,4)) -> 0.0597 | AZ18: - | BE18: - | BK18: =ROUND(VLOOKUP(AC18,'Measurement Act'!$A$4:$C$207,3),2) -> 2.2
B19: E-1~3 | F19: 0.75625 | J19: 3 | M19: 5 | P19: 669 | T19: 15 | X19: 197 | AC19: 19 | AG19: 0.1 | AK19: =IF(X19="","",ROUND(X19*298.15/101.32*($BE$9+AG19-BK19)/(273.15+AC19)/1000,3)) -> 0.2 | AP19: 0.00741 | AU19: =IF(AP19="","",ROUND(AP19/AK19,4)) -> 0.0371 | AZ19: - | BE19: - | BK19: =ROUND(VLOOKUP(AC19,'Measurement Act'!$A$4:$C$207,3),2) -> 2.2
AP20: Average | AU20: =ROUND(AVERAGE(AU15:AY19),4) -> 0.0529 | AZ20: - | BE20: -
B21: Equipment No. | I21: Gas meter | T21: DVM － 013 －003 | AK21: Suction pump | AU21: DVM － 027 －009
I22: Orsat apparatus | T22: DVM － 045 －
AK24: Calculated by | AP24: Checked by | AU24: PC Input | AZ24: Collated by
B26: NITROGEN OXIDE CONCENTRATION IN FLUE GAS
B27: Measuring point | Z27: Oxygen standard concentration | AR27: On | AV27: %
B28: Measuring time | F28: NOx flask | AL28: Suction volume at standard condition | AP28: Ion concentration determined from the working curve | AX28: Nitrogen oxide concentration | BF28: Oxygen concentration
F29: No. | J29: Before sampling | V29: After sampling | AH29: Volume
J30: Absolute pressure | N30: Temp. | R30: Saturated vapor pressure | V30: Absolute pressure | Z30: Temp. | AD30: Saturated vapor pressure | AP30: NO3 | AT30: NO2 | AX30: Measured value | BB30: Conversion value
J31: Pi | N31: ti | R31: Pni | V31: Pf | Z31: tf | AD31: Pnf | AH31: V-20 | AL31: Vs | AP31: a | AT31: b | AX31: Cs | BB31: C | BF31: Os
J32: kPa | N32: ℃ | R32: kPa | V32: kPa | Z32: ℃ | AD32: kPa | AH32: mL | AL32: mL | AP32: mg/L | AT32: mg/L | AX32: ppm | BB32: ppm | BF32: %
AP36: Average
P37: Flask (After collecting)
P38: No. | S38: Atmospheric pressure | Z38: Residual pressure
S39: kPa | Z39: kPa
B44: Equipment No. | I44: Manometer | T44: DVM － － | AI44: Mighty pump | AS44: DVM－ 029 －
I45: Orsat apparatus | T45: DVM － 016 －
B49: Retention period | K49: 5 years | R49: Storage department | Z49: Technical department | AI49: MM-G-02.01 | AR49: Enacted date | BB49: 43117

Sheet DUST-RESULT-1
B2: THAI BINH 1 THERMAL POWER PLANT | AH2: DATE: | AN2: 12-Feb-2018
AH3: CONDITION: | AN3: 300MW
D7: ESP FLUE GAS MEASUREMENT DATA SHEET
D8: DUST CONCENTRATION
W13: Gas direction
D30: INLET - Duct A | AC30: INLET - Duct B
D32: Average | P32: g/Nm3 | AC32: Average | AO32: g/Nm3
W41: Gas direction
D58: OUTLET - Duct A | AC58: OUTLET - Duct B
D60: Average | P60: g/Nm3 | AC60: Average | AO60: g/Nm3

Sheet Summary Result
B2: THAI BINH 1 THERMAL POWER PLANT | AH2: DATE: | AN2: 43143
AH3: CONDITION:
D7: FLUE GAS MEASUREMENT DATA SHEET
D8: ESP PERFORMANCE TEST
D11: Item | P11: ESP INLET | AF11: ESP OUTLET
P12: DUCT A | X12: DUCT B | AF12: DUCT A | AN12: DUCT B
D13: Moisture content | N13: %
D14: Gas temperature | N14: ℃
D15: Gas static pressure | N15: Pa
D16: Flow rate (wet) | N16: m3N/h
D17: Flow rate (dry) | N17: m3N/h
D18: Gas composition | J18: CO2 | N18: %
J19: O2 | N19: %
J20: CO | N20: %
J21: N2 | N21: %
D22: Dust concentration | N22: g/m3N
D23: Dust concentration | N23: g/m3N

Sheet Measurement Act
A1: 0 | B1: 611.21 | C1: =B1/1000 -> 0.61121 | F1: Measuring objects | G1: Measuring method 1,JIS number | H1: Measuring method 2
E2: 0 | G2: blank as below
A3: 1 | B3: 657.08 | C3: =B3/1000 -> 0.65708 | E3: 1 | F3: Dust concentration | G3: JIS Z 8808(2013) | H3: (Circular filter paper)
E4: 2 | F4: Dust concentration | G4: JIS Z 8808(2013) | H4: (Cylinder filter paper)
A5: 2 | B5: 705.97 | C5: =B5/1000 -> 0.70597 | E5: 3 | F5: Sulfur oxides concentration | G5: JIS K 0103(2011)-7.1 | H5: Ion chromatography
E6: 4 | F6: Sulfur oxides concentration | G6: JIS K 0103(2011)-7.2 | H6: Precipitation titrimetry (arsenazoⅢmethod)
A7: 3 | B7: 758.06 | C7: =B7/1000 -> 0.75806 | E7: 5 | F7: Sulfur oxides concentration | G7: JIS K 0103(2011)-8 | H7: Automated measuring method
E8: 6 | F8: Sulfur oxides concentration | G8: JIS K 0103(2011)-Annex JA (normative) | H8: Turbidimetry (light scattering method)
A9: 4 | B9: 813.52 | C9: =B9/1000 -> 0.81352 | E9: 7 | F9: Nitrogen oxides concentration | G9: JIS K 0104(2011)-7.1 | H9: Zinc reduction naphthyethylenediamine absorptiometry (Zn-NEDA method)
E10: 8 | F10: Nitrogen oxides concentration | G10: JIS K 0104(2011)-7.3 | H10: Ion chromatography
A11: 5 | B11: 872.54 | C11: =B11/1000 -> 0.87254 | E11: 9 | F11: Nitrogen oxides concentration | G11: JIS K 0104(2011)-7.4 | H11: Phenol disulfonic acid absorptiometry (PDS method)
E12: 10 | F12: Nitrogen oxides concentration | G12: JIS K 0104(2011)-7.5 | H12: Saltzman absorptiometry
A13: 6 | B13: 935.31 | C13: =B13/1000 -> 0.93531 | E13: 11 | F13: Nitrogen oxides concentration | G13: JIS K 0104(2011)-8 | H13: Automated measuring method：Chemiluminescence method
E14: 12 | F14: Oxygen concentration | G14: JIS K 0301(1998)-5.1 | H14: Chemical analysis：Orsat
A15: 7 | B15: 1002 | C15: =B15/1000 -> 1.002 | E15: 13 | F15: Oxygen concentration | G15: JIS K 0301(1998)-6 | H15: Automated measuring method：Zirconia
E16: 14 | F16: Oxygen concentration | G16: JIS K 0301(1998)-6 | H16: Automated measuring method：Magnetic force
A17: 8 | B17: 1072.9 | C17: =B17/1000 -> 1.0729 | E17: 15 | F17: Ammonia concentration | G17: JIS K 0099(2004)-7.1 | H17: Indophenol blue absorption spectrophotometry
E18: 16 | F18: Ammonia concentration | G18: JIS K 0099(2004)-7.2 | H18: Gas chromatography
A19: 9 | B19: 1148.2 | C19: =B19/1000 -> 1.1482 | E19: 17 | F19: Fluorine concentration | G19: JIS K 0105(1998)-6.1 | H19: Lanthanum-Alizarin complexone absorptiometry
E20: 18 | F20: Hydrogen fluoride concentration | G20: JIS K 0105(1998)-6.1 | H20: Lanthanum-Alizarin complexone absorptiometry
A21: 10 | B21: 1228.1 | C21: =B21/1000 -> 1.2281 | E21: 19 | F21: Chlorine concentration | G21: JIS K 0106(2010)-7.1 | H21: ABTS
E22: 20 | F22: Chlorine concentration | G22: JIS K 0106(2010)-7.2 | H22: PCP
A23: 11 | B23: 1312.9 | C23: =B23/1000 -> 1.3129 | E23: 21 | F23: Chlorine concentration | G23: JIS K 0106(2010)-7.3 | H23: Ion chromatography
E24: 22 | F24: Chlorine concentration | G24: JIS K 0106(2010)-Annex A (normative) | H24: o－Tolidine colorimetry
A25: 12 | B25: 1402.8 | C25: =B25/1000 -> 1.4028 | E25: 23 | F25: Hydrogen chloride concentration | G25: JIS K 0107(2002)-7.1 | H25: Ion chromatography
E26: 24 | F26: Hydrogen chloride concentration | G26: JIS K 0107(2002)-7.2 | H26: Silver-nitrate titration method
A27: 13 | B27: 1498 | C27: =B27/1000 -> 1.498 | E27: 25 | F27: Hydrogen chloride concentration | G27: JIS K 0107(2002)-Annex D (normative) | H27: Mercury (Ⅱ) thiocyanate absorptiometry
E28: 26 | F28: Carbon monoxide concentration | G28: JIS K 0098(1998)-5 | H28: Gas chromatography
A29: 14 | B29: 1598.9 | C29: =B29/1000 -> 1.5989 | E29: 27 | F29: Carbon monoxide concentration | G29: JIS K 0098(1998)-6 | H29: Detection tube
E30: 28 | F30: Carbon monoxide concentration | G30: JIS K 0098(1998)-7 | H30: Infrared absorption spectrophotometry
A31: 15 | B31: 1705.7 | C31: =B31/1000 -> 1.7057 | E31: 29 | F31: Hydrogen sulfide concentration | G31: JIS K 0108(2010)-8 | H31: Gas chromatography
E32: 30 | F32: Hydrogen sulfide concentration | G32: JIS K 0108(2010)-9 | H32: Methylene blue absorptiometry
A33: 16 | B33: 1818.7 | C33: =B33/1000 -> 1.8187 | E33: 31 | F33: Hydrogen cyanide concentration | G33: JIS K 0109(1998)-6 | H33: Gas chromatography
E34: 32 | F34: Hydrogen cyanide concentration | G34: JIS K 0109(1998)-7 | H34: 4-Pyridinecarboxylate-pyrazolone absorptiometry
A35: 17 | B35: 1938.3 | C35: =B35/1000 -> 1.9383 | E35: 33 | F35: Cadmium concentration | G35: JIS K 0083(2006)-7.1 | H35: Flame atomic absorption spectrometry
E36: 34 | F36: Cadmium concentration | G36: JIS K 0083(2006)-7.3 | H36: ICP atomic emission spectroscopy
A37: 18 | B37: 2064.7 | C37: =B37/1000 -> 2.0647 | E37: 35 | F37: Cadmium concentration | G37: JIS K 0083(2006)-7.4 | H37: ICP mass spectrometry
E38: 36 | F38: Lead concentration | G38: JIS K 0083(2006)-8.1 | H38: Flame atomic absorption spectrometry
A39: 19 | B39: 2198.2 | C39: =B39/1000 -> 2.1982 | E39: 37 | F39: Lead concentration | G39: JIS K 0083(2006)-8.3 | H39: ICP atomic emission spectroscopy
E40: 38 | F40: Lead concentration | G40: JIS K 0083(2006)-8.4 | H40: ICP mass spectrometry
...
