Workbook

Sheet Phuong phap
A1: TỔNG HỢP CÁC PHƯƠNG PHÁP SỬ DỤNG CHO HOẠT ĐỘNG QUAN TRẮC MÔI TRƯỜNG NƯỚC THẢI
A2: Số TT | B2: Thông số quan trắc | C2: Phương pháp sử dụng
A3: A | B3: HOẠT ĐỘNG QUAN TRẮC VÀ PHÂN TÍCH MÔI TRƯỜNG NƯỚC THẢI
A4: 1 | B4: Nhiệt độ | C4: SMEWW 2550B:2012
A5: 2 | B5: pH | C5: TCVN 6492:2011
A6: 3 | B6: Lưu lượng thải
A7: 4 | B7: TDS | C7: SMEWW 2540C:2012
A8: 5 | B8: Độ màu | C8: TCVN 6185: 2008
A9: 6 | B9: Nhu cầu oxy sinh hoá (BOD5) | C9: SMEWW 5210B: 2012
A10: 7 | B10: Nhu cầu oxy hoá học (COD) | C10: SMEWW 5220C: 2012
A11: 8 | B11: Chất rắn lơ lửng (SS) | C11: TCVN 6625-2000
A12: 9 | B12: Coliform. E.Coli | C12: TCVN 6187-1-2009
A13: 10 | B13: Coliform, E.Coli | C13: TCVN 6187-2- 2009
A14: 11 | B14: Tổng Dầu, mỡ khoáng | C14: SMEWW 5520B,C: 2012
A15: 12 | B15: Cyanua (CN-) | C15: TCVN 6181: 1996
A16: 13 | B16: Tổng P | C16: TCVN 6202: 2008
A17: 14 | B17: Tổng N | C17: TCVN 6638:2000
A18: 15 | B18: Nitơ amôn (NH4+) | C18: TCVN 6179-1:1996
... A36: 33 | B36: Phân tích đồng thời các kim loại | C36: TCVN 6665: 2011

Sheet DGL
A1: ĐƠN GIÁ TIỀN LƯƠNG LAO ĐỘNG KỸ THUẬT
A2: - Hệ số lương theo Nghị định số 204/2004/NĐ-CP ngày 14 tháng 12 năm 2004 của Chính phủ về chế độ tiền lương đối với cán bộ công chức, viên chức và lực lượng vũ trang và chế độ phụ cấp lương trong các công ty nhà nước; - Mức đóng các khoản bảo hiểm (BHXH, BHYT, BHTN) theo quy định tại Luật Bảo hiểm xã hội năm 2006; - Mức lương tối thiểu theo Nghị định số 99/2015/QH13 ngày 11 tháng 11 năm 2015 của Quốc hội khóa 13 quy định mức lương tối thiểu chung là 1.300.000 đồng /tháng; - Số ngày công trong 1 tháng là: 26 ngày
J3: 26 | K3: 1300000
A4: Số TT | B4: Mã hiệu | C4: Chức danh | D4: Hệ số lương | E4: Lương cấp bậc | F4: Lương phụ 11% | G4: Phụ cấp Lưu động (0,4) | H4: Phụ cấp Độc hại (0,1) | I4: Phụ cấp tổ trưởng 0,2/5 | J4: BHXH, YT, TN, KPCĐ | K4: Tổng cộng lương tháng | L4: Đơn giá tiền lương
A6: (1) | C6: (2) | D6: (3) | E6: (4) | F6: (5) = 11%*(4) | G6: (6) | H6: (7) | I6: (8) | J6: (9) = 23.5%*(4) | K6: (10)=9+4+5+6+7+8 | L6: (11)=(10)/26
A7: I | C7: NGOẠI NGHIỆP | F7: 0.11 | G7: 0.4 | H7: 0.1 | J7: 0.235
A8: 1 | B8: 1QTVTNMT hạng IV.2 | C8: Quan trắc viên tài nguyên môi trường hạng IV bậc 2 | D8: 2.41 | E8: =$K$3*D8 -> 3133000 | F8: =E8*$F$7 -> 344630 | G8: =$K$3*$G$7 -> 520000 | H8: =$K$3*$H$7 -> 130000 | I8: =$K$3*0/5 -> 0 | J8: =E8*$J$7 -> 736255 | K8: =SUM(E8:J8) -> 4863885 | L8: =K8/$J$3 -> 187072.5
A9: 2 | B9: 1QTVTNMT hạng IV.3 | C9: Quan trắc viên tài nguyên môi trường hạng IV bậc 3 | D9: 2.72 | E9: =$K$3*D9 -> 3536000 | F9: =E9*$F$7 -> 388960 | G9: =$K$3*$G$7 -> 520000 | H9: =$K$3*$H$7 -> 130000 | I9: =$K$3*0/5 -> 0 | J9: =E9*$J$7 -> 830960 | K9: =SUM(E9:J9) -> 5405920 | L9: =K9/$J$3 -> 207920
A10: 3 | B10: 1QTVTNMT hạng III.1 | C10: Quan trắc viên tài nguyên môi trường hạng III bậc 1 | D10: 2.34 | E10: =$K$3*D10 -> 3042000 | F10: =E10*$F$7 -> 334620 | G10: =$K$3*$G$7 -> 520000 | H10: =$K$3*$H$7 -> 130000 | I10: =$K$3*0/5 -> 0 | J10: =E10*$J$7 -> 714870 | K10: =SUM(E10:J10) -> 4741490 | L10: =K10/$J$3 -> 182365
A11: 4 | B11: 1QTVTNMT hạng III.2 | C11: Quan trắc viên tài nguyên môi trường hạng III bậc 2 | D11: 2.67 | E11: =$K$3*D11 -> 3471000 | F11: =E11*$F$7 -> 381810 | G11: =$K$3*$G$7 -> 520000 | H11: =$K$3*$H$7 -> 130000 | I11: =$K$3*0/5 -> 0 | J11: =E11*$J$7 -> 815685 | K11: =SUM(E11:J11) -> 5318495 | L11: =K11/$J$3 -> 204557.5
A12: 5 | B12: 1QTVTNMT hạng III.3 | C12: Quan trắc viên tài nguyên môi trường hạng III bậc 3 | D12: 3 | E12: =$K$3*D12 -> 3900000 | F12: =E12*$F$7 -> 429000 | G12: =$K$3*$G$7 -> 520000 | H12: =$K$3*$H$7 -> 130000 | I12: =$K$3*0/5 -> 0 | J12: =E12*$J$7 -> 916500 | K12: =SUM(E12:J12) -> 5895500 | L12: =K12/$J$3 -> 226750
A13: 6 | B13: 1QTVTNMT hạng III.4 | C13: Quan trắc viên tài nguyên môi trường hạng III bậc 4 | D13: 3.33 | E13: =$K$3*D13 -> 4329000 | F13: =E13*$F$7 -> 476190 | G13: =$K$3*$G$7 -> 520000 | H13: =$K$3*$H$7 -> 130000 | I13: =$K$3*0/5 -> 0 | J13: =E13*$J$7 -> 1017315 | K13: =SUM(E13:J13) -> 6472505 | L13: =K13/$J$3 -> 248942.5
A14: II | C14: NỘI NGHIỆP
A15: 1 | B15: 1QTVTNMT hạng IV.2a | C15: Quan trắc viên tài nguyên môi trường hạng IV bậc 2 | D15: 2.41 | E15: =$K$3*D15 -> 3133000 | F15: =E15*$F$7 -> 344630 | G15: =0*$K$3 -> 0 | H15: =$K$3*$H$7 -> 130000 | I15: =$K$3*0/5 -> 0 | J15: =E15*$J$7 -> 736255 | K15: =SUM(E15:J15) -> 4343885 | L15: =K15/$J$3 -> 167072.5
A16: 2 | B16: 1QTVTNMT hạng III.1a | C16: Quan trắc viên tài nguyên môi trường hạng III bậc 1 | D16: 2.34 | E16: =$K$3*D16 -> 3042000 | F16: =E16*$F$7 -> 334620 | G16: 0 | H16: =$K$3*$H$7 -> 130000 | I16: =$K$3*0/5 -> 0 | J16: =E16*$J$7 -> 714870 | K16: =SUM(E16:J16) -> 4221490 | L16: =K16/$J$3 -> 162365
A17: 3 | B17: 1QTVTNMT hạng III.2a | C17: Quan trắc viên tài nguyên môi trường hạng III bậc 2 | D17: 2.67 | E17: =$K$3*D17 -> 3471000 | F17: =E17*$F$7 -> 381810 | G17: =0*$K$3 -> 0 | H17: =$K$3*$H$7 -> 130000 | I17: =$K$3*0/5 -> 0 | J17: =E17*$J$7 -> 815685 | K17: =SUM(E17:J17) -> 4798495 | L17: =K17/$J$3 -> 184557.5
A18: 4 | B18: 1QTVTNMT hạng III.3a | C18: Quan trắc viên tài nguyên môi trường hạng III bậc 3 | D18: 3 | E18: =$K$3*D18 -> 3900000 | F18: =E18*$F$7 -> 429000 | G18: =0*$K$3 -> 0 | H18: =$K$3*$H$7 -> 130000 | I18: =$K$3*0/5 -> 0 | J18: =E18*$J$7 -> 916500 | K18: =SUM(E18:J18) -> 5375500 | L18: =K18/$J$3 -> 206750
A19: 5 | B19: 1QTVTNMT hạng III.4a | C19: Quan trắc viên tài nguyên môi trường hạng III bậc 4 | D19: 3.33 | E19: =$K$3*D19 -> 4329000 | F19: =E19*$F$7 -> 476190 | G19: =0*$K$3 -> 0 | H19: =$K$3*$H$7 -> 130000 | I19: =$K$3*0/5 -> 0 | J19: =E19*$J$7 -> 1017315 | K19: =SUM(E19:J19) -> 5952505 | L19: =K19/$J$3 -> 228942.5
A20: 6 | B20: 1QTVTNMT hạng III.5a | C20: Quan trắc viên tài nguyên môi trường hạng III bậc 5 | D20: 3.66 | E20: =$K$3*D20 -> 4758000 | F20: =E20*$F$7 -> 523380 | G20: =0*$K$3 -> 0 | H20: =$K$3*$H$7 -> 130000 | I20: =$K$3*0/5 -> 0 | J20: =E20*$J$7 -> 1118130 | K20: =SUM(E20:J20) -> 6529510 | L20: =K20/$J$3 -> 251135

Sheet LDKT
A1: CHI PHÍ NHÂN CÔNG (Hoạt động quan trắc môi trường nước thải)
F2: Đơn vị tính: đồng
A3: STT | B3: Mã hiệu | C3: Thông số quan trắc | D3: Định biên | E3: Định mức | F3: Đơn giá lương ngày | G3: Thành tiền
A4: A | B4: HOẠT ĐỘNG QUAN TRẮC VÀ PHÂN TÍCH MÔI TRƯỜNG NƯỚC THẢI
A5: A1 | B5: Công tác quan trắc môi trường nước thải tại hiện trường (1NT) | E5: 1.2 | G5: ĐV: Thông số
A6: 1 | B6: 1NT1 | C6: Nhiệt độ | D6: 1QTVTNMT hạng III.1 | E6: 0.2 | F6: =VLOOKUP(D6,DGL!$B$8:$L$203,11,0) -> 182365 | G6: =F6*E6*1.2 -> 43767.6 | I6: =F6*E6*1.2 -> 43767.6
A7: 2 | B7: 1NT2 | C7: pH | D7: 1QTVTNMT hạng III.1 | E7: 0.2 | F7: =VLOOKUP(D7,DGL!$B$8:$L$203,11,0) -> 182365 | G7: =F7*E7*1.2 -> 43767.6
A8: 3 | B8: 1NT3 | C8: Vận tốc | D8: 1QTVTNMT hạng III.2 | E8: 0.4 | F8: =VLOOKUP(D8,DGL!$B$8:$L$203,11,0) -> 204557.5 | G8: =F8*E8*1.2 -> 98187.6
A9: 4 | B9: 1NT4a | C9: TDS | D9: 1QTVTNMT hạng III.1 | E9: 0.2 | F9: =VLOOKUP(D9,DGL!$B$8:$L$203,11,0) -> 182365 | G9: =F9*E9*1.2 -> 43767.6
A10: 5 | B10: 1NT4b | C10: Độ màu | D10: 1QTVTNMT hạng III.1 | E10: 0.2 | F10: =VLOOKUP(D10,DGL!$B$8:$L$203,11,0) -> 182365 | G10: =F10*E10*1.2 -> 43767.6
A11: 6 | B11: 1NT5a | C11: Nhu cầu oxy sinh hoá (BOD5 | D11: 1QTVTNMT hạng III.1 | E11: 0.2 | F11: =VLOOKUP(D11,DGL!$B$8:$L$203,11,0) -> 182365 | G11: =F11*E11*1.2 -> 43767.6
A12: 7 | B12: 1NT5b | C12: Nhu cầu oxy hoá học (COD) | D12: 1QTVTNMT hạng III.1 | E12: 0.2 | F12: =VLOOKUP(D12,DGL!$B$8:$L$203,11,0) -> 182365 | G12: =F12*E12*1.2 -> 43767.6
A13: 8 | B13: 1NT6 | C13: Chất rắn lơ lửng (SS) | D13: 1QTVTNMT hạng III.1 | E13: 0.2 | F13: =VLOOKUP(D13,DGL!$B$8:$L$203,11,0) -> 182365 | G13: =F13*E13*1.2 -> 43767.6
A14: 9 | B14: 1NT7a | C14: Coliform | D14: 1QTVTNMT hạng III.2 | E14: 0.2 | F14: =VLOOKUP(D14,DGL!$B$8:$L$203,11,0) -> 204557.5 | G14: =F14*E14*1.2 -> 49093.8
A15: 10 | B15: 1NT7b | C15: E.Coli | D15: 1QTVTNMT hạng III.3 | E15: 0.2 | F15: =VLOOKUP(D15,DGL!$B$8:$L$203,11,0) -> 226750 | G15: =F15*E15*1.2 -> 54420
A16: 11 | B16: 1NT8 | C16: Tổng Dầu, mỡ khoáng | D16: 1QTVTNMT hạng III.3 | E16: 0.2 | F16: =VLOOKUP(D16,DGL!$B$8:$L$203,11,0) -> 226750 | G16: =F16*E16*1.2 -> 54420
A17: 12 | B17: 1NT9 | C17: Cyanua (CN-) | D17: 1QTVTNMT hạng III.2 | E17: 0.2 | F17: =VLOOKUP(D17,DGL!$B$8:$L$203,11,0) -> 204557.5 | G17: =F17*E17*1.2 -> 49093.8
A18: 13 | B18: 1NT10a | C18: Tổng P | D18: 1QTVTNMT hạng III.2 | E18: 0.2 | F18: =VLOOKUP(D18,DGL!$B$8:$L$203,11,0) -> 204557.5 | G18: =F18*E18*1.2 -> 49093.8
... A43: 38 | B43: 1NT13c | C43: PCBs | D43: 1QTVTNMT hạng III.3 | E43: 0.2 | F43: =VLOOKUP(D43,DGL!$B$8:$L$203,11,0) -> 226750 | G43: =F43*E43*1.2 -> 54420
A44: C2 | B44: Công tác phân tích môi trường nước thải trong phòng thí nghiệm (2NT)
A45: 1 | B45: 2NT5a | C45: Nhu cầu oxy sinh hoá (BOD5) | D45: 1QTVTNMT hạng III.1a | E45: 0.47 | F45: =VLOOKUP(D45,DGL!$B$8:$L$203,11,0) -> 162365 | G45: =E45*F45 -> 76311.55
A46: 2 | B46: 2NT5b | C46: Nhu cầu oxy hoá học (COD) | D46: 1QTVTNMT hạng III.1a | E46: 0.5 | F46: =VLOOKUP(D46,DGL!$B$8:$L$203,11,0) -> 162365 | G46: =E46*F46 -> 81182.5
A47: 3 | B47: 2NT6 | C47: Tổng chất rắn lơ lửng (TSS) | D47: 1QTVTNMT hạng III.1a | E47: 0.47 | F47: =VLOOKUP(D47,DGL!$B$8:$L$203,11,0) -> 162365 | G47: =E47*F47 -> 76311.55
A48: 4 | B48: 2NT7a1 | C48: Coliform | D48: 1QTVTNMT hạng III.2a | E48: 0.6 | F48: =VLOOKUP(D48,DGL!$B$8:$L$203,11,0) -> 184557.5 | G48: =E48*F48 -> 110734.5
A49: 5 | B49: 2NT7a2 | C49: Coliform | D49: 1QTVTNMT hạng III.2a | E49: 0.6 | F49: =VLOOKUP(D49,DGL!$B$8:$L$203,11,0) -> 184557.5 | G49: =E49*F49 -> 110734.5
A50: 6 | B50: 2NT7b1 | C50: E.Coli | D50: 1QTVTNMT hạng III.2a | E50: 0.6 | F50: =VLOOKUP(D50,DGL!$B$8:$L$203,11,0) -> 184557.5 | G50: =E50*F50 -> 110734.5
A51: 7 | B51: 2NT7b2 | C51: E.Coli | D51: 1QTVTNMT hạng III.2a | E51: 0.6 | F51: =VLOOKUP(D51,DGL!$B$8:$L$203,11,0) -> 184557.5 | G51: =E51*F51 -> 110734.5
A52: 8 | B52: 2NT8 | C52: Tổng Dầu, mỡ khoáng | D52: 1QTVTNMT hạng III.2a | E52: 0.6 | F52: =VLOOKUP(D52,DGL!$B$8:$L$203,11,0) -> 184557.5 | G52: =E52*F52 -> 110734.5
A53: 9 | B53: 2NT9 | C53: Cyanua (CN-) | D53: 1QTVTNMT hạng III.2a | E53: 0.62 | F53: =VLOOKUP(D53,DGL!$B$8:$L$203,11,0) -> 184557.5 | G53: =E53*F53 -> 114425.65
A54: 10 | B54: 2NT10a | C54: Tổng P | D54: 1QTVTNMT hạng III.2a | E54: 0.62 | F54: =VLOOKUP(D54,DGL!$B$8:$L$203,11,0) -> 184557.5 | G54: =E54*F54 -> 114425.65
A55: 11 | B55: 2NT10b | C55: Tổng N | D55: 1QTVTNMT hạng III.2a | E55: 0.62 | F55: =VLOOKUP(D55,DGL!$B$8:$L$203,11,0) -> 184557.5 | G55: =E55*F55 -> 114425.65
A56: 12 | B56: 2NT10c | C56: Nitơ amôn (NH4+) | D56: 1QTVTNMT hạng III.1a | E56: 0.5 | F56: =VLOOKUP(D56,DGL!$B$8:$L$203,11,0) -> 162365 | G56: =E56*F56 -> 81182.5
... A80: 36 | B80: 2NT14 | C80: Phân tích đồng thời các kim loại ( giá tính cho 01 mẫu) | D80: 1QTVTNMT hạng III.3a | E80: 1 | F80: =VLOOKUP(D80,DGL!$B$8:$L$203,11,0) -> 206750 | G80: =E80*F80 -> 206750

Sheet Dcu
A1: CHI PHÍ CÔNG CỤ, DỤNG CỤ (Hoạt động quan trắc môi trường nước thải)
F2: ĐVT: Đồng
A3: STT | B3: Danh mục dụng cụ | C3: Đơn vị tính | D3: Thời hạn | E3: Định mức | F3: Ðơn giá (đồng) | G3: Thành tiền (đồng)
D4: (tháng)
A5: A | B5: HOẠT ĐỘNG QUAN TRẮC VÀ PHÂN TÍCH MÔI TRƯỜNG NƯỚC THẢI
A6: A1 | B6: Công tác quan trắc môi trường nước thải tại hiện trường (1NT) | G6: ĐV: Thông số
A7: 1NT1 | B7: pH | G7: =SUM(G8:G18)*1.05 -> 2850.3462
A8: 1 | B8: Đầu đo | C8: cái | D8: =VLOOKUP(B8,[1]Dcu!$B$3:$D$511,3,0) -> 6 | E8: 0.048 | F8: =VLOOKUP(B8,[1]Dcu!$B$3:$E$511,4,0) -> 2500000 | G8: =F8/(D8*26)*E8 -> 769.23077
A9: 2 | B9: Quần áo BHLĐ | C9: bộ | D9: =VLOOKUP(B9,[1]Dcu!$B$3:$D$511,3,0) -> 12 | E9: 0.096 | F9: =VLOOKUP(B9,[1]Dcu!$B$3:$E$511,4,0) -> 50000 | G9: =F9/(D9*26)*E9 -> 15.384615
A10: 3 | B10: Giầy BHLĐ | C10: đôi | D10: =VLOOKUP(B10,[1]Dcu!$B$3:$D$511,3,0) -> 6 | E10: 0.096 | F10: =VLOOKUP(B10,[1]Dcu!$B$3:$E$511,4,0) -> 25000 | G10: =F10/(D10*26)*E10 -> 15.384615
A11: 4 | B11: Tất sợi | C11: đôi | D11: =VLOOKUP(B11,[1]Dcu!$B$3:$D$511,3,0) -> 6 | E11: 0.096 | F11: =VLOOKUP(B11,[1]Dcu!$B$3:$E$511,4,0) -> 7000 | G11: =F11/(D11*26)*E11 -> 4.3076923
A12: 5 | B12: Mũ cứng | C12: cái | D12: =VLOOKUP(B12,[1]Dcu!$B$3:$D$511,3,0) -> 12 | E12: 0.096 | F12: =VLOOKUP(B12,[1]Dcu!$B$3:$E$511,4,0) -> 20000 | G12: =F12/(D12*26)*E12 -> 6.1538462
A13: 6 | B13: Ô che mưa, che nắng | C13: cái | D13: =VLOOKUP(B13,[1]Dcu!$B$3:$D$511,3,0) -> 24 | E13: 0.048 | F13: =VLOOKUP(B13,[1]Dcu!$B$3:$E$511,4,0) -> 110000 | G13: =F13/(D13*26)*E13 -> 8.4615385
A14: 7 | B14: Bản đồ địa hình | C14: cái | D14: =VLOOKUP(B14,[1]Dcu!$B$3:$D$511,3,0) -> 3 | E14: 0.048 | F14: =VLOOKUP(B14,[1]Dcu!$B$3:$E$511,4,0) -> 70000 | G14: =F14/(D14*26)*E14 -> 43.076923
A15: 8 | B15: Khẩu trang y tế | C15: hộp | D15: =VLOOKUP(B15,[1]Dcu!$B$3:$D$511,3,0) -> 0.3 | E15: 0.02 | F15: =VLOOKUP(B15,[1]Dcu!$B$3:$E$511,4,0) -> 400000 | G15: =F15/(D15*26)*E15 -> 1025.641
A16: 9 | B16: Găng tay y tế | C16: hộp | D16: =VLOOKUP(B16,[1]Dcu!$B$3:$D$511,3,0) -> 0.3 | E16: 0.02 | F16: =VLOOKUP(B16,[1]Dcu!$B$3:$E$511,4,0) -> 200000 | G16: =F16/(D16*26)*E16 -> 512.82051
A17: 11 | B17: Bàn lưu động | C17: cái | D17: =VLOOKUP(B17,[1]Dcu!$B$3:$D$511,3,0) -> 60 | E17: 0.048 | F17: =VLOOKUP(B17,[1]Dcu!$B$3:$E$511,4,0) -> 210000 | G17: =F17/(D17*26)*E17 -> 6.4615385
A18: 13 | B18: Đai bảo hiểm | C18: cái | D18: =VLOOKUP(B18,[1]Dcu!$B$3:$D$511,3,0) -> 6 | E18: 0.048 | F18: =VLOOKUP(B18,[1]Dcu!$B$3:$E$511,4,0) -> 1000000 | G18: =F18/(D18*26)*E18 -> 307.69231
A19: 1NT2 | B19: Nhiệt độ | E19: Như mục 1NT1 | G19: =G7 -> 2850.3462
A20: 1NT3 | B20: Vận tốc | G20: =SUM(G21:G32)*1.1 -> 3102.5077
A21: 1 | B21: Đầu đo | C21: cái | D21: =VLOOKUP(B21,[1]Dcu!$B$3:$D$511,3,0) -> 6 | E21: 0.048 | F21: =VLOOKUP(B21,[1]Dcu!$B$3:$E$511,4,0) -> 2500000 | G21: =F21/(D21*26)*E21 -> 769.23077
A22: 2 | B22: Máng đo tiêu chuẩn | C22: cái | D22: =VLOOKUP(B22,[1]Dcu!$B$3:$D$511,3,0) -> 9 | E22: 0.048 | F22: =VLOOKUP(B22,[1]Dcu!$B$3:$E$511,4,0) -> 2000000 | G22: =F22/(D22*26)*E22 -> 410.25641
A23: 3 | B23: Cốc nhựa | C23: cái | D23: =VLOOKUP(B23,[1]Dcu!$B$3:$D$511,3,0) -> 36 | E23: 0.048 | F23: =VLOOKUP(B23,[1]Dcu!$B$3:$E$511,4,0) -> 80000 | G23: =F23/(D23*26)*E23 -> 4.1025641
A24: 4 | B24: Bình tia | C24: cái | D24: =VLOOKUP(B24,[1]Dcu!$B$3:$D$511,3,0) -> 36 | E24: 0.048 | F24: =VLOOKUP(B24,[1]Dcu!$B$3:$E$511,4,0) -> 110000 | G24: =F24/(D24*26)*E24 -> 5.6410256
A25: 5 | B25: Quần áo BHLĐ | C25: bộ | D25: =VLOOKUP(B25,[1]Dcu!$B$3:$D$511,3,0) -> 12 | E25: 0.096 | F25: =VLOOKUP(B25,[1]Dcu!$B$3:$E$511,4,0) -> 50000 | G25: =F25/(D25*26)*E25 -> 15.384615
A26: 6 | B26: Giầy BHLĐ | C26: đôi | D26: =VLOOKUP(B26,[1]Dcu!$B$3:$D$511,3,0) -> 6 | E26: 0.096 | F26: =VLOOKUP(B26,[1]Dcu!$B$3:$E$511,4,0) -> 25000 | G26: =F26/(D26*26)*E26 -> 15.384615
A27: 7 | B27: Tất sợi | C27: đôi | D27: =VLOOKUP(B27,[1]Dcu!$B$3:$D$511,3,0) -> 6 | E27: 0.096 | F27: =VLOOKUP(B27,[1]Dcu!$B$3:$E$511,4,0) -> 7000 | G27: =F27/(D27*26)*E27 -> 4.3076923
A28: 8 | B28: Mũ cứng | C28: cái | D28: =VLOOKUP(B28,[1]Dcu!$B$3:$D$511,3,0) -> 12 | E28: 0.096 | F28: =VLOOKUP(B28,[1]Dcu!$B$3:$E$511,4,0) -> 20000 | G28: =F28/(D28*26)*E28 -> 6.1538462
A29: 9 | B29: Ô che mưa, che nắng | C29: cái | D29: =VLOOKUP(B29,[1]Dcu!$B$3:$D$511,3,0) -> 24 | E29: 0.048 | F29: =VLOOKUP(B29,[1]Dcu!$B$3:$E$511,4,0) -> 110000 | G29: =F29/(D29*26)*E29 -> 8.4615385
A30: 10 | B30: Bản đồ địa hình | C30: cái | D30: =VLOOKUP(B30,[1]Dcu!$B$3:$D$511,3,0) -> 3 | E30: 0.048 | F30: =VLOOKUP(B30,[1]Dcu!$B$3:$E$511,4,0) -> 70000 | G30: =F30/(D30*26)*E30 -> 43.076923
A31: 11 | B31: Khẩu trang y tế | C31: hộp | D31: =VLOOKUP(B31,[1]Dcu!$B$3:$D$511,3,0) -> 0.3 | E31: 0.02 | F31: =VLOOKUP(B31,[1]Dcu!$B$3:$E$511,4,0) -> 400000 | G31: =F31/(D31*26)*E31 -> 1025.641
A32: 12 | B32: Găng tay y tế | C32: hộp | D32: =VLOOKUP(B32,[1]Dcu!$B$3:$D$511,3,0) -> 0.3 | E32: 0.02 | F32: =VLOOKUP(B32,[1]Dcu!$B$3:$E$511,4,0) -> 200000 | G32: =F32/(D32*26)*E32 -> 512.82051
A33: 1NT4a | B33: TDS | G33: =SUM(G34:G46)*1.05 -> 4655.4846
A34: 1 | B34: Chai đựng hóa chất | C34: cái | D34: =VLOOKUP(B34,[1]Dcu!$B$3:$D$511,3,0) -> 12 | E34: 0.048 | F34: =VLOOKUP(B34,[1]Dcu!$B$3:$E$511,4,0) -> 100000 | G34: =F34/(D34*26)*E34 -> 15.384615
A35: 2 | B35: Chai đựng mẫu | C35: cái | D35: =VLOOKUP(B35,[1]Dcu!$B$3:$D$511,3,0) -> 12 | E35: 0.048 | F35: =VLOOKUP(B35,[1]Dcu!$B$3:$E$511,4,0) -> 80000 | G35: =F35/(D35*26)*E35 -> 12.307692
A36: 3 | B36: Bình tia | C36: cái | D36: =VLOOKUP(B36,[1]Dcu!$B$3:$D$511,3,0) -> 36 | E36: 0.048 | F36: =VLOOKUP(B36,[1]Dcu!$B$3:$E$511,4,0) -> 110000 | G36: =F36/(D36*26)*E36 -> 5.6410256
A37: 4 | B37: Quần áo BHLĐ | C37: bộ | D37: =VLOOKUP(B37,[1]Dcu!$B$3:$D$511,3,0) -> 12 | E37: 0.096 | F37: =VLOOKUP(B37,[1]Dcu!$B$3:$E$511,4,0) -> 50000 | G37: =F37/(D37*26)*E37 -> 15.384615
A38: 5 | B38: Giầy BHLĐ | C38: đôi | D38: =VLOOKUP(B38,[1]Dcu!$B$3:$D$511,3,0) -> 6 | E38: 0.096 | F38: =VLOOKUP(B38,[1]Dcu!$B$3:$E$511,4,0) -> 25000 | G38: =F38/(D38*26)*E38 -> 15.384615
A39: 6 | B39: Tất sợi | C39: đôi | D39: =VLOOKUP(B39,[1]Dcu!$B$3:$D$511,3,0) -> 6 | E39: 0.096 | F39: =VLOOKUP(B39,[1]Dcu!$B$3:$E$511,4,0) -> 7000 | G39: =F39/(D39*26)*E39 -> 4.3076923
A40: 7 | B40: Mũ cứng | C40: cái | D40: =VLOOKUP(B40,[1]Dcu!$B$3:$D$511,3,0) -> 12 | E40: 0.096 | F40: =VLOOKUP(B40,[1]Dcu!$B$3:$E$511,4,0) -> 20000 | G40: =F40/(D40*26)*E40 -> 6.1538462
...

Sheet VL
A1: PHỤ LỤC 1.3
A2: CHI PHÍ VẬT LIỆU (Hoạt động quan trắc môi trường nước thải)
F3: ĐVT: Đồng
B4: STT | C4: Danh mục vật tư | D4: Đơn vị tính | E4: Định mức | F4: Đơn giá | G4: Thành tiền
A5: A | B5: HOẠT ĐỘNG QUAN TRẮC VÀ PHÂN TÍCH MÔI TRƯỜNG NƯỚC THẢI
A6: A1 | B6: Công tác quan trắc môi trường nước thải tại hiện trường (1NT)
A7: 1 | B7: 1NT1 | C7: Nhiệt độ | G7: =SUM(G8:G14)*1.08 -> 57834
B8: 1 | C8: Nước cất | D8: lít | E8: 0.1 | F8: =VLOOKUP(C8,[1]VL!$B$3:$E$524,4,0) -> 5000 | G8: =F8*E8 -> 500
B9: 2 | C9: Pin chuyên dụng | D9: cục | E9: 0.5 | F9: =VLOOKUP(C9,[1]VL!$B$3:$E$524,4,0) -> 25000 | G9: =F9*E9 -> 12500
B10: 3 | C10: Cồn lau dụng cụ | D10: ml | E10: 10 | F10: =VLOOKUP(C10,[1]VL!$B$3:$E$524,4,0) -> 35 | G10: =F10*E10 -> 350
B11: 4 | C11: Sổ công tác | D11: cuốn | E11: 0.005 | F11: =VLOOKUP(C11,[1]VL!$B$3:$E$524,4,0) -> 10000 | G11: =F11*E11 -> 50
B12: 5 | C12: Nước rửa đầu đo | D12: lít | E12: 0.1 | F12: =VLOOKUP(C12,[1]VL!$B$3:$E$524,4,0) -> 390000 | G12: =F12*E12 -> 39000
B13: 6 | C13: Cồn lau dụng cụ | D13: ml | E13: 10 | F13: =VLOOKUP(C13,[1]VL!$B$3:$E$524,4,0) -> 35 | G13: =F13*E13 -> 350
B14: 7 | C14: Giấy lau | D14: hộp | E14: 0.02 | F14: =VLOOKUP(C14,[1]VL!$B$3:$E$524,4,0) -> 40000 | G14: =F14*E14 -> 800
A15: 2 | B15: 1NT2 | C15: pH | G15: =SUM(G16:G22)*1.08 -> 87156
B16: 1 | C16: Nước cất | D16: lít | E16: 0.1 | F16: =VLOOKUP(C16,[1]VL!$B$3:$E$524,4,0) -> 5000 | G16: =F16*E16 -> 500
B17: 2 | C17: Dung dịch chuẩn pH ở giá trị pH = 4 và pH = 10 | D17: ml | E17: 5 | F17: =VLOOKUP(C17,[1]VL!$B$3:$E$524,4,0) -> 5500 | G17: =F17*E17 -> 27500
B18: 3 | C18: Pin chuyên dụng | D18: cục | E18: 0.5 | F18: =VLOOKUP(C18,[1]VL!$B$3:$E$524,4,0) -> 25000 | G18: =F18*E18 -> 12500
B19: 4 | C19: Cồn lau dụng cụ | D19: ml | E19: 10 | F19: =VLOOKUP(C19,[1]VL!$B$3:$E$524,4,0) -> 35 | G19: =F19*E19 -> 350
B20: 5 | C20: Sổ công tác | D20: cuốn | E20: 0.005 | F20: =VLOOKUP(C20,[1]VL!$B$3:$E$524,4,0) -> 10000 | G20: =F20*E20 -> 50
B21: 6 | C21: Giấy lau | D21: hộp | E21: 0.02 | F21: =VLOOKUP(C21,[1]VL!$B$3:$E$524,4,0) -> 40000 | G21: =F21*E21 -> 800
B22: 7 | C22: Nước rửa đầu đo | D22: lít | E22: 0.1 | F22: =VLOOKUP(C22,[1]VL!$B$3:$E$524,4,0) -> 390000 | G22: =F22*E22 -> 39000
A23: 3 | B23: 1NT3 | C23: Vận tốc | G23: =SUM(G24:G27)*1.08 -> 2646
B24: 1 | C24: Pin chuyên dụng | D24: cục | E24: 0.05 | F24: =VLOOKUP(C24,[1]VL!$B$3:$E$524,4,0) -> 25000 | G24: =F24*E24 -> 1250
B25: 2 | C25: Sổ công tác | D25: cuốn | E25: 0.005 | F25: =VLOOKUP(C25,[1]VL!$B$3:$E$524,4,0) -> 10000 | G25: =F25*E25 -> 50
B26: 3 | C26: Cồn lau dụng cụ | D26: ml | E26: 10 | F26: =VLOOKUP(C26,[1]VL!$B$3:$E$524,4,0) -> 35 | G26: =F26*E26 -> 350
B27: 4 | C27: Giấy lau | D27: hộp | E27: 0.02 | F27: =VLOOKUP(C27,[1]VL!$B$3:$E$524,4,0) -> 40000 | G27: =F27*E27 -> 800
A28: 4 | B28: 1NT4a | C28: TDS | G28: =SUM(G29:G33)*1.08 -> 70416
B29: 1 | C29: Dung dịch chuẩn 1000 Pt-Co | D29: ml | E29: 5 | F29: =VLOOKUP(C29,[1]VL!$B$3:$E$524,4,0) -> 5000 | G29: =F29*E29 -> 25000
B30: 2 | C30: Nước rửa đầu đo | D30: lít | E30: 0.1 | F30: =VLOOKUP(C30,[1]VL!$B$3:$E$524,4,0) -> 390000 | G30: =F30*E30 -> 39000
B31: 3 | C31: Cồn lau dụng cụ | D31: ml | E31: 10 | F31: =VLOOKUP(C31,[1]VL!$B$3:$E$524,4,0) -> 35 | G31: =F31*E31 -> 350
B32: 4 | C32: Sổ công tác | D32: cuốn | E32: 0.005 | F32: =VLOOKUP(C32,[1]VL!$B$3:$E$524,4,0) -> 10000 | G32: =F32*E32 -> 50
B33: 5 | C33: Giấy lau | D33: hộp | E33: 0.02 | F33: =VLOOKUP(C33,[1]VL!$B$3:$E$524,4,0) -> 40000 | G33: =F33*E33 -> 800
A34: 5 | B34: 1NT4b | C34: Độ màu | D34: Như mục 1NT4a | G34: =G28 -> 70416
A35: 6 | B35: 1NT5a | C35: Nhu cầu oxy sinh hóa (BOD5) | G35: =SUM(G36:G39)*1.08 -> 28458
B36: 1 | C36: Đá khô | D36: túi | E36: 0.5 | F36: =VLOOKUP(C36,[1]VL!$B$3:$E$524,4,0) -> 50000 | G36: =F36*E36 -> 25000
B37: 2 | C37: Sổ công tác | D37: cuốn | E37: 0.005 | F37: =VLOOKUP(C37,[1]VL!$B$3:$E$524,4,0) -> 10000 | G37: =F37*E37 -> 50
B38: 3 | C38: Bút ghi kính | D38: cái | E38: 0.05 | F38: =VLOOKUP(C38,[1]VL!$B$3:$E$524,4,0) -> 10000 | G38: =F38*E38 -> 500
B39: 4 | C39: Giấy lau | D39: hộp | E39: 0.02 | F39: =VLOOKUP(C39,[1]VL!$B$3:$E$524,4,0) -> 40000 | G39: =F39*E39 -> 800
A40: 7 | B40: 1NT5b | C40: Nhu cầu oxy hoá học (COD) | G40: =SUM(G41:G46)*1.08 -> 37638
...

Sheet TB
A1: TT | B1: Mã hiệu | C1: Danh mục thiết bị | D1: Đơn vị tính | E1: Công suất (Kw) | F1: Định mức (Ca) | G1: Mức KH/ca | H1: Nguyên giá (đồng) | I1: Thành tiền (đồng)
A2: A | B2: HOẠT ĐỘNG QUAN TRẮC VÀ PHÂN TÍCH MÔI TRƯỜNG NƯỚC THẢI
A3: A1 | B3: Công tác quan trắc môi trường nước thải tại hiện trường (1NT) | J3: 250
A4: 1 | B4: 1NT1 | C4: Nhiệt độ nước | I4: =SUM(I5:I9) -> 2672.5024
B5: 1 | C5: Thiết bị lấy mẫu nước | D5: bộ | F5: 0.036 | G5: =H5/(J5*$J$3) -> 41160 | H5: =VLOOKUP(C5,[1]TB!$B$3:$D$503,3,0) -> 51450000 | I5: =F5*G5 -> 1481.76 | J5: =VLOOKUP(C5,[1]TB!$B$3:$E$205,4,0) -> 5
B6: 2 | C6: Thiết bị đo hiện số | D6: bộ | E6: Pin khô | F6: 0.036 | G6: =H6/(J6*$J$3) -> 13538.4 | H6: =VLOOKUP(C6,[1]TB!$B$3:$D$503,3,0) -> 16923000 | I6: =F6*G6 -> 487.3824 | J6: =VLOOKUP(C6,[1]TB!$B$3:$E$205,4,0) -> 5
B7: 3 | C7: Máy định vị GPS cầm tay | D7: bộ | E7: Pin khô | F7: 0.036 | G7: =H7/(J7*$J$3) -> 8360 | H7: =VLOOKUP(C7,[1]TB!$B$3:$D$503,3,0) -> 10450000 | I7: =F7*G7 -> 300.96 | J7: =VLOOKUP(C7,[1]TB!$B$3:$E$205,4,0) -> 5
B8: 4 | C8: Máy ảnh kỹ thuật số | D8: cái | E8: Pin khô | F8: 0.02 | G8: =H8/(J8*$J$3) -> 2520 | H8: =VLOOKUP(C8,[1]TB!$B$3:$D$503,3,0) -> 3150000 | I8: =F8*G8 -> 50.4 | J8: =VLOOKUP(C8,[1]TB!$B$3:$E$205,4,0) -> 5
B9: 5 | C9: Máy khuấy từ | D9: cái | F9: 0.02 | G9: =H9/(J9*$J$3) -> 17600 | H9: =VLOOKUP(C9,[1]TB!$B$3:$D$503,3,0) -> 22000000 | I9: =F9*G9 -> 352 | J9: =VLOOKUP(C9,[1]TB!$B$3:$E$205,4,0) -> 5
A10: 2 | B10: 1NT2 | C10: pH | I10: =SUM(I11:I15) -> 2672.5024
B11: 1 | C11: Thiết bị lấy mẫu nước | D11: bộ | F11: 0.036 | G11: =H11/(J11*$J$3) -> 41160 | H11: =VLOOKUP(C11,[1]TB!$B$3:$D$503,3,0) -> 51450000 | I11: =F11*G11 -> 1481.76 | J11: =VLOOKUP(C11,[1]TB!$B$3:$E$205,4,0) -> 5
B12: 2 | C12: Thiết bị đo hiện số | D12: bộ | E12: Pin khô | F12: 0.036 | G12: =H12/(J12*$J$3) -> 13538.4 | H12: =VLOOKUP(C12,[1]TB!$B$3:$D$503,3,0) -> 16923000 | I12: =F12*G12 -> 487.3824 | J12: =VLOOKUP(C12,[1]TB!$B$3:$E$205,4,0) -> 5
B13: 3 | C13: Máy định vị GPS cầm tay | D13: bộ | E13: Pin khô | F13: 0.036 | G13: =H13/(J13*$J$3) -> 8360 | H13: =VLOOKUP(C13,[1]TB!$B$3:$D$503,3,0) -> 10450000 | I13: =F13*G13 -> 300.96 | J13: =VLOOKUP(C13,[1]TB!$B$3:$E$205,4,0) -> 5
B14: 4 | C14: Máy khuấy từ | D14: cái | F14: 0.02 | G14: =H14/(J14*$J$3) -> 17600 | H14: =VLOOKUP(C14,[1]TB!$B$3:$D$503,3,0) -> 22000000 | I14: =F14*G14 -> 352 | J14: =VLOOKUP(C14,[1]TB!$B$3:$E$205,4,0) -> 5
B15: 5 | C15: Máy ảnh kỹ thuật số | D15: cái | E15: Pin khô | F15: 0.02 | G15: =H15/(J15*$J$3) -> 2520 | H15: =VLOOKUP(C15,[1]TB!$B$3:$D$503,3,0) -> 3150000 | I15: =F15*G15 -> 50.4 | J15: =VLOOKUP(C15,[1]TB!$B$3:$E$205,4,0) -> 5
A16: 3 | B16: 1NT3 | C16: Vận tốc | I16: =SUM(I17:I19) -> 838.7424
B17: 1 | C17: Thiết bị đo hiện số | D17: bộ | E17: Pin khô | F17: 0.036 | G17: =H17/(J17*$J$3) -> 13538.4 | H17: =VLOOKUP(C17,[1]TB!$B$3:$D$503,3,0) -> 16923000 | I17: =F17*G17 -> 487.3824 | J17: =VLOOKUP(C17,[1]TB!$B$3:$E$205,4,0) -> 5
B18: 2 | C18: Máy định vị GPS cầm tay | D18: bộ | E18: Pin khô | F18: 0.036 | G18: =H18/(J18*$J$3) -> 8360 | H18: =VLOOKUP(C18,[1]TB!$B$3:$D$503,3,0) -> 10450000 | I18: =F18*G18 -> 300.96 | J18: =VLOOKUP(C18,[1]TB!$B$3:$E$205,4,0) -> 5
B19: 3 | C19: Máy ảnh kỹ thuật số | D19: cái | E19: Pin khô | F19: 0.02 | G19: =H19/(J19*$J$3) -> 2520 | H19: =VLOOKUP(C19,[1]TB!$B$3:$D$503,3,0) -> 3150000 | I19: =F19*G19 -> 50.4 | J19: =VLOOKUP(C19,[1]TB!$B$3:$E$205,4,0) -> 5
A20: 4 | B20: 1NT4a | C20: TDS | I20: =SUM(I21:I23) -> 838.7424
B21: 1 | C21: Thiết bị đo hiện số | D21: bộ | E21: Pin khô | F21: 0.036 | G21: =H21/(J21*$J$3) -> 13538.4 | H21: =VLOOKUP(C21,[1]TB!$B$3:$D$503,3,0) -> 16923000 | I21: =F21*G21 -> 487.3824 | J21: =VLOOKUP(C21,[1]TB!$B$3:$E$205,4,0) -> 5
B22: 2 | C22: Máy định vị GPS cầm tay | D22: bộ | E22: Pin khô | F22: 0.036 | G22: =H22/(J22*$J$3) -> 8360 | H22: =VLOOKUP(C22,[1]TB!$B$3:$D$503,3,0) -> 10450000 | I22: =F22*G22 -> 300.96 | J22: =VLOOKUP(C22,[1]TB!$B$3:$E$205,4,0) -> 5
B23: 3 | C23: Máy ảnh kỹ thuật số | D23: cái | E23: Pin khô | F23: 0.02 | G23: =H23/(J23*$J$3) -> 2520 | H23: =VLOOKUP(C23,[1]TB!$B$3:$D$503,3,0) -> 3150000 | I23: =F23*G23 -> 50.4 | J23: =VLOOKUP(C23,[1]TB!$B$3:$E$205,4,0) -> 5
A24: 5 | B24: 1NT4b | C24: Độ màu | D24: Như mục 1NT4a | I24: =I20 -> 838.7424
A25: 6 | B25: 1NT5a | C25: Nhu cầu oxy sinh hóa (BOD5) | I25: =SUM(I26:I28) -> 1833.12
B26: 1 | C26: Thiết bị lấy mẫu nước | D26: bộ | F26: 0.036 | G26: =H26/(J26*$J$3) -> 41160 | H26: =VLOOKUP(C26,[1]TB!$B$3:$D$503,3,0) -> 51450000 | I26: =F26*G26 -> 1481.76 | J26: =VLOOKUP(C26,[1]TB!$B$3:$E$205,4,0) -> 5
B27: 2 | C27: Máy định vị GPS cầm tay | D27: bộ | E27: Pin khô | F27: 0.036 | G27: =H27/(J27*$J$3) -> 8360 | H27: =VLOOKUP(C27,[1]TB!$B$3:$D$503,3,0) -> 10450000 | I27: =F27*G27 -> 300.96 | J27: =VLOOKUP(C27,[1]TB!$B$3:$E$205,4,0) -> 5
B28: 3 | C28: Máy ảnh kỹ thuật số | D28: cái | E28: Pin khô | F28: 0.02 | G28: =H28/(J28*$J$3) -> 2520 | H28: =VLOOKUP(C28,[1]TB!$B$3:$D$503,3,0) -> 3150000 | I28: =F28*G28 -> 50.4 | J28: =VLOOKUP(C28,[1]TB!$B$3:$E$205,4,0) -> 5
A29: 7 | B29: 1NT5b | C29: Nhu cầu oxy hoá học (COD) | I29: =SUM(I30:I32) -> 1833.12
B30: 1 | C30: Thiết bị lấy mẫu nước | D30: bộ | F30: 0.036 | G30: =H30/(J30*$J$3) -> 41160 | H30: =VLOOKUP(C30,[1]TB!$B$3:$D$503,3,0) -> 51450000 | I30: =F30*G30 -> 1481.76 | J30: =VLOOKUP(C30,[1]TB!$B$3:$E$205,4,0) -> 5
B31: 2 | C31: Máy định vị GPS cầm tay | D31: bộ | E31: Pin khô | F31: 0.036 | G31: =H31/(J31*$J$3) -> 8360 | H31: =VLOOKUP(C31,[1]TB!$B$3:$D$503,3,0) -> 10450000 | I31: =F31*G31 -> 300.96 | J31: =VLOOKUP(C31,[1]TB!$B$3:$E$205,4,0) -> 5
B32: 3 | C32: Máy ảnh kỹ thuật số | D32: cái | E32: Pin khô | F32: 0.02 | G32: =H32/(J32*$J$3) -> 2520 | H32: =VLOOKUP(C32,[1]TB!$B$3:$D$503,3,0) -> 3150000 | I32: =F32*G32 -> 50.4 | J32: =VLOOKUP(C32,[1]TB!$B$3:$E$205,4,0) -> 5
A33: 8 | B33: 1NT6 | C33: Chất rắn lơ lửng (SS) | I33: =SUM(I34:I36) -> 1833.12
B34: 1 | C34: Thiết bị lấy mẫu nước | D34: bộ | F34: 0.036 | G34: =H34/(J34*$J$3) -> 41160 | H34: =VLOOKUP(C34,[1]TB!$B$3:$D$503,3,0) -> 51450000 | I34: =F34*G34 -> 1481.76 | J34: =VLOOKUP(C34,[1]TB!$B$3:$E$205,4,0) -> 5
B35: 2 | C35: Thiết bị định vị GPS | D35: bộ | E35: Pin khô | F35: 0.036 | G35: =H35/(J35*$J$3) -> 8360 | H35: =VLOOKUP(C35,[1]TB!$B$3:$D$503,3,0) -> 10450000 | I35: =F35*G35 -> 300.96 | J35: =VLOOKUP(C35,[1]TB!$B$3:$E$205,4,0) -> 5
B36: 3 | C36: Máy ảnh kỹ thuật số | D36: cái | E36: Pin khô | F36: 0.02 | G36: =H36/(J36*$J$3) -> 2520 | H36: =VLOOKUP(C36,[1]TB!$B$3:$D$503,3,0) -> 3150000 | I36: =F36*G36 -> 50.4 | J36: =VLOOKUP(C36,[1]TB!$B$3:$E$205,4,0) -> 5
A37: 9 | B37: 1NT7a | C37: Coliform | I37: =SUM(I38:I40) -> 1833.12
B38: 1 | C38: Thiết bị lấy mẫu nước | D38: bộ | F38: 0.036 | G38: =H38/(J38*$J$3) -> 41160 | H38: =VLOOKUP(C38,[1]TB!$B$3:$D$503,3,0) -> 51450000 | I38: =F38*G38 -> 1481.76 | J38: =VLOOKUP(C38,[1]TB!$B$3:$E$205,4,0) -> 5
B39: 2 | C39: Máy định vị GPS cầm tay | D39: bộ | E39: Pin khô | F39: 0.036 | G39: =H39/(J39*$J$3) -> 8360 | H39: =VLOOKUP(C39,[1]TB!$B$3:$D$503,3,0) -> 10450000 | I39: =F39*G39 -> 300.96 | J39: =VLOOKUP(C39,[1]TB!$B$3:$E$205,4,0) -> 5
B40: 3 | C40: Máy ảnh kỹ thuật số | D40: cái | E40: Pin khô | F40: 0.02 | G40: =H40/(J40*$J$3) -> 2520 | H40: =VLOOKUP(C40,[1]TB!$B$3:$D$503,3,0) -> 3150000 | I40: =F40*G40 -> 50.4 | J40: =VLOOKUP(C40,[1]TB!$B$3:$E$205,4,0) -> 5
...

Sheet TH dongia
A1: PHỤ LỤC 9
A2: TỔNG HỢP ĐƠN GIÁ SẢN PHẨM HOẠT ĐỘNG QUAN TRẮC NƯỚC THẢI
B3: Hệ số lương tối thiểu: 1.300.000 đồng/ tháng | I3: Đơn vị tính: đồng/thông số
A4: Số TT | B4: Mã hiệu | C4: Thông số quan trắc | D4: Chi phí LĐKT | E4: Chi phí CCDC | F4: Chi phí vật liệu | G4: CP năng lượng | H4: Chi phí khấu hao | I4: Chi phí trực tiếp | J4: Chi phí chung (20%) | K4: Đơn giá (không VAT)
A5: A | B5: B | C5: C | D5: 1 | E5: 2 | F5: 3 | G5: 4 | H5: 5 | I5: 6=1+2+3+4 | J5: 7=6*20% | K5: 8=6+7
A6: A | B6: HOẠT ĐỘNG QUAN TRẮC NƯỚC THẢI
A7: A1 | B7: Công tác quan trắc nước thải tại hiện trường (1NT)
A8: 1 | B8: 1NT1 | C8: Nhiệt độ | D8: =VLOOKUP(B8,LDKT!$B$6:$G$1236,6,0) -> 43767.6 | E8: =VLOOKUP(B8,Dcu!$A$7:$G$1960,7,0) -> 2850.3462 | F8: =VLOOKUP(B8,VL!$B$7:$G$1005,6,0) -> 57834 | G8: 0 | H8: =VLOOKUP(B8,TB!$B$4:$I$2042,8,0) -> 2672.5024 | I8: =D8+E8+F8+G8 -> 104451.95 | J8: =I8*20% -> 20890.389 | K8: =ROUND((J8+I8),-2) -> 125300
A9: 2 | B9: 1NT2 | C9: pH | D9: =VLOOKUP(B9,LDKT!$B$6:$G$1236,6,0) -> 43767.6 | E9: =VLOOKUP(B9,Dcu!$A$7:$G$1960,7,0) -> 2850.3462 | F9: =VLOOKUP(B9,VL!$B$7:$G$1005,6,0) -> 87156 | G9: 0 | H9: =VLOOKUP(B9,TB!$B$4:$I$2042,8,0) -> 2672.5024 | I9: =D9+E9+F9+G9 -> 133773.95 | J9: =I9*20% -> 26754.789 | K9: =ROUND((J9+I9),-2) -> 160500
A10: 3 | B10: 1NT3 | C10: Vận tốc | D10: =VLOOKUP(B10,LDKT!$B$6:$G$1236,6,0) -> 98187.6 | E10: =VLOOKUP(B10,Dcu!$A$7:$G$1960,7,0) -> 3102.5077 | F10: =VLOOKUP(B10,VL!$B$7:$G$1005,6,0) -> 2646 | G10: 0 | H10: =VLOOKUP(B10,TB!$B$4:$I$2042,8,0) -> 838.7424 | I10: =D10+E10+F10+G10 -> 103936.11 | J10: =I10*20% -> 20787.222 | K10: =ROUND((J10+I10),-2) -> 124700
A11: 4 | B11: 1NT4b | C11: TDS | D11: =VLOOKUP(B11,LDKT!$B$6:$G$1236,6,0) -> 43767.6 | E11: =VLOOKUP(B11,Dcu!$A$7:$G$1960,7,0) -> 4655.4846 | F11: =VLOOKUP(B11,VL!$B$7:$G$1005,6,0) -> 70416 | G11: 0 | H11: =VLOOKUP(B11,TB!$B$4:$I$2042,8,0) -> 838.7424 | I11: =D11+E11+F11+G11 -> 118839.08 | J11: =I11*20% -> 23767.817 | K11: =ROUND((J11+I11),-2) -> 142600
A12: 5 | B12: 1NT4a | C12: Độ màu | D12: =VLOOKUP(B12,LDKT!$B$6:$G$1236,6,0) -> 43767.6 | E12: =VLOOKUP(B12,Dcu!$A$7:$G$1960,7,0) -> 4655.4846 | F12: =VLOOKUP(B12,VL!$B$7:$G$1005,6,0) -> 70416 | G12: 0 | H12: =VLOOKUP(B12,TB!$B$4:$I$2042,8,0) -> 838.7424 | I12: =D12+E12+F12+G12 -> 118839.08 | J12: =I12*20% -> 23767.817 | K12: =ROUND((J12+I12),-2) -> 142600
A13: 6 | B13: 1NT5a | C13: Nhu cầu oxy sinh hoá (BOD5 | D13: =VLOOKUP(B13,LDKT!$B$6:$G$1236,6,0) -> 43767.6 | E13: =VLOOKUP(B13,Dcu!$A$7:$G$1960,7,0) -> 4639.3308 | F13: =VLOOKUP(B13,VL!$B$7:$G$1005,6,0) -> 28458 | G13: 0 | H13: =VLOOKUP(B13,TB!$B$4:$I$2042,8,0) -> 1833.12 | I13: =D13+E13+F13+G13 -> 76864.931 | J13: =I13*20% -> 15372.986 | K13: =ROUND((J13+I13),-2) -> 92200
A14: 7 | B14: 1NT5b | C14: Nhu cầu oxy hoá học (COD) | D14: =VLOOKUP(B14,LDKT!$B$6:$G$1236,6,0) -> 43767.6 | E14: =VLOOKUP(B14,Dcu!$A$7:$G$1960,7,0) -> 4655.4846 | F14: =VLOOKUP(B14,VL!$B$7:$G$1005,6,0) -> 37638 | G14: 0 | H14: =VLOOKUP(B14,TB!$B$4:$I$2042,8,0) -> 1833.12 | I14: =D14+E14+F14+G14 -> 86061.085 | J14: =I14*20% -> 17212.217 | K14: =ROUND((J14+I14),-2) -> 103300
A15: 8 | B15: 1NT6 | C15: Chất rắn lơ lửng (SS) | D15: =VLOOKUP(B15,LDKT!$B$6:$G$1236,6,0) -> 43767.6 | E15: =VLOOKUP(B15,Dcu!$A$7:$G$1960,7,0) -> 4913.9462 | F15: =VLOOKUP(B15,VL!$B$7:$G$1005,6,0) -> 28296 | G15: 0 | H15: =VLOOKUP(B15,TB!$B$4:$I$2042,8,0) -> 1833.12 | I15: =D15+E15+F15+G15 -> 76977.546 | J15: =I15*20% -> 15395.509 | K15: =ROUND((J15+I15),-2) -> 92400
A16: 9 | B16: 1NT7a | C16: Coliform | D16: =VLOOKUP(B16,LDKT!$B$6:$G$1236,6,0) -> 49093.8 | E16: =VLOOKUP(B16,Dcu!$A$7:$G$1960,7,0) -> 4707.1769 | F16: =VLOOKUP(B16,VL!$B$7:$G$1005,6,0) -> 45738 | G16: 0 | H16: =VLOOKUP(B16,TB!$B$4:$I$2042,8,0) -> 1833.12 | I16: =D16+E16+F16+G16 -> 99538.977 | J16: =I16*20% -> 19907.795 | K16: =ROUND((J16+I16),-2) -> 119400
A17: 10 | B17: 1NT7b | C17: E.Coli | D17: =VLOOKUP(B17,LDKT!$B$6:$G$1236,6,0) -> 54420 | E17: =VLOOKUP(B17,Dcu!$A$7:$G$1960,7,0) -> 4707.1769 | F17: =VLOOKUP(B17,VL!$B$7:$G$1005,6,0) -> 45738 | G17: 0 | H17: =VLOOKUP(B17,TB!$B$4:$I$2042,8,0) -> 1833.12 | I17: =D17+E17+F17+G17 -> 104865.18 | J17: =I17*20% -> 20973.035 | K17: =ROUND((J17+I17),-2) -> 125800
A18: 11 | B18: 1NT8 | C18: Tổng Dầu, mỡ khoáng | D18: =VLOOKUP(B18,LDKT!$B$6:$G$1236,6,0) -> 54420 | E18: =VLOOKUP(B18,Dcu!$A$7:$G$1960,7,0) -> 4924.7154 | F18: =VLOOKUP(B18,VL!$B$7:$G$1005,6,0) -> 45738 | G18: 0 | H18: =VLOOKUP(B18,TB!$B$4:$I$2042,8,0) -> 1833.12 | I18: =D18+E18+F18+G18 -> 105082.72 | J18: =I18*20% -> 21016.543 | K18: =ROUND((J18+I18),-2) -> 126100
A19: 12 | B19: 1NT9 | C19: Cyanua (CN-) | D19: =VLOOKUP(B19,LDKT!$B$6:$G$1236,6,0) -> 49093.8 | E19: =VLOOKUP(B19,Dcu!$A$7:$G$1960,7,0) -> 4646.6 | F19: =VLOOKUP(B19,VL!$B$7:$G$1005,6,0) -> 53868.24 | G19: 0 | H19: =VLOOKUP(B19,TB!$B$4:$I$2042,8,0) -> 1833.12 | I19: =D19+E19+F19+G19 -> 107608.64 | J19: =I19*20% -> 21521.728 | K19: =ROUND((J19+I19),-2) -> 129100
... A45: 38 | B45: 1NT13c | C45: PCBs | D45: =VLOOKUP(B45,LDKT!$B$6:$G$1236,6,0) -> 54420 | E45: =VLOOKUP(B45,Dcu!$A$7:$G$1960,7,0) -> 4639.3308 | F45: =VLOOKUP(B45,VL!$B$7:$G$1005,6,0) -> 18740.7 | G45: 0 | H45: =VLOOKUP(B45,TB!$B$4:$I$2042,8,0) -> 1833.12 | I45: =D45+E45+F45+G45 -> 77800.031 | J45: =I45*20% -> 15560.006 | K45: =ROUND((J45+I45),-2) -> 93400
A46: A2 | B46: Công tác phân tích nước thải trong phòng thí nghiệm (2NT)
A47: 1 | B47: 2NT5a | C47: Nhu cầu oxy sinh hoá (BOD5) | D47: =VLOOKUP(B47,LDKT!$B$6:$G$1236,6,0) -> 76311.55 | E47: =VLOOKUP(B47,Dcu!$A$7:$G$1960,7,0) -> 64236.071 | F47: =VLOOKUP(B47,VL!$B$7:$G$1005,6,0) -> 17356.896 | G47: =TB!I89 -> 7434.71 | H47: =VLOOKUP(B47,TB!$B$4:$I$2042,8,0) -> 22790.6 | I47: =D47+E47+F47+G47 -> 165339.23 | J47: =I47*20% -> 33067.845 | K47: =ROUND((J47+I47),-2) -> 198400
A48: 2 | B48: 2NT5b | C48: Nhu cầu oxy hoá học (COD) | D48: =VLOOKUP(B48,LDKT!$B$6:$G$1236,6,0) -> 81182.5 | E48: =VLOOKUP(B48,Dcu!$A$7:$G$1960,7,0) -> 22248.892 | F48: =VLOOKUP(B48,VL!$B$7:$G$1005,6,0) -> 65399.4 | G48: =TB!I99 -> 11022.486 | H48: =VLOOKUP(B48,TB!$B$4:$I$2042,8,0) -> 40558.6 | I48: =D48+E48+F48+G48 -> 179853.28 | J48: =I48*20% -> 35970.656 | K48: =ROUND((J48+I48),-2) -> 215800
A49: 3 | B49: 2NT6 | C49: Chất rắn lơ lửng (SS) | D49: =VLOOKUP(B49,LDKT!$B$6:$G$1236,6,0) -> 76311.55 | E49: =VLOOKUP(B49,Dcu!$A$7:$G$1960,7,0) -> 3577.8846 | F49: =VLOOKUP(B49,VL!$B$7:$G$1005,6,0) -> 20536.2 | G49: =TB!I107 -> 10562.986 | H49: =VLOOKUP(B49,TB!$B$4:$I$2042,8,0) -> 14053.4 | I49: =D49+E49+F49+G49 -> 110988.62 | J49: =I49*20% -> 22197.724 | K49: =ROUND((J49+I49),-2) -> 133200
A50: 4 | B50: 2NT7a1 | C50: Coliform (TCVN 6187-1:2009) | D50: =VLOOKUP(B50,LDKT!$B$6:$G$1236,6,0) -> 110734.5 | E50: =VLOOKUP(B50,Dcu!$A$7:$G$1960,7,0) -> 6388.95 | F50: =VLOOKUP(B50,VL!$B$7:$G$1005,6,0) -> 218879.28 | G50: =TB!I117 -> 33874.34 | H50: =VLOOKUP(B50,TB!$B$4:$I$2042,8,0) -> 41153.8 | I50: =D50+E50+F50+G50 -> 369877.07 | J50: =I50*20% -> 73975.414 | K50: =ROUND((J50+I50),-2) -> 443900
A51: 5 | B51: 2NT7a2 | C51: Coliform (TCVN 6187-2:2009) | D51: =VLOOKUP(B51,LDKT!$B$6:$G$1236,6,0) -> 110734.5 | E51: =VLOOKUP(B51,Dcu!$A$7:$G$1960,7,0) -> 6388.95 | F51: =VLOOKUP(B51,VL!$B$7:$G$1005,6,0) -> 231285.24 | G51: =TB!I117 -> 33874.34 | H51: =VLOOKUP(B51,TB!$B$4:$I$2042,8,0) -> 41153.8 | I51: =D51+E51+F51+G51 -> 382283.03 | J51: =I51*20% -> 76456.606 | K51: =ROUND((J51+I51),-2) -> 458700
A52: 6 | B52: 2NT7b1 | C52: E.Coli (TCVN 6187-1:2009) | D52: =VLOOKUP(B52,LDKT!$B$6:$G$1236,6,0) -> 110734.5 | E52: =VLOOKUP(B52,Dcu!$A$7:$G$1960,7,0) -> 6388.95 | F52: =VLOOKUP(B52,VL!$B$7:$G$1005,6,0) -> 218879.28 | G52: =TB!I117 -> 33874.34 | H52: =VLOOKUP(B52,TB!$B$4:$I$2042,8,0) -> 41153.8 | I52: =D52+E52+F52+G52 -> 369877.07 | J52: =I52*20% -> 73975.414 | K52: =ROUND((J52+I52),-2) -> 443900
A53: 7 | B53: 2NT7b2 | C53: E.Coli (TCVN 6187-2:2009) | D53: =VLOOKUP(B53,LDKT!$B$6:$G$1236,6,0) -> 110734.5 | E53: =VLOOKUP(B53,Dcu!$A$7:$G$1960,7,0) -> 6388.95 | F53: =VLOOKUP(B53,VL!$B$7:$G$1005,6,0) -> 231285.24 | G53: =TB!I117 -> 33874.34 | H53: =VLOOKUP(B53,TB!$B$4:$I$2042,8,0) -> 41153.8 | I53: =D53+E53+F53+G53 -> 382283.03 | J53: =I53*20% -> 76456.606 | K53: =ROUND((J53+I53),-2) -> 458700
A54: 8 | B54: 2NT8 | C54: Tổng Dầu, mỡ khoáng | D54: =VLOOKUP(B54,LDKT!$B$6:$G$1236,6,0) -> 110734.5 | E54: =VLOOKUP(B54,Dcu!$A$7:$G$1960,7,0) -> 48598.588 | F54: =VLOOKUP(B54,VL!$B$7:$G$1005,6,0) -> 213792.48 | G54: =TB!I129 -> 50085.5 | H54: =VLOOKUP(B54,TB!$B$4:$I$2042,8,0) -> 25732.6 | I54: =D54+E54+F54+G54 -> 423211.07 | J54: =I54*20% -> 84642.214 | K54: =ROUND((J54+I54),-2) -> 507900
A55: 9 | B55: 2NT9 | C55: Cyanua (CN-) | D55: =VLOOKUP(B55,LDKT!$B$6:$G$1236,6,0) -> 114425.65 | E55: =VLOOKUP(B55,Dcu!$A$7:$G$1960,7,0) -> 38706.307 | F55: =VLOOKUP(B55,VL!$B$7:$G$1005,6,0) -> 172352.88 | G55: =TB!I138 -> 15200.26 | H55: =VLOOKUP(B55,TB!$B$4:$I$2042,8,0) -> 23858.4 | I55: =D55+E55+F55+G55 -> 340685.1 | J55: =I55*20% -> 68137.019 | K55: =ROUND((J55+I55),-2) -> 408800
A56: 10 | B56: 2NT10a | C56: Tổng P | D56: =VLOOKUP(B56,LDKT!$B$6:$G$1236,6,0) -> 114425.65 | E56: =VLOOKUP(B56,Dcu!$A$7:$G$1960,7,0) -> 36474.63 | F56: =VLOOKUP(B56,VL!$B$7:$G$1005,6,0) -> 33656.58 | G56: =TB!I148 -> 18968.16 | H56: =VLOOKUP(B56,TB!$B$4:$I$2042,8,0) -> 35450.4 | I56: =D56+E56+F56+G56 -> 203525.02 | J56: =I56*20% -> 40705.004 | K56: =ROUND((J56+I56),-2) -> 244200
A57: 11 | B57: 2NT10b | C57: Tổng N | D57: =VLOOKUP(B57,LDKT!$B$6:$G$1236,6,0) -> 114425.65 | E57: =VLOOKUP(B57,Dcu!$A$7:$G$1960,7,0) -> 42387.29 | F57: =VLOOKUP(B57,VL!$B$7:$G$1005,6,0) -> 49011.48 | G57: =TB!I158 -> 23526.4 | H57: =VLOOKUP(B57,TB!$B$4:$I$2042,8,0) -> 37324.6 | I57: =D57+E57+F57+G57 -> 229350.82 | J57: =I57*20% -> 45870.164 | K57: =ROUND((J57+I57),-2) -> 275200
A58: 12 | B58: 2NT10c | C58: Nitơ amôn (NH4+) | D58: =VLOOKUP(B58,LDKT!$B$6:$G$1236,6,0) -> 81182.5 | E58: =VLOOKUP(B58,Dcu!$A$7:$G$1960,7,0) -> 41339.364 | F58: =VLOOKUP(B58,VL!$B$7:$G$1005,6,0) -> 48587.04 | G58: =TB!I166 -> 12345.846 | H58: =VLOOKUP(B58,TB!$B$4:$I$2042,8,0) -> 20895.9 | I58: =D58+E58+F58+G58 -> 183454.75 | J58: =I58*20% -> 36690.95 | K58: =ROUND((J58+I58),-2) -> 220100
A59: 13 | B59: 2NT10d | C59: Sunlfua (S2-) | D59: =VLOOKUP(B59,LDKT!$B$6:$G$1236,6,0) -> 92278.75 | E59: =VLOOKUP(B59,Dcu!$A$7:$G$1960,7,0) -> 40275.162 | F59: =VLOOKUP(B59,VL!$B$7:$G$1005,6,0) -> 43020.072 | G59: =TB!I175 -> 11336.784 | H59: =VLOOKUP(B59,TB!$B$4:$I$2042,8,0) -> 23858.4 | I59: =D59+E59+F59+G59 -> 186910.77 | J59: =I59*20% -> 37382.154 | K59: =ROUND((J59+I59),-2) -> 224300
A60: 14 | B60: 2NT10đ | C60: Crom (VI) | D60: =VLOOKUP(B60,LDKT!$B$6:$G$1236,6,0) -> 92278.75 | E60: =VLOOKUP(B60,Dcu!$A$7:$G$1960,7,0) -> 25007.954 | F60: =VLOOKUP(B60,VL!$B$7:$G$1005,6,0) -> 52239.6 | G60: =TB!I175 -> 11336.784 | H60: =VLOOKUP(B60,TB!$B$4:$I$2042,8,0) -> 20895.9 | I60: =D60+E60+F60+G60 -> 180863.09 | J60: =I60*20% -> 36172.618 | K60: =ROUND((J60+I60),-2) -> 217000
A61: 15 | B61: 2NT10e | C61: Nitrate (NO3) | D61: =VLOOKUP(B61,LDKT!$B$6:$G$1236,6,0) -> 92278.75 | E61: =VLOOKUP(B61,Dcu!$A$7:$G$1960,7,0) -> 61600.55 | F61: =VLOOKUP(B61,VL!$B$7:$G$1005,6,0) -> 139330.8 | G61: =TB!I185 -> 11336.784 | H61: =VLOOKUP(B61,TB!$B$4:$I$2042,8,0) -> 22395.9 | I61: =D61+E61+F61+G61 -> 304546.88 | J61: =I61*20% -> 60909.377 | K61: =ROUND((J61+I61),-2) -> 365500
A62: 16 | B62: 2NT10f | C62: Sulphat (SO42) | D62: =VLOOKUP(B62,LDKT!$B$6:$G$1236,6,0) -> 92278.75 | E62: =VLOOKUP(B62,Dcu!$A$7:$G$1960,7,0) -> 24571.8 | F62: =VLOOKUP(B62,VL!$B$7:$G$1005,6,0) -> 79833.6 | G62: =TB!I194 -> 13378.802 | H62: =VLOOKUP(B62,TB!$B$4:$I$2042,8,0) -> 22473.4 | I62: =D62+E62+F62+G62 -> 210062.95 | J62: =I62*20% -> 42012.59 | K62: =ROUND((J62+I62),-2) -> 252100
A63: 17 | B63: 2NT10g | C63: Photphat (PO43-) | D63: =VLOOKUP(B63,LDKT!$B$6:$G$1236,6,0) -> 92278.75 | E63: =VLOOKUP(B63,Dcu!$A$7:$G$1960,7,0) -> 25007.954 | F63: =VLOOKUP(B63,VL!$B$7:$G$1005,6,0) -> 25360.56 | G63: =TB!I203 -> 15992.438 | H63: =VLOOKUP(B63,TB!$B$4:$I$2042,8,0) -> 43003.4 | I63: =D63+E63+F63+G63 -> 158639.7 | J63: =I63*20% -> 31727.94 | K63: =ROUND((J63+I63),-2) -> 190400
A64: 18 | B64: 2NT10h | C64: Florua (F-) | D64: =VLOOKUP(B64,LDKT!$B$6:$G$1236,6,0) -> 92278.75 | E64: =VLOOKUP(B64,Dcu!$A$7:$G$1960,7,0) -> 25007.954 | F64: =VLOOKUP(B64,VL!$B$7:$G$1005,6,0) -> 134697.6 | G64: =TB!I212 -> 11336.784 | H64: =VLOOKUP(B64,TB!$B$4:$I$2042,8,0) -> 23858.4 | I64: =D64+E64+F64+G64 -> 263321.09 | J64: =I64*20% -> 52664.218 | K64: =ROUND((J64+I64),-2) -> 316000
A65: 19 | B65: 2NT10i | C65: Clorua (Cl-) | D65: =VLOOKUP(B65,LDKT!$B$6:$G$1236,6,0) -> 92278.75 | E65: =VLOOKUP(B65,Dcu!$A$7:$G$1960,7,0) -> 18776.327 | F65: =VLOOKUP(B65,VL!$B$7:$G$1005,6,0) -> 89158.32 | G65: =TB!I220 -> 9662.366 | H65: =VLOOKUP(B65,TB!$B$4:$I$2042,8,0) -> 21843.4 | I65: =D65+E65+F65+G65 -> 209875.76 | J65: =I65*20% -> 41975.153 | K65: =ROUND((J65+I65),-2) -> 251900
...
