Workbook
Name _: 'Results - Run 1'!$O$17
Name A: 'Pre-Test'!$D$11
Name Ai: 'Pre-Test'!$D$12
Name An: 'Pre-Test'!$Q$14
Name Bws_1: 'Results - Run 1'!$O$23
Name Bws_2: 'Results - Run 2'!$O$23
Name Bws_3: 'Results - Run 3'!$O$23
Name Bwse: 'Pre-Test'!$D$7
Name Ca_1: 'Results - Run 1'!$O$30
Name Ca_2: 'Results - Run 2'!$O$30
Name Ca_3: 'Results - Run 3'!$O$30
Name Cf_1: 'Results - Run 1'!$L$33
Name Cf_2: 'Results - Run 2'!$L$33
Name Cf_3: 'Results - Run 3'!$L$33
Name Cfe: 'Pre-Test'!$L$8
Name COO: 'Pre-Test'!$G$7
Name Cp: 'Pre-Test'!$P$12
Name Cpp: 'Pre-Test'!$P$11
Name D50I_1: 'Results - Run 1'!$L$34
Name D50I_2: 'Results - Run 2'!$L$34
Name D50I_3: 'Results - Run 3'!$L$34
Name D50IV_1: 'Results - Run 1'!$L$35
Name D50IV_2: 'Results - Run 2'!$L$35
Name D50IV_3: 'Results - Run 3'!$L$35
Name D50LL: 'Pre-Test'!$L$9
Name D50LLh: 'Pre-Test'!$L$10
Name D50T: 'Pre-Test'!$L$11
Name Date: 'Results - Run 2'!$D$3
Name dH_1: 'Run 1'!$N$48
Name dH_2: 'Run 2'!$N$48
Name dH_3: 'Run 3'!$N$48
Name dHa: 'Pre-Test'!$Q$9
Name dHe: 'Pre-Test'!$L$14
Name dHh: 'Run 1'!$Q$9
Name dHh_2: 'Run 2'!$Q$9
Name dHh_3: 'Run 3'!$Q$9
Name dHl: 'Run 1'!$O$9
Name dHl_2: 'Run 2'!$O$9
Name dHl_3: 'Run 3'!$O$9
Name Dn: 'Pre-Test'!$Q$13
Name dP_1: 'Run 1'!$F$48
Name dP_2: 'Run 2'!$F$48
Name dP_3: 'Run 3'!$F$48
Name dPsqavg_1: 'Run 1'!$U$44
Name dPsqavg_2: 'Run 2'!$U$44
Name dPsqavg_3: 'Run 3'!$U$44
Name Kp: 'Pre-Test'!$Y$11
Name M1_1: 'Results - Run 1'!$D$19
Name M1_2: 'Results - Run 2'!$D$19
Name M1_3: 'Results - Run 3'!$D$19
Name M2_1: 'Results - Run 1'!$D$25
Name M2_2: 'Results - Run 2'!$D$25
Name M2_3: 'Results - Run 3'!$D$25
Name M3_1: 'Results - Run 1'!$I$25
Name M3_2: 'Results - Run 2'!$I$25
Name M3_3: 'Results - Run 3'!$I$25
Name M4_1: 'Results - Run 1'!$I$19
Name M4_2: 'Results - Run 2'!$I$19
Name M4_3: 'Results - Run 3'!$I$19
Name MB: 'Pre-Test'!$Q$7

Sheet Notes
A1: Spreadsheet ES-Method 201A-MASTER-V2.85.xlsx
A2: Version 2.85 (May 22, 2017)
A3: for
A5: U.S. EPA Method 201A Determination of Filterable PM10 & PM2.5 Emissions
A9: Copyright 2017
A10: by
A11: Environmental Supply Company, Inc.
A12: 708 E Club Blvd
A13: Durham, NC 27704
A14: (919) 956-9688
A16: www.environsupply.com
A20: Notes:
A23: 1. | C23: This color designates data entry.
A25: 2. | C25: This color designates calculations.
A27: 3. | B27: Tab button will move to next available data entry cell.
A29: 4. | B29: All cells are protected except green data entry cells. There is
B30: no password for protection.
A32: 5. | B32: The Stack Area cell on the Pre-Test page will turn red if the
B33: stack area is too small or it will change to blue if blockage
B34: must be considered. Nozzle calculations adjust for
B35: blockage if necessary.

Sheet Pre-Test
C2: Location: | J2: Start Time: | O2: RUN No.
C3: Date: | J3: End Time: | O3: JOB No.
B5: STACK DATA | I5: PRE-TEST CALCULATIONS | O5: EQUIPMENT
C7: % Moisture: | E7: % est. | F7: %CO2: | H7: % | I7: Viscocity ms: | L7: =IF(ISNUMBER(Tse),-150.3162+13.4622*SQRT(Tse+460)+3861530/(Tse+460)^2+0.591123*(1-Bwse/100)*OO-91.9723*Bwse/100+0.0000151761*Bwse/100*(Tse+460)^2,"-") -> - | N7: mpoise | P7: METER BOX:
C8: Barometric: | E8: in Hg | F8: %O2: | H8: % | I8: Cunningham: | L8: =IF(ISNUMBER(vise),1+0.0057193*(vise/Psp/2.25)*SQRT((Tse+460)/Mwe),"-") -> - | P8: Y:
C9: Static Press: | E9: in H2O | F9: %N2/CO: | G9: =IF(AND(ISNUMBER(COO),ISNUMBER(OO)),100-COO-OO,"-") -> - | H9: % | I9: D50LL: | L9: =IF(ISNUMBER(Cfe),9.507*Cfe^0.3007*(Mwe*Psp/(Tse+460))^0.1993,"-") -> - | N9: mm | P9: DH@: | R9: in H2O
C10: Stack Press: | D10: =IF(AND(ISNUMBER(Pgp),ISNUMBER(Pbarp)),Pbarp+Pgp/13.6,"-") -> - | E10: in Hg | F10: Md: | G10: =IF(ISNUMBER(NN),0.44*COO+0.32*OO+0.28*NN,"-") -> - | H10: lb/lb-mole | I10: [Nre>3162] D50LL: | L10: =IF(ISNUMBER(Cfe),IF(Nre>3162,10.0959*Cfe^0.44*(Mwe*Psp/(Tse+460))^0.06,"-"),"-") -> - | N10: mm | O10: Estimated Tm: | R10: °F
C11: Stack Area: | E11: ft2 | F11: Est. Mw: | G11: =IF(ISNUMBER(Md),Md*(1-Bwse/100)+18*Bwse/100,"-") -> - | H11: lb/lb-mole | I11: D50T: | L11: =IF(ISNUMBER(D50LLh),(11+D50LLh)/2,IF(ISNUMBER(D50LL),(11+D50LL)/2,"-")) -> - | N11: mm | O11: Cp': | Q11: S/N
C12: Stack Area: | D12: =IF(ISNUMBER(A),A*144,"-") -> - | E12: in2 | I12: Estimated Qs: | L12: =IF(ISNUMBER(D50T),0.07296*vise*((Tse+460)/Mwe/Psp)^0.2949*(1/D50T)^1.4102,"-") -> - | N12: acfm | O12: Cp: | Q12: S/N
B13: STANDARD | E13: Tstd: | F13: 68 | G13: °F | I13: Estimated Nre: | L13: =IF(ISNUMBER(Qse),864000*Psp*Mwe/(Tse+460)*Qse/vise,"-") -> - | P13: Nozzle Dia: | R13: inches
B14: CONDITIONS | E14: Pstd: | F14: 29.92 | G14: inches Hg | I14: Estimated DH: | L14: =IF(ISNUMBER(Nre),(Qse*(1-Bwse/100)*Psp/(Tse+460))^2*1.083*(Tme+460)*Md*dHa/Pbarp,"-") -> - | N14: in H2O | P14: Nozzle Area: | Q14: =IF(ISNUMBER(Dn),PI()*Dn^2/4/144,"-") -> - | R14: ft2
F15: =IF(ISNUMBER(F13),F13+460,"") -> 528
B16: PRELIMINARY TRAVERSE | L16: NOZZLE SELECTION
B19: Sample Point | C19: Cyclonic Flow Check | E19: Preliminary DP (in. H2O) | I19: Stack Temperature
L20: Nozzle | M20: Diam. | N20: Vn | O20: Vmin | P20: Vmax | Q20: DPmin | R20: DPmax | V20: Absolute Null Angle ° | X20: R(min) | Y20: R(max)
C21: Null Angle ° | E21: DPm | F21: DPs | G21: DPs2 | I21: (°F) | L21: S/N | M21: Dn (in) | N21: (fps) | O21: (fps) | P21: (fps) | Q21: ( inches H2O) | U21: sqrt(DPm)
B22: 1 | F22: =IF(ISNUMBER(E22),E22*(Cp/Cpp)^2,"-") -> - | G22: =IF(ISNUMBER(F22),IF(A<7.227,F22*(1/(1-22/Ai))^2,"-"),"-") -> - | N22: =IF(ISNUMBER(Qse),3.055775*Qse/(M22)^2,"-") -> - | O22: =IF(ISNUMBER(X22),N22*X22,"-") -> - | P22: =IF(ISNUMBER(Y22),N22*Y22,"-") -> - | Q22: =IF(ISNUMBER(O22),0.00013686*Psp*Mwe*(O22)^2/(Tse+460)/Cp^2,"-") -> - | R22: =IF(ISNUMBER(P22),0.00013686*Psp*Mwe*(P22)^2/(Tse+460)/Cp^2,"-") -> - | U22: =IF(ISNUMBER(E22),SQRT(E22),"-") -> - | V22: =IF(ISNUMBER(C22),ABS(C22),"-") -> - | X22: =IF(ISNUMBER(N22),IF((0.2603*vise*SQRT(Qse))/(N22)^1.5>0.3072,0.5,(0.2457+SQRT(0.3072-(0.2603*vise*SQRT(Qse))/(N22)^1.5))),"-") -> - | Y22: =IF(ISNUMBER(N22),IF((0.4457+SQRT(0.569+(0.2603*vise*SQRT(Qse))/(N22)^1.5))>1.5,1.5,(0.4457+SQRT(0.569+(0.2603*vise*SQRT(Qse))/(N22)^1.5))),"-") -> -
B23: =B22+1 -> 2 | F23: =IF(ISNUMBER(E23),E23*(Cp/Cpp)^2,"-") -> - | G23: =IF(ISNUMBER(F23),IF(A<7.227,F23*(1/(1-22/Ai))^2,"-"),"-") -> - | N23: =IF(ISNUMBER(Qse),3.055775*Qse/(M23)^2,"-") -> - | O23: =IF(ISNUMBER(X23),N23*X23,"-") -> - | P23: =IF(ISNUMBER(Y23),N23*Y23,"-") -> - | Q23: =IF(ISNUMBER(O23),0.00013686*Psp*Mwe*(O23)^2/(Tse+460)/Cp^2,"-") -> - | R23: =IF(ISNUMBER(P23),0.00013686*Psp*Mwe*(P23)^2/(Tse+460)/Cp^2,"-") -> - | U23: =IF(ISNUMBER(E23),SQRT(E23),"-") -> - | V23: =IF(ISNUMBER(C23),ABS(C23),"-") -> - | X23: =IF(ISNUMBER(N23),IF((0.2603*vise*SQRT(Qse))/(N23)^1.5>0.3072,0.5,(0.2457+SQRT(0.3072-(0.2603*vise*SQRT(Qse))/(N23)^1.5))),"-") -> - | Y23: =IF(ISNUMBER(N23),IF((0.4457+SQRT(0.569+(0.2603*vise*SQRT(Qse))/(N23)^1.5))>1.5,1.5,(0.4457+SQRT(0.569+(0.2603*vise*SQRT(Qse))/(N23)^1.5))),"-") -> -
B24: =B23+1 -> 3 | F24: =IF(ISNUMBER(E24),E24*(Cp/Cpp)^2,"-") -> - | G24: =IF(ISNUMBER(F24),IF(A<7.227,F24*(1/(1-22/Ai))^2,"-"),"-") -> - | N24: =IF(ISNUMBER(Qse),3.055775*Qse/(M24)^2,"-") -> - | O24: =IF(ISNUMBER(X24),N24*X24,"-") -> - | P24: =IF(ISNUMBER(Y24),N24*Y24,"-") -> - | Q24: =IF(ISNUMBER(O24),0.00013686*Psp*Mwe*(O24)^2/(Tse+460)/Cp^2,"-") -> - | R24: =IF(ISNUMBER(P24),0.00013686*Psp*Mwe*(P24)^2/(Tse+460)/Cp^2,"-") -> - | U24: =IF(ISNUMBER(E24),SQRT(E24),"-") -> - | V24: =IF(ISNUMBER(C24),ABS(C24),"-") -> - | X24: =IF(ISNUMBER(N24),IF((0.2603*vise*SQRT(Qse))/(N24)^1.5>0.3072,0.5,(0.2457+SQRT(0.3072-(0.2603*vise*SQRT(Qse))/(N24)^1.5))),"-") -> - | Y24: =IF(ISNUMBER(N24),IF((0.4457+SQRT(0.569+(0.2603*vise*SQRT(Qse))/(N24)^1.5))>1.5,1.5,(0.4457+SQRT(0.569+(0.2603*vise*SQRT(Qse))/(N24)^1.5))),"-") -> -
B25: =B24+1 -> 4 | F25: =IF(ISNUMBER(E25),E25*(Cp/Cpp)^2,"-") -> - | G25: =IF(ISNUMBER(F25),IF(A<7.227,F25*(1/(1-22/Ai))^2,"-"),"-") -> - | N25: =IF(ISNUMBER(Qse),3.055775*Qse/(M25)^2,"-") -> - | O25: =IF(ISNUMBER(X25),N25*X25,"-") -> - | P25: =IF(ISNUMBER(Y25),N25*Y25,"-") -> - | Q25: =IF(ISNUMBER(O25),0.00013686*Psp*Mwe*(O25)^2/(Tse+460)/Cp^2,"-") -> - | R25: =IF(ISNUMBER(P25),0.00013686*Psp*Mwe*(P25)^2/(Tse+460)/Cp^2,"-") -> - | U25: =IF(ISNUMBER(E25),SQRT(E25),"-") -> - | V25: =IF(ISNUMBER(C25),ABS(C25),"-") -> - | X25: =IF(ISNUMBER(N25),IF((0.2603*vise*SQRT(Qse))/(N25)^1.5>0.3072,0.5,(0.2457+SQRT(0.3072-(0.2603*vise*SQRT(Qse))/(N25)^1.5))),"-") -> - | Y25: =IF(ISNUMBER(N25),IF((0.4457+SQRT(0.569+(0.2603*vise*SQRT(Qse))/(N25)^1.5))>1.5,1.5,(0.4457+SQRT(0.569+(0.2603*vise*SQRT(Qse))/(N25)^1.5))),"-") -> -
B26: =B25+1 -> 5 | F26: =IF(ISNUMBER(E26),E26*(Cp/Cpp)^2,"-") -> - | G26: =IF(ISNUMBER(F26),IF(A<7.227,F26*(1/(1-22/Ai))^2,"-"),"-") -> - | N26: =IF(ISNUMBER(Qse),3.055775*Qse/(M26)^2,"-") -> - | O26: =IF(ISNUMBER(X26),N26*X26,"-") -> - | P26: =IF(ISNUMBER(Y26),N26*Y26,"-") -> - | Q26: =IF(ISNUMBER(O26),0.00013686*Psp*Mwe*(O26)^2/(Tse+460)/Cp^2,"-") -> - | R26: =IF(ISNUMBER(P26),0.00013686*Psp*Mwe*(P26)^2/(Tse+460)/Cp^2,"-") -> - | U26: =IF(ISNUMBER(E26),SQRT(E26),"-") -> - | V26: =IF(ISNUMBER(C26),ABS(C26),"-") -> - | X26: =IF(ISNUMBER(N26),IF((0.2603*vise*SQRT(Qse))/(N26)^1.5>0.3072,0.5,(0.2457+SQRT(0.3072-(0.2603*vise*SQRT(Qse))/(N26)^1.5))),"-") -> - | Y26: =IF(ISNUMBER(N26),IF((0.4457+SQRT(0.569+(0.2603*vise*SQRT(Qse))/(N26)^1.5))>1.5,1.5,(0.4457+SQRT(0.569+(0.2603*vise*SQRT(Qse))/(N26)^1.5))),"-") -> -
B27: =B26+1 -> 6 | F27: =IF(ISNUMBER(E27),E27*(Cp/Cpp)^2,"-") -> - | G27: =IF(ISNUMBER(F27),IF(A<7.227,F27*(1/(1-22/Ai))^2,"-"),"-") -> - | N27: =IF(ISNUMBER(Qse),3.055775*Qse/(M27)^2,"-") -> - | O27: =IF(ISNUMBER(X27),N27*X27,"-") -> - | P27: =IF(ISNUMBER(Y27),N27*Y27,"-") -> - | Q27: =IF(ISNUMBER(O27),0.00013686*Psp*Mwe*(O27)^2/(Tse+460)/Cp^2,"-") -> - | R27: =IF(ISNUMBER(P27),0.00013686*Psp*Mwe*(P27)^2/(Tse+460)/Cp^2,"-") -> - | U27: =IF(ISNUMBER(E27),SQRT(E27),"-") -> - | V27: =IF(ISNUMBER(C27),ABS(C27),"-") -> - | X27: =IF(ISNUMBER(N27),IF((0.2603*vise*SQRT(Qse))/(N27)^1.5>0.3072,0.5,(0.2457+SQRT(0.3072-(0.2603*vise*SQRT(Qse))/(N27)^1.5))),"-") -> - | Y27: =IF(ISNUMBER(N27),IF((0.4457+SQRT(0.569+(0.2603*vise*SQRT(Qse))/(N27)^1.5))>1.5,1.5,(0.4457+SQRT(0.569+(0.2603*vise*SQRT(Qse))/(N27)^1.5))),"-") -> -
B28: =B27+1 -> 7 | F28: =IF(ISNUMBER(E28),E28*(Cp/Cpp)^2,"-") -> - | G28: =IF(ISNUMBER(F28),IF(A<7.227,F28*(1/(1-22/Ai))^2,"-"),"-") -> - | N28: =IF(ISNUMBER(Qse),3.055775*Qse/(M28)^2,"-") -> - | O28: =IF(ISNUMBER(X28),N28*X28,"-") -> - | P28: =IF(ISNUMBER(Y28),N28*Y28,"-") -> - | Q28: =IF(ISNUMBER(O28),0.00013686*Psp*Mwe*(O28)^2/(Tse+460)/Cp^2,"-") -> - | R28: =IF(ISNUMBER(P28),0.00013686*Psp*Mwe*(P28)^2/(Tse+460)/Cp^2,"-") -> - | U28: =IF(ISNUMBER(E28),SQRT(E28),"-") -> - | V28: =IF(ISNUMBER(C28),ABS(C28),"-") -> - | X28: =IF(ISNUMBER(N28),IF((0.2603*vise*SQRT(Qse))/(N28)^1.5>0.3072,0.5,(0.2457+SQRT(0.3072-(0.2603*vise*SQRT(Qse))/(N28)^1.5))),"-") -> - | Y28: =IF(ISNUMBER(N28),IF((0.4457+SQRT(0.569+(0.2603*vise*SQRT(Qse))/(N28)^1.5))>1.5,1.5,(0.4457+SQRT(0.569+(0.2603*vise*SQRT(Qse))/(N28)^1.5))),"-") -> -
B29: =B28+1 -> 8 | F29: =IF(ISNUMBER(E29),E29*(Cp/Cpp)^2,"-") -> - | G29: =IF(ISNUMBER(F29),IF(A<7.227,F29*(1/(1-22/Ai))^2,"-"),"-") -> - | N29: =IF(ISNUMBER(Qse),3.055775*Qse/(M29)^2,"-") -> - | O29: =IF(ISNUMBER(X29),N29*X29,"-") -> - | P29: =IF(ISNUMBER(Y29),N29*Y29,"-") -> - | Q29: =IF(ISNUMBER(O29),0.00013686*Psp*Mwe*(O29)^2/(Tse+460)/Cp^2,"-") -> - | R29: =IF(ISNUMBER(P29),0.00013686*Psp*Mwe*(P29)^2/(Tse+460)/Cp^2,"-") -> - | U29: =IF(ISNUMBER(E29),SQRT(E29),"-") -> - | V29: =IF(ISNUMBER(C29),ABS(C29),"-") -> - | X29: =IF(ISNUMBER(N29),IF((0.2603*vise*SQRT(Qse))/(N29)^1.5>0.3072,0.5,(0.2457+SQRT(0.3072-(0.2603*vise*SQRT(Qse))/(N29)^1.5))),"-") -> - | Y29: =IF(ISNUMBER(N29),IF((0.4457+SQRT(0.569+(0.2603*vise*SQRT(Qse))/(N29)^1.5))>1.5,1.5,(0.4457+SQRT(0.569+(0.2603*vise*SQRT(Qse))/(N29)^1.5))),"-") -> -
B30: =B29+1 -> 9 | F30: =IF(ISNUMBER(E30),E30*(Cp/Cpp)^2,"-") -> - | G30: =IF(ISNUMBER(F30),IF(A<7.227,F30*(1/(1-22/Ai))^2,"-"),"-") -> - | N30: =IF(ISNUMBER(Qse),3.055775*Qse/(M30)^2,"-") -> - | O30: =IF(ISNUMBER(X30),N30*X30,"-") -> - | P30: =IF(ISNUMBER(Y30),N30*Y30,"-") -> - | Q30: =IF(ISNUMBER(O30),0.00013686*Psp*Mwe*(O30)^2/(Tse+460)/Cp^2,"-") -> - | R30: =IF(ISNUMBER(P30),0.00013686*Psp*Mwe*(P30)^2/(Tse+460)/Cp^2,"-") -> - | U30: =IF(ISNUMBER(E30),SQRT(E30),"-") -> - | V30: =IF(ISNUMBER(C30),ABS(C30),"-") -> - | X30: =IF(ISNUMBER(N30),IF((0.2603*vise*SQRT(Qse))/(N30)^1.5>0.3072,0.5,(0.2457+SQRT(0.3072-(0.2603*vise*SQRT(Qse))/(N30)^1.5))),"-") -> - | Y30: =IF(ISNUMBER(N30),IF((0.4457+SQRT(0.569+(0.2603*vise*SQRT(Qse))/(N30)^1.5))>1.5,1.5,(0.4457+SQRT(0.569+(0.2603*vise*SQRT(Qse))/(N30)^1.5))),"-") -> -
B31: =B30+1 -> 10 | F31: =IF(ISNUMBER(E31),E31*(Cp/Cpp)^2,"-") -> - | G31: =IF(ISNUMBER(F31),IF(A<7.227,F31*(1/(1-22/Ai))^2,"-"),"-") -> - | N31: =IF(ISNUMBER(Qse),3.055775*Qse/(M31)^2,"-") -> - | O31: =IF(ISNUMBER(X31),N31*X31,"-") -> - | P31: =IF(ISNUMBER(Y31),N31*Y31,"-") -> - | Q31: =IF(ISNUMBER(O31),0.00013686*Psp*Mwe*(O31)^2/(Tse+460)/Cp^2,"-") -> - | R31: =IF(ISNUMBER(P31),0.00013686*Psp*Mwe*(P31)^2/(Tse+460)/Cp^2,"-") -> - | U31: =IF(ISNUMBER(E31),SQRT(E31),"-") -> - | V31: =IF(ISNUMBER(C31),ABS(C31),"-") -> - | X31: =IF(ISNUMBER(N31),IF((0.2603*vise*SQRT(Qse))/(N31)^1.5>0.3072,0.5,(0.2457+SQRT(0.3072-(0.2603*vise*SQRT(Qse))/(N31)^1.5))),"-") -> - | Y31: =IF(ISNUMBER(N31),IF((0.4457+SQRT(0.569+(0.2603*vise*SQRT(Qse))/(N31)^1.5))>1.5,1.5,(0.4457+SQRT(0.569+(0.2603*vise*SQRT(Qse))/(N31)^1.5))),"-") -> -
B32: =B31+1 -> 11 | F32: =IF(ISNUMBER(E32),E32*(Cp/Cpp)^2,"-") -> - | G32: =IF(ISNUMBER(F32),IF(A<7.227,F32*(1/(1-22/Ai))^2,"-"),"-") -> - | N32: =IF(ISNUMBER(Qse),3.055775*Qse/(M32)^2,"-") -> - | O32: =IF(ISNUMBER(X32),N32*X32,"-") -> - | P32: =IF(ISNUMBER(Y32),N32*Y32,"-") -> - | Q32: =IF(ISNUMBER(O32),0.00013686*Psp*Mwe*(O32)^2/(Tse+460)/Cp^2,"-") -> - | R32: =IF(ISNUMBER(P32),0.00013686*Psp*Mwe*(P32)^2/(Tse+460)/Cp^2,"-") -> - | U32: =IF(ISNUMBER(E32),SQRT(E32),"-") -> - | V32: =IF(ISNUMBER(C32),ABS(C32),"-") -> - | X32: =IF(ISNUMBER(N32),IF((0.2603*vise*SQRT(Qse))/(N32)^1.5>0.3072,0.5,(0.2457+SQRT(0.3072-(0.2603*vise*SQRT(Qse))/(N32)^1.5))),"-") -> - | Y32: =IF(ISNUMBER(N32),IF((0.4457+SQRT(0.569+(0.2603*vise*SQRT(Qse))/(N32)^1.5))>1.5,1.5,(0.4457+SQRT(0.569+(0.2603*vise*SQRT(Qse))/(N32)^1.5))),"-") -> -
B33: =B32+1 -> 12 | F33: =IF(ISNUMBER(E33),E33*(Cp/Cpp)^2,"-") -> - | G33: =IF(ISNUMBER(F33),IF(A<7.227,F33*(1/(1-22/Ai))^2,"-"),"-") -> - | N33: =IF(ISNUMBER(Qse),3.055775*Qse/(M33)^2,"-") -> - | O33: =IF(ISNUMBER(X33),N33*X33,"-") -> - | P33: =IF(ISNUMBER(Y33),N33*Y33,"-") -> - | Q33: =IF(ISNUMBER(O33),0.00013686*Psp*Mwe*(O33)^2/(Tse+460)/Cp^2,"-") -> - | R33: =IF(ISNUMBER(P33),0.00013686*Psp*Mwe*(P33)^2/(Tse+460)/Cp^2,"-") -> - | U33: =IF(ISNUMBER(E33),SQRT(E33),"-") -> - | V33: =IF(ISNUMBER(C33),ABS(C33),"-") -> - | X33: =IF(ISNUMBER(N33),IF((0.2603*vise*SQRT(Qse))/(N33)^1.5>0.3072,0.5,(0.2457+SQRT(0.3072-(0.2603*vise*SQRT(Qse))/(N33)^1.5))),"-") -> - | Y33: =IF(ISNUMBER(N33),IF((0.4457+SQRT(0.569+(0.2603*vise*SQRT(Qse))/(N33)^1.5))>1.5,1.5,(0.4457+SQRT(0.569+(0.2603*vise*SQRT(Qse))/(N33)^1.5))),"-") -> -
B34: =B33+1 -> 13 | F34: =IF(ISNUMBER(E34),E34*(Cp/Cpp)^2,"-") -> - | G34: =IF(ISNUMBER(F34),IF(A<7.227,F34*(1/(1-22/Ai))^2,"-"),"-") -> - | U34: =IF(ISNUMBER(E34),SQRT(E34),"-") -> - | V34: =IF(ISNUMBER(C34),ABS(C34),"-") -> -
B35: =B34+1 -> 14 | F35: =IF(ISNUMBER(E35),E35*(Cp/Cpp)^2,"-") -> - | G35: =IF(ISNUMBER(F35),IF(A<7.227,F35*(1/(1-22/Ai))^2,"-"),"-") -> - | L35: NOTE: This spreadsheet contains circular references, therefore, iterative calculation must be turned on in Excel. In the 2010 version of Excel, the iterative calculation selection is located in File/Options/Formulas. | U35: =IF(ISNUMBER(E35),SQRT(E35),"-") -> - | V35: =IF(ISNUMBER(C35),ABS(C35),"-") -> -
B36: =B35+1 -> 15 | F36: =IF(ISNUMBER(E36),E36*(Cp/Cpp)^2,"-") -> - | G36: =IF(ISNUMBER(F36),IF(A<7.227,F36*(1/(1-22/Ai))^2,"-"),"-") -> - | U36: =IF(ISNUMBER(E36),SQRT(E36),"-") -> - | V36: =IF(ISNUMBER(C36),ABS(C36),"-") -> -
B37: =B36+1 -> 16 | F37: =IF(ISNUMBER(E37),E37*(Cp/Cpp)^2,"-") -> - | G37: =IF(ISNUMBER(F37),IF(A<7.227,F37*(1/(1-22/Ai))^2,"-"),"-") -> - | U37: =IF(ISNUMBER(E37),SQRT(E37),"-") -> - | V37: =IF(ISNUMBER(C37),ABS(C37),"-") -> -
B38: =B37+1 -> 17 | F38: =IF(ISNUMBER(E38),E38*(Cp/Cpp)^2,"-") -> - | G38: =IF(ISNUMBER(F38),IF(A<7.227,F38*(1/(1-22/Ai))^2,"-"),"-") -> - | U38: =IF(ISNUMBER(E38),SQRT(E38),"-") -> - | V38: =IF(ISNUMBER(C38),ABS(C38),"-") -> -
B39: =B38+1 -> 18 | F39: =IF(ISNUMBER(E39),E39*(Cp/Cpp)^2,"-") -> - | G39: =IF(ISNUMBER(F39),IF(A<7.227,F39*(1/(1-22/Ai))^2,"-"),"-") -> - | U39: =IF(ISNUMBER(E39),SQRT(E39),"-") -> - | V39: =IF(ISNUMBER(C39),ABS(C39),"-") -> -
B40: =B39+1 -> 19 | F40: =IF(ISNUMBER(E40),E40*(Cp/Cpp)^2,"-") -> - | G40: =IF(ISNUMBER(F40),IF(A<7.227,F40*(1/(1-22/Ai))^2,"-"),"-") -> - | U40: =IF(ISNUMBER(E40),SQRT(E40),"-") -> - | V40: =IF(ISNUMBER(C40),ABS(C40),"-") -> -
B41: =B40+1 -> 20 | F41: =IF(ISNUMBER(E41),E41*(Cp/Cpp)^2,"-") -> - | G41: =IF(ISNUMBER(F41),IF(A<7.227,F41*(1/(1-22/Ai))^2,"-"),"-") -> - | U41: =IF(ISNUMBER(E41),SQRT(E41),"-") -> - | V41: =IF(ISNUMBER(C41),ABS(C41),"-") -> -
B42: =B41+1 -> 21 | F42: =IF(ISNUMBER(E42),E42*(Cp/Cpp)^2,"-") -> - | G42: =IF(ISNUMBER(F42),IF(A<7.227,F42*(1/(1-22/Ai))^2,"-"),"-") -> - | U42: =IF(ISNUMBER(E42),SQRT(E42),"-") -> - | V42: =IF(ISNUMBER(C42),ABS(C42),"-") -> -
B43: =B42+1 -> 22 | F43: =IF(ISNUMBER(E43),E43*(Cp/Cpp)^2,"-") -> - | G43: =IF(ISNUMBER(F43),IF(A<7.227,F43*(1/(1-22/Ai))^2,"-"),"-") -> - | U43: =IF(ISNUMBER(E43),SQRT(E43),"-") -> - | V43: =IF(ISNUMBER(C43),ABS(C43),"-") -> -
B44: =B43+1 -> 23 | F44: =IF(ISNUMBER(E44),E44*(Cp/Cpp)^2,"-") -> - | G44: =IF(ISNUMBER(F44),IF(A<7.227,F44*(1/(1-22/Ai))^2,"-"),"-") -> - | U44: =IF(ISNUMBER(E44),SQRT(E44),"-") -> - | V44: =IF(ISNUMBER(C44),ABS(C44),"-") -> -
B45: =B44+1 -> 24 | F45: =IF(ISNUMBER(E45),E45*(Cp/Cpp)^2,"-") -> - | G45: =IF(ISNUMBER(F45),IF(A<7.227,F45*(1/(1-22/Ai))^2,"-"),"-") -> - | U45: =IF(ISNUMBER(E45),SQRT(E45),"-") -> - | V45: =IF(ISNUMBER(C45),ABS(C45),"-") -> -
...

Sheet Run 1
C2: Location: | D2: =IF(ISTEXT('Pre-Test'!D2:H2),'Pre-Test'!D2:H2,"") | J2: Start Time: | N2: RUN No.
C3: Date: | J3: End Time: | N3: JOB No. | O3: =IF(ISTEXT('Pre-Test'!P3),'Pre-Test'!P3,"")
B5: STACK DATA | F5: EQUIPMENT | J5: ESTIMATES | N5: +/- 50°F DH
C6: % Moisture: | D6: =IF(ISNUMBER(Bwse),Bwse,"-") -> - | E6: % est. | G6: METER BOX: | H6: =IF(ISTEXT(MB),MB,"-") -> - | J6: Ts (°F): | K6: =IF(ISNUMBER(Tse),Tse,"-") -> - | L6: Tm (°F): | M6: =IF(ISNUMBER(Tme),Tme,"-") -> - | N6: Ts-50° | O6: =IF(ISNUMBER(Tse),Tse-50,"-") -> - | P6: Ts+50° | Q6: =IF(ISNUMBER(Tse),Tse+50,"-") -> -
C7: Barometric: | E7: in Hg | G7: Y: | H7: =IF(ISNUMBER(Y),Y,"-") -> - | K7: Est. Qs: | L7: =IF(ISNUMBER(Qse),Qse,"-") -> - | M7: cfm | N7: Est. Qs: | O7: =IF(ISNUMBER(Qse),0.002837*vise*((Tsl+460)/Mwe/Ps_1)^0.2949,"-") -> - | P7: Est. Qs: | Q7: =IF(ISNUMBER(Qse),0.002837*vise*((Tsh+460)/Mwe/Ps_1)^0.2949,"-") -> -
C8: Static Press: | E8: in H2O | G8: DH@: | H8: =IF(ISNUMBER(dHa),dHa,"-") -> - | I8: in H2O | K8: Est. ms: | L8: =IF(ISNUMBER(vise),vise,"-") -> - | M8: mpoise | N8: Est. ms: | O8: =IF(ISNUMBER(Tsl),-150.3162+13.4622*SQRT(Tsl+460)+3861530/(Tsl+460)^2+0.591123*(1-Bwse/100)*OO/100-91.9723*Bwse/100+0.0000151761*Bwse/100*(Tsl+460)^2,"-") -> - | P8: Est. ms: | Q8: =IF(ISNUMBER(Tsh),-150.3162+13.4622*SQRT(Tsh+460)+3861530/(Tsh+460)^2+0.591123*(1-Bwse/100)*OO/100-91.9723*Bwse/100+0.0000151761*Bwse/100*(Tsh+460)^2,"-") -> -
C9: Stack Press: | D9: =IF(AND(ISNUMBER(Pg_1),ISNUMBER(Pbar_1)),Pbar_1+Pg_1/13.6,"-") -> - | E9: in Hg | F9: Cp': | G9: =IF(ISNUMBER(Cpp),Cpp,"-") -> - | H9: S/N | I9: =IF(OR(ISNUMBER('Pre-Test'!R11),ISTEXT('Pre-Test'!R11)),'Pre-Test'!R11,"-") -> - | K9: Est. DH: | L9: =IF(ISNUMBER(dHe),dHe,"-") -> - | M9: in H2O | N9: Est. DH: | O9: =IF(ISNUMBER(dHe),(Qse*(1-Bwse/100)*Ps_1/(Tsl+460))^2*(Tme+460)*Md*(1.083)*dHa/Pbar_1,"-") -> - | P9: Est. DH: | Q9: =IF(ISNUMBER(dHe),(Qse*(1-Bwse/100)*Ps_1/(Tsh+460))^2*(Tme+460)*Md*(1.083)*dHa/Pbar_1,"-") -> -
C10: %CO2: | D10: =IF(ISNUMBER(COO),COO,"-") -> - | E10: % | F10: Cp: | G10: =IF(ISNUMBER(Cp),Cp,"-") -> - | H10: S/N | I10: =IF(OR(ISNUMBER('Pre-Test'!R11),ISTEXT('Pre-Test'!R11)),'Pre-Test'!R11,"-") -> - | J10: LEAK CHECKS
C11: %O2: | D11: =IF(ISNUMBER(OO),OO,"-") -> - | E11: % | G11: Nozzle Dia: | H11: =IF(ISNUMBER(Dn),Dn,"-") -> - | I11: inches | K11: DGM initial | P11: cf
C12: %N2/CO: | D12: =IF(ISNUMBER(NN),NN,"-") -> - | E12: % | G12: Stack Area: | H12: =IF(ISNUMBER(A),A,"-") -> - | I12: ft2 | K12: DGM final | P12: cf
C13: Md: | D13: =IF(ISNUMBER(Md),Md,"-") -> - | E13: lb/lb-mole | G13: # of Points: | I13: points | K13: Time | P13: min.
C14: Est. Mw: | D14: =IF(ISNUMBER(Mwe),Mwe,"-") -> - | E14: lb/lb-mole | F14: Run Time: | I14: min | K14: Leak Rate | L14: =IF(ISNUMBER(L13),(L12-L11)/L13,"-") -> - | N14: =IF(ISNUMBER(N13),(N12-N11)/N13,"-") -> - | P14: cfm
C15: Tstd: | D15: =IF(ISNUMBER(Tstd),Tstd,"-") -> 528 | E15: °R | G15: Pstd: | H15: =IF(ISNUMBER(Pstd),Pstd,"-") -> 29.92 | I15: in Hg | K15: Vacuum | P15: in. Hg
B17: Sample Point | C17: Clock Time (min) | D17: Dry Gas Meter Reading (ft3) | F17: Pitot | G17: Gas Temperatures (°F) | J17: Orifice Press. | L17: Pump | M17: Gas Temps
F18: DP | G18: DGM | J18: DH (in H20) | L18: Vac. | M18: (°F) | O18: Imp. | P18: Qs (acfm) | Q18: D50 [10 mm] | R18: D50 [2.5 mm] | U18: sqrt(DP) (in. H2O) | V18: Vs (fps) | W18: Vms (dscf) | X18: QSst (dscfm) | Y18: Viscocity (mm) | Z18: Nre Actual | AA18: Re-estim. Cr50 | AC18: DPmin (in H2O) | AD18: DPmax (in H2O) | AE18: Vn (fps) | AF18: Vmin (fps) | AG18: Vmax (fps) | AH18: Rmin | AI18: Rmax
F19: ("H2O) | G19: Inlet | H19: Outlet | I19: Stack | J19: Ideal | K19: Actual | L19: (in Hg) | M19: Probe | N19: Filter | O19: Exit
B20: 1 | C20: =IF(ISNUMBER(F20),MAX(ROUND(Cp/Cpp*U20/'Pre-Test'!$U$46*Tr_1*4/N_1,0)/4,2),"-") -> - | J20: =IF(ISNUMBER(I20),(Qse*(1-Bwse/100)*Ps_1/(I20+460))^2*1.083*(H20+460)*Md*dHa/Pbar_1,dHe) -> - | P20: =IF(ISNUMBER(D21),((D21-D20)*Y*(I20+460)/(AVERAGE(G20:H20)+460)*(Pbar_1+K20/13.6)/Ps_1)/(1-Bwse/100)/C20,"-") -> - | Q20: =IF(ISNUMBER(P20),0.15625*((I20+460)/Mwe/Ps_1)^0.2091*(Y20/P20)^0.7091,"-") -> - | R20: =IF(ISNUMBER(P20),IF(Z20<3162,0.0024302*(Y20/P20)^1.1791*SQRT(1/AA20)*((I20+460)/Ps_1/Mwe)^0.679,0.019723*(Y20/P20)^0.8058*SQRT(1/AA20)*((I20+460)/Ps_1/Mwe)^0.3058),"-") -> - | U20: =IF(ISNUMBER(F20),SQRT(F20),"-") -> - | V20: =IF(ISNUMBER(U20),85.49*Cp*U20*SQRT((I20+460)/Ps_1/Mwe),"-") -> - | W20: =IF(ISNUMBER(D21),Tstd/Pstd*Y*(D21-D20)*(Pbar_1+K20/13.6)/(AVERAGE(G20:H20)+460),"-") -> - | X20: =IF(ISNUMBER(W20),W20/C20,"-") -> - | Y20: =IF(ISNUMBER(I20),-150.3162+13.4622*SQRT(I20+460)+3861530/(I20+460)^2+0.591123*(1-Bwse/100)*OO-91.9723*Bwse/100+0.0000151761*Bwse/100*(I20+460)^2,"-") -> - | Z20: =IF(ISNUMBER(Y20),864000*Ps_1*Mwe/(I20+460)*P20/Y20,"-") -> - | AA20: =IF(ISNUMBER(Y20),1+0.0057193*(Y20/Ps_1/(IF(ISNUMBER(R20),R20,2.5))*SQRT((I20+460)/Mwe)),"-") -> - | AC20: =IF(ISNUMBER(AF20),0.00013686*Ps_1*Mwe*(AF20)^2/(I20+460)/Cp^2,"-") -> - | AD20: =IF(ISNUMBER(AG20),0.00013686*Ps_1*Mwe*(AG20)^2/(I20+460)/Cp^2,"-") -> - | AE20: =IF(ISNUMBER(P20),3.055775*P20/(Dn)^2,"-") -> - | AF20: =IF(ISNUMBER(AH20),AE20*AH20,"-") -> - | AG20: =IF(ISNUMBER(AI20),AE20*AI20,"-") -> - | AH20: =IF(ISNUMBER(AE20),IF((0.2603*Y20*SQRT(P20))/(AE20)^1.5>0.3072,0.5,(0.2457+SQRT(0.3072-(0.2603*Y20*SQRT(P20))/(AE20)^1.5))),"-") -> - | AI20: =IF(ISNUMBER(AE20),IF((0.4457+SQRT(0.569+(0.2603*Y20*SQRT(P20))/(AE20)^1.5))>1.5,1.5,(0.4457+SQRT(0.569+(0.2603*Y20*SQRT(P20))/(AE20)^1.5))),"-") -> -
B21: 2 | C21: =IF(2>N_1,"-",IF(ISNUMBER(F21),MAX(ROUND(Cp/Cpp*U21/'Pre-Test'!$U$46*Tr_1*4/N_1,0)/4,2)+C20,"-")) -> - | J21: =IF(ISNUMBER(I21),(Qse*(1-Bwse/100)*Ps_1/(I21+460))^2*1.083*(H21+460)*Md*dHa/Pbar_1,"-") -> - | P21: =IF(ISNUMBER(D22),((D22-D21)*Y*(I21+460)/(AVERAGE(G21:H21)+460)*(Pbar_1+K21/13.6)/Ps_1)/(1-Bwse/100)/(C21-C20),"-") -> - | Q21: =IF(ISNUMBER(P21),0.15625*((I21+460)/Mwe/Ps_1)^0.2091*(Y21/P21)^0.7091,"-") -> - | R21: =IF(ISNUMBER(P21),IF(Z21<3162,0.0024302*(Y21/P21)^1.1791*SQRT(1/AA21)*((I21+460)/Ps_1/Mwe)^0.679,0.019723*(Y21/P21)^0.8058*SQRT(1/AA21)*((I21+460)/Ps_1/Mwe)^0.3058),"-") -> - | U21: =IF(ISNUMBER(F21),SQRT(F21),"-") -> - | V21: =IF(ISNUMBER(U21),85.49*Cp*U21*SQRT((I21+460)/Ps_1/Mwe),"-") -> - | W21: =IF(ISNUMBER(D22),Tstd/Pstd*Y*(D22-D21)*(Pbar_1+K21/13.6)/(AVERAGE(G21:H21)+460),"-") -> - | X21: =IF(ISNUMBER(W21),W21/(C21-C20),"-") -> - | Y21: =IF(ISNUMBER(I21),-150.3162+13.4622*SQRT(I21+460)+3861530/(I21+460)^2+0.591123*(1-Bwse/100)*OO-91.9723*Bwse/100+0.0000151761*Bwse/100*(I21+460)^2,"-") -> - | Z21: =IF(ISNUMBER(Y21),864000*Ps_1*Mwe/(I21+460)*P21/Y21,"-") -> - | AA21: =IF(ISNUMBER(Y21),1+0.0057193*(Y21/Ps_1/(IF(ISNUMBER(R21),R21,2.5))*SQRT((I21+460)/Mwe)),"-") -> - | AC21: =IF(ISNUMBER(AF21),0.00013686*Ps_1*Mwe*(AF21)^2/(I21+460)/Cp^2,"-") -> - | AD21: =IF(ISNUMBER(AG21),0.00013686*Ps_1*Mwe*(AG21)^2/(I21+460)/Cp^2,"-") -> - | AE21: =IF(ISNUMBER(P21),3.055775*P21/(Dn)^2,"-") -> - | AF21: =IF(ISNUMBER(AH21),AE21*AH21,"-") -> - | AG21: =IF(ISNUMBER(AI21),AE21*AI21,"-") -> - | AH21: =IF(ISNUMBER(AE21),IF((0.2603*Y21*SQRT(P21))/(AE21)^1.5>0.3072,0.5,(0.2457+SQRT(0.3072-(0.2603*Y21*SQRT(P21))/(AE21)^1.5))),"-") -> - | AI21: =IF(ISNUMBER(AE21),IF((0.4457+SQRT(0.569+(0.2603*Y21*SQRT(P21))/(AE21)^1.5))>1.5,1.5,(0.4457+SQRT(0.569+(0.2603*Y21*SQRT(P21))/(AE21)^1.5))),"-") -> -
B22: 3 | C22: =IF(3>N_1,"-",IF(ISNUMBER(F22),MAX(ROUND(Cp/Cpp*U22/'Pre-Test'!$U$46*Tr_1*4/N_1,0)/4,2)+C21,"-")) -> - | J22: =IF(ISNUMBER(I22),(Qse*(1-Bwse/100)*Ps_1/(I22+460))^2*1.083*(H22+460)*Md*dHa/Pbar_1,"-") -> - | P22: =IF(ISNUMBER(D23),((D23-D22)*Y*(I22+460)/(AVERAGE(G22:H22)+460)*(Pbar_1+K22/13.6)/Ps_1)/(1-Bwse/100)/(C22-C21),"-") -> - | Q22: =IF(ISNUMBER(P22),0.15625*((I22+460)/Mwe/Ps_1)^0.2091*(Y22/P22)^0.7091,"-") -> - | R22: =IF(ISNUMBER(P22),IF(Z22<3162,0.0024302*(Y22/P22)^1.1791*SQRT(1/AA22)*((I22+460)/Ps_1/Mwe)^0.679,0.019723*(Y22/P22)^0.8058*SQRT(1/AA22)*((I22+460)/Ps_1/Mwe)^0.3058),"-") -> - | U22: =IF(ISNUMBER(F22),SQRT(F22),"-") -> - | V22: =IF(ISNUMBER(U22),85.49*Cp*U22*SQRT((I22+460)/Ps_1/Mwe),"-") -> - | W22: =IF(ISNUMBER(D23),Tstd/Pstd*Y*(D23-D22)*(Pbar_1+K22/13.6)/(AVERAGE(G22:H22)+460),"-") -> - | X22: =IF(ISNUMBER(W22),W22/(C22-C21),"-") -> - | Y22: =IF(ISNUMBER(I22),-150.3162+13.4622*SQRT(I22+460)+3861530/(I22+460)^2+0.591123*(1-Bwse/100)*OO-91.9723*Bwse/100+0.0000151761*Bwse/100*(I22+460)^2,"-") -> - | Z22: =IF(ISNUMBER(Y22),864000*Ps_1*Mwe/(I22+460)*P22/Y22,"-") -> - | AA22: =IF(ISNUMBER(Y22),1+0.0057193*(Y22/Ps_1/(IF(ISNUMBER(R22),R22,2.5))*SQRT((I22+460)/Mwe)),"-") -> - | AC22: =IF(ISNUMBER(AF22),0.00013686*Ps_1*Mwe*(AF22)^2/(I22+460)/Cp^2,"-") -> - | AD22: =IF(ISNUMBER(AG22),0.00013686*Ps_1*Mwe*(AG22)^2/(I22+460)/Cp^2,"-") -> - | AE22: =IF(ISNUMBER(P22),3.055775*P22/(Dn)^2,"-") -> - | AF22: =IF(ISNUMBER(AH22),AE22*AH22,"-") -> - | AG22: =IF(ISNUMBER(AI22),AE22*AI22,"-") -> - | AH22: =IF(ISNUMBER(AE22),IF((0.2603*Y22*SQRT(P22))/(AE22)^1.5>0.3072,0.5,(0.2457+SQRT(0.3072-(0.2603*Y22*SQRT(P22))/(AE22)^1.5))),"-") -> - | AI22: =IF(ISNUMBER(AE22),IF((0.4457+SQRT(0.569+(0.2603*Y22*SQRT(P22))/(AE22)^1.5))>1.5,1.5,(0.4457+SQRT(0.569+(0.2603*Y22*SQRT(P22))/(AE22)^1.5))),"-") -> -
B23: 4 | C23: =IF(4>N_1,"-",IF(ISNUMBER(F23),MAX(ROUND(Cp/Cpp*U23/'Pre-Test'!$U$46*Tr_1*4/N_1,0)/4,2)+C22,"-")) -> - | J23: =IF(ISNUMBER(I23),(Qse*(1-Bwse/100)*Ps_1/(I23+460))^2*1.083*(H23+460)*Md*dHa/Pbar_1,"-") -> - | P23: =IF(ISNUMBER(D24),((D24-D23)*Y*(I23+460)/(AVERAGE(G23:H23)+460)*(Pbar_1+K23/13.6)/Ps_1)/(1-Bwse/100)/(C23-C22),"-") -> - | Q23: =IF(ISNUMBER(P23),0.15625*((I23+460)/Mwe/Ps_1)^0.2091*(Y23/P23)^0.7091,"-") -> - | R23: =IF(ISNUMBER(P23),IF(Z23<3162,0.0024302*(Y23/P23)^1.1791*SQRT(1/AA23)*((I23+460)/Ps_1/Mwe)^0.679,0.019723*(Y23/P23)^0.8058*SQRT(1/AA23)*((I23+460)/Ps_1/Mwe)^0.3058),"-") -> - | U23: =IF(ISNUMBER(F23),SQRT(F23),"-") -> - | V23: =IF(ISNUMBER(U23),85.49*Cp*U23*SQRT((I23+460)/Ps_1/Mwe),"-") -> - | W23: =IF(ISNUMBER(D24),Tstd/Pstd*Y*(D24-D23)*(Pbar_1+K23/13.6)/(AVERAGE(G23:H23)+460),"-") -> - | X23: =IF(ISNUMBER(W23),W23/(C23-C22),"-") -> - | Y23: =IF(ISNUMBER(I23),-150.3162+13.4622*SQRT(I23+460)+3861530/(I23+460)^2+0.591123*(1-Bwse/100)*OO-91.9723*Bwse/100+0.0000151761*Bwse/100*(I23+460)^2,"-") -> - | Z23: =IF(ISNUMBER(Y23),864000*Ps_1*Mwe/(I23+460)*P23/Y23,"-") -> - | AA23: =IF(ISNUMBER(Y23),1+0.0057193*(Y23/Ps_1/(IF(ISNUMBER(R23),R23,2.5))*SQRT((I23+460)/Mwe)),"-") -> - | AC23: =IF(ISNUMBER(AF23),0.00013686*Ps_1*Mwe*(AF23)^2/(I23+460)/Cp^2,"-") -> - | AD23: =IF(ISNUMBER(AG23),0.00013686*Ps_1*Mwe*(AG23)^2/(I23+460)/Cp^2,"-") -> - | AE23: =IF(ISNUMBER(P23),3.055775*P23/(Dn)^2,"-") -> - | AF23: =IF(ISNUMBER(AH23),AE23*AH23,"-") -> - | AG23: =IF(ISNUMBER(AI23),AE23*AI23,"-") -> - | AH23: =IF(ISNUMBER(AE23),IF((0.2603*Y23*SQRT(P23))/(AE23)^1.5>0.3072,0.5,(0.2457+SQRT(0.3072-(0.2603*Y23*SQRT(P23))/(AE23)^1.5))),"-") -> - | AI23: =IF(ISNUMBER(AE23),IF((0.4457+SQRT(0.569+(0.2603*Y23*SQRT(P23))/(AE23)^1.5))>1.5,1.5,(0.4457+SQRT(0.569+(0.2603*Y23*SQRT(P23))/(AE23)^1.5))),"-") -> -
B24: 5 | C24: =IF(5>N_1,"-",IF(ISNUMBER(F24),MAX(ROUND(Cp/Cpp*U24/'Pre-Test'!$U$46*Tr_1*4/N_1,0)/4,2)+C23,"-")) -> - | J24: =IF(ISNUMBER(I24),(Qse*(1-Bwse/100)*Ps_1/(I24+460))^2*1.083*(H24+460)*Md*dHa/Pbar_1,"-") -> - | P24: =IF(ISNUMBER(D25),((D25-D24)*Y*(I24+460)/(AVERAGE(G24:H24)+460)*(Pbar_1+K24/13.6)/Ps_1)/(1-Bwse/100)/(C24-C23),"-") -> - | Q24: =IF(ISNUMBER(P24),0.15625*((I24+460)/Mwe/Ps_1)^0.2091*(Y24/P24)^0.7091,"-") -> - | R24: =IF(ISNUMBER(P24),IF(Z24<3162,0.0024302*(Y24/P24)^1.1791*SQRT(1/AA24)*((I24+460)/Ps_1/Mwe)^0.679,0.019723*(Y24/P24)^0.8058*SQRT(1/AA24)*((I24+460)/Ps_1/Mwe)^0.3058),"-") -> - | U24: =IF(ISNUMBER(F24),SQRT(F24),"-") -> - | V24: =IF(ISNUMBER(U24),85.49*Cp*U24*SQRT((I24+460)/Ps_1/Mwe),"-") -> - | W24: =IF(ISNUMBER(D25),Tstd/Pstd*Y*(D25-D24)*(Pbar_1+K24/13.6)/(AVERAGE(G24:H24)+460),"-") -> - | X24: =IF(ISNUMBER(W24),W24/(C24-C23),"-") -> - | Y24: =IF(ISNUMBER(I24),-150.3162+13.4622*SQRT(I24+460)+3861530/(I24+460)^2+0.591123*(1-Bwse/100)*OO-91.9723*Bwse/100+0.0000151761*Bwse/100*(I24+460)^2,"-") -> - | Z24: =IF(ISNUMBER(Y24),864000*Ps_1*Mwe/(I24+460)*P24/Y24,"-") -> - | AA24: =IF(ISNUMBER(Y24),1+0.0057193*(Y24/Ps_1/(IF(ISNUMBER(R24),R24,2.5))*SQRT((I24+460)/Mwe)),"-") -> - | AC24: =IF(ISNUMBER(AF24),0.00013686*Ps_1*Mwe*(AF24)^2/(I24+460)/Cp^2,"-") -> - | AD24: =IF(ISNUMBER(AG24),0.00013686*Ps_1*Mwe*(AG24)^2/(I24+460)/Cp^2,"-") -> - | AE24: =IF(ISNUMBER(P24),3.055775*P24/(Dn)^2,"-") -> - | AF24: =IF(ISNUMBER(AH24),AE24*AH24,"-") -> - | AG24: =IF(ISNUMBER(AI24),AE24*AI24,"-") -> - | AH24: =IF(ISNUMBER(AE24),IF((0.2603*Y24*SQRT(P24))/(AE24)^1.5>0.3072,0.5,(0.2457+SQRT(0.3072-(0.2603*Y24*SQRT(P24))/(AE24)^1.5))),"-") -> - | AI24: =IF(ISNUMBER(AE24),IF((0.4457+SQRT(0.569+(0.2603*Y24*SQRT(P24))/(AE24)^1.5))>1.5,1.5,(0.4457+SQRT(0.569+(0.2603*Y24*SQRT(P24))/(AE24)^1.5))),"-") -> -
B25: 6 | C25: =IF(6>N_1,"-",IF(ISNUMBER(F25),MAX(ROUND(Cp/Cpp*U25/'Pre-Test'!$U$46*Tr_1*4/N_1,0)/4,2)+C24,"-")) -> - | J25: =IF(ISNUMBER(I25),(Qse*(1-Bwse/100)*Ps_1/(I25+460))^2*1.083*(H25+460)*Md*dHa/Pbar_1,"-") -> - | P25: =IF(ISNUMBER(D26),((D26-D25)*Y*(I25+460)/(AVERAGE(G25:H25)+460)*(Pbar_1+K25/13.6)/Ps_1)/(1-Bwse/100)/(C25-C24),"-") -> - | Q25: =IF(ISNUMBER(P25),0.15625*((I25+460)/Mwe/Ps_1)^0.2091*(Y25/P25)^0.7091,"-") -> - | R25: =IF(ISNUMBER(P25),IF(Z25<3162,0.0024302*(Y25/P25)^1.1791*SQRT(1/AA25)*((I25+460)/Ps_1/Mwe)^0.679,0.019723*(Y25/P25)^0.8058*SQRT(1/AA25)*((I25+460)/Ps_1/Mwe)^0.3058),"-") -> - | U25: =IF(ISNUMBER(F25),SQRT(F25),"-") -> - | V25: =IF(ISNUMBER(U25),85.49*Cp*U25*SQRT((I25+460)/Ps_1/Mwe),"-") -> - | W25: =IF(ISNUMBER(D26),Tstd/Pstd*Y*(D26-D25)*(Pbar_1+K25/13.6)/(AVERAGE(G25:H25)+460),"-") -> - | X25: =IF(ISNUMBER(W25),W25/(C25-C24),"-") -> - | Y25: =IF(ISNUMBER(I25),-150.3162+13.4622*SQRT(I25+460)+3861530/(I25+460)^2+0.591123*(1-Bwse/100)*OO-91.9723*Bwse/100+0.0000151761*Bwse/100*(I25+460)^2,"-") -> - | Z25: =IF(ISNUMBER(Y25),864000*Ps_1*Mwe/(I25+460)*P25/Y25,"-") -> - | AA25: =IF(ISNUMBER(Y25),1+0.0057193*(Y25/Ps_1/(IF(ISNUMBER(R25),R25,2.5))*SQRT((I25+460)/Mwe)),"-") -> - | AC25: =IF(ISNUMBER(AF25),0.00013686*Ps_1*Mwe*(AF25)^2/(I25+460)/Cp^2,"-") -> - | AD25: =IF(ISNUMBER(AG25),0.00013686*Ps_1*Mwe*(AG25)^2/(I25+460)/Cp^2,"-") -> - | AE25: =IF(ISNUMBER(P25),3.055775*P25/(Dn)^2,"-") -> - | AF25: =IF(ISNUMBER(AH25),AE25*AH25,"-") -> - | AG25: =IF(ISNUMBER(AI25),AE25*AI25,"-") -> - | AH25: =IF(ISNUMBER(AE25),IF((0.2603*Y25*SQRT(P25))/(AE25)^1.5>0.3072,0.5,(0.2457+SQRT(0.3072-(0.2603*Y25*SQRT(P25))/(AE25)^1.5))),"-") -> - | AI25: =IF(ISNUMBER(AE25),IF((0.4457+SQRT(0.569+(0.2603*Y25*SQRT(P25))/(AE25)^1.5))>1.5,1.5,(0.4457+SQRT(0.569+(0.2603*Y25*SQRT(P25))/(AE25)^1.5))),"-") -> -
B26: 7 | C26: =IF(7>N_1,"-",IF(ISNUMBER(F26),MAX(ROUND(Cp/Cpp*U26/'Pre-Test'!$U$46*Tr_1*4/N_1,0)/4,2)+C25,"-")) -> - | J26: =IF(ISNUMBER(I26),(Qse*(1-Bwse/100)*Ps_1/(I26+460))^2*1.083*(H26+460)*Md*dHa/Pbar_1,"-") -> - | P26: =IF(ISNUMBER(D27),((D27-D26)*Y*(I26+460)/(AVERAGE(G26:H26)+460)*(Pbar_1+K26/13.6)/Ps_1)/(1-Bwse/100)/(C26-C25),"-") -> - | Q26: =IF(ISNUMBER(P26),0.15625*((I26+460)/Mwe/Ps_1)^0.2091*(Y26/P26)^0.7091,"-") -> - | R26: =IF(ISNUMBER(P26),IF(Z26<3162,0.0024302*(Y26/P26)^1.1791*SQRT(1/AA26)*((I26+460)/Ps_1/Mwe)^0.679,0.019723*(Y26/P26)^0.8058*SQRT(1/AA26)*((I26+460)/Ps_1/Mwe)^0.3058),"-") -> - | U26: =IF(ISNUMBER(F26),SQRT(F26),"-") -> - | V26: =IF(ISNUMBER(U26),85.49*Cp*U26*SQRT((I26+460)/Ps_1/Mwe),"-") -> - | W26: =IF(ISNUMBER(D27),Tstd/Pstd*Y*(D27-D26)*(Pbar_1+K26/13.6)/(AVERAGE(G26:H26)+460),"-") -> - | X26: =IF(ISNUMBER(W26),W26/(C26-C25),"-") -> - | Y26: =IF(ISNUMBER(I26),-150.3162+13.4622*SQRT(I26+460)+3861530/(I26+460)^2+0.591123*(1-Bwse/100)*OO-91.9723*Bwse/100+0.0000151761*Bwse/100*(I26+460)^2,"-") -> - | Z26: =IF(ISNUMBER(Y26),864000*Ps_1*Mwe/(I26+460)*P26/Y26,"-") -> - | AA26: =IF(ISNUMBER(Y26),1+0.0057193*(Y26/Ps_1/(IF(ISNUMBER(R26),R26,2.5))*SQRT((I26+460)/Mwe)),"-") -> - | AC26: =IF(ISNUMBER(AF26),0.00013686*Ps_1*Mwe*(AF26)^2/(I26+460)/Cp^2,"-") -> - | AD26: =IF(ISNUMBER(AG26),0.00013686*Ps_1*Mwe*(AG26)^2/(I26+460)/Cp^2,"-") -> - | AE26: =IF(ISNUMBER(P26),3.055775*P26/(Dn)^2,"-") -> - | AF26: =IF(ISNUMBER(AH26),AE26*AH26,"-") -> - | AG26: =IF(ISNUMBER(AI26),AE26*AI26,"-") -> - | AH26: =IF(ISNUMBER(AE26),IF((0.2603*Y26*SQRT(P26))/(AE26)^1.5>0.3072,0.5,(0.2457+SQRT(0.3072-(0.2603*Y26*SQRT(P26))/(AE26)^1.5))),"-") -> - | AI26: =IF(ISNUMBER(AE26),IF((0.4457+SQRT(0.569+(0.2603*Y26*SQRT(P26))/(AE26)^1.5))>1.5,1.5,(0.4457+SQRT(0.569+(0.2603*Y26*SQRT(P26))/(AE26)^1.5))),"-") -> -
B27: 8 | C27: =IF(8>N_1,"-",IF(ISNUMBER(F27),MAX(ROUND(Cp/Cpp*U27/'Pre-Test'!$U$46*Tr_1*4/N_1,0)/4,2)+C26,"-")) -> - | J27: =IF(ISNUMBER(I27),(Qse*(1-Bwse/100)*Ps_1/(I27+460))^2*1.083*(H27+460)*Md*dHa/Pbar_1,"-") -> - | P27: =IF(ISNUMBER(D28),((D28-D27)*Y*(I27+460)/(AVERAGE(G27:H27)+460)*(Pbar_1+K27/13.6)/Ps_1)/(1-Bwse/100)/(C27-C26),"-") -> - | Q27: =IF(ISNUMBER(P27),0.15625*((I27+460)/Mwe/Ps_1)^0.2091*(Y27/P27)^0.7091,"-") -> - | R27: =IF(ISNUMBER(P27),IF(Z27<3162,0.0024302*(Y27/P27)^1.1791*SQRT(1/AA27)*((I27+460)/Ps_1/Mwe)^0.679,0.019723*(Y27/P27)^0.8058*SQRT(1/AA27)*((I27+460)/Ps_1/Mwe)^0.3058),"-") -> - | U27: =IF(ISNUMBER(F27),SQRT(F27),"-") -> - | V27: =IF(ISNUMBER(U27),85.49*Cp*U27*SQRT((I27+460)/Ps_1/Mwe),"-") -> - | W27: =IF(ISNUMBER(D28),Tstd/Pstd*Y*(D28-D27)*(Pbar_1+K27/13.6)/(AVERAGE(G27:H27)+460),"-") -> - | X27: =IF(ISNUMBER(W27),W27/(C27-C26),"-") -> - | Y27: =IF(ISNUMBER(I27),-150.3162+13.4622*SQRT(I27+460)+3861530/(I27+460)^2+0.591123*(1-Bwse/100)*OO-91.9723*Bwse/100+0.0000151761*Bwse/100*(I27+460)^2,"-") -> - | Z27: =IF(ISNUMBER(Y27),864000*Ps_1*Mwe/(I27+460)*P27/Y27,"-") -> - | AA27: =IF(ISNUMBER(Y27),1+0.0057193*(Y27/Ps_1/(IF(ISNUMBER(R27),R27,2.5))*SQRT((I27+460)/Mwe)),"-") -> - | AC27: =IF(ISNUMBER(AF27),0.00013686*Ps_1*Mwe*(AF27)^2/(I27+460)/Cp^2,"-") -> - | AD27: =IF(ISNUMBER(AG27),0.00013686*Ps_1*Mwe*(AG27)^2/(I27+460)/Cp^2,"-") -> - | AE27: =IF(ISNUMBER(P27),3.055775*P27/(Dn)^2,"-") -> - | AF27: =IF(ISNUMBER(AH27),AE27*AH27,"-") -> - | AG27: =IF(ISNUMBER(AI27),AE27*AI27,"-") -> - | AH27: =IF(ISNUMBER(AE27),IF((0.2603*Y27*SQRT(P27))/(AE27)^1.5>0.3072,0.5,(0.2457+SQRT(0.3072-(0.2603*Y27*SQRT(P27))/(AE27)^1.5))),"-") -> - | AI27: =IF(ISNUMBER(AE27),IF((0.4457+SQRT(0.569+(0.2603*Y27*SQRT(P27))/(AE27)^1.5))>1.5,1.5,(0.4457+SQRT(0.569+(0.2603*Y27*SQRT(P27))/(AE27)^1.5))),"-") -> -
B28: 9 | C28: =IF(9>N_1,"-",IF(ISNUMBER(F28),MAX(ROUND(Cp/Cpp*U28/'Pre-Test'!$U$46*Tr_1*4/N_1,0)/4,2)+C27,"-")) -> - | J28: =IF(ISNUMBER(I28),(Qse*(1-Bwse/100)*Ps_1/(I28+460))^2*1.083*(H28+460)*Md*dHa/Pbar_1,"-") -> - | P28: =IF(ISNUMBER(D29),((D29-D28)*Y*(I28+460)/(AVERAGE(G28:H28)+460)*(Pbar_1+K28/13.6)/Ps_1)/(1-Bwse/100)/(C28-C27),"-") -> - | Q28: =IF(ISNUMBER(P28),0.15625*((I28+460)/Mwe/Ps_1)^0.2091*(Y28/P28)^0.7091,"-") -> - | R28: =IF(ISNUMBER(P28),IF(Z28<3162,0.0024302*(Y28/P28)^1.1791*SQRT(1/AA28)*((I28+460)/Ps_1/Mwe)^0.679,0.019723*(Y28/P28)^0.8058*SQRT(1/AA28)*((I28+460)/Ps_1/Mwe)^0.3058),"-") -> - | U28: =IF(ISNUMBER(F28),SQRT(F28),"-") -> - | V28: =IF(ISNUMBER(U28),85.49*Cp*U28*SQRT((I28+460)/Ps_1/Mwe),"-") -> - | W28: =IF(ISNUMBER(D29),Tstd/Pstd*Y*(D29-D28)*(Pbar_1+K28/13.6)/(AVERAGE(G28:H28)+460),"-") -> - | X28: =IF(ISNUMBER(W28),W28/(C28-C27),"-") -> - | Y28: =IF(ISNUMBER(I28),-150.3162+13.4622*SQRT(I28+460)+3861530/(I28+460)^2+0.591123*(1-Bwse/100)*OO-91.9723*Bwse/100+0.0000151761*Bwse/100*(I28+460)^2,"-") -> - | Z28: =IF(ISNUMBER(Y28),864000*Ps_1*Mwe/(I28+460)*P28/Y28,"-") -> - | AA28: =IF(ISNUMBER(Y28),1+0.0057193*(Y28/Ps_1/(IF(ISNUMBER(R28),R28,2.5))*SQRT((I28+460)/Mwe)),"-") -> - | AC28: =IF(ISNUMBER(AF28),0.00013686*Ps_1*Mwe*(AF28)^2/(I28+460)/Cp^2,"-") -> - | AD28: =IF(ISNUMBER(AG28),0.00013686*Ps_1*Mwe*(AG28)^2/(I28+460)/Cp^2,"-") -> - | AE28: =IF(ISNUMBER(P28),3.055775*P28/(Dn)^2,"-") -> - | AF28: =IF(ISNUMBER(AH28),AE28*AH28,"-") -> - | AG28: =IF(ISNUMBER(AI28),AE28*AI28,"-") -> - | AH28: =IF(ISNUMBER(AE28),IF((0.2603*Y28*SQRT(P28))/(AE28)^1.5>0.3072,0.5,(0.2457+SQRT(0.3072-(0.2603*Y28*SQRT(P28))/(AE28)^1.5))),"-") -> - | AI28: =IF(ISNUMBER(AE28),IF((0.4457+SQRT(0.569+(0.2603*Y28*SQRT(P28))/(AE28)^1.5))>1.5,1.5,(0.4457+SQRT(0.569+(0.2603*Y28*SQRT(P28))/(AE28)^1.5))),"-") -> -
B29: 10 | C29: =IF(10>N_1,"-",IF(ISNUMBER(F29),MAX(ROUND(Cp/Cpp*U29/'Pre-Test'!$U$46*Tr_1*4/N_1,0)/4,2)+C28,"-")) -> - | J29: =IF(ISNUMBER(I29),(Qse*(1-Bwse/100)*Ps_1/(I29+460))^2*1.083*(H29+460)*Md*dHa/Pbar_1,"-") -> - | P29: =IF(ISNUMBER(D30),((D30-D29)*Y*(I29+460)/(AVERAGE(G29:H29)+460)*(Pbar_1+K29/13.6)/Ps_1)/(1-Bwse/100)/(C29-C28),"-") -> - | Q29: =IF(ISNUMBER(P29),0.15625*((I29+460)/Mwe/Ps_1)^0.2091*(Y29/P29)^0.7091,"-") -> - | R29: =IF(ISNUMBER(P29),IF(Z29<3162,0.0024302*(Y29/P29)^1.1791*SQRT(1/AA29)*((I29+460)/Ps_1/Mwe)^0.679,0.019723*(Y29/P29)^0.8058*SQRT(1/AA29)*((I29+460)/Ps_1/Mwe)^0.3058),"-") -> - | U29: =IF(ISNUMBER(F29),SQRT(F29),"-") -> - | V29: =IF(ISNUMBER(U29),85.49*Cp*U29*SQRT((I29+460)/Ps_1/Mwe),"-") -> - | W29: =IF(ISNUMBER(D30),Tstd/Pstd*Y*(D30-D29)*(Pbar_1+K29/13.6)/(AVERAGE(G29:H29)+460),"-") -> - | X29: =IF(ISNUMBER(W29),W29/(C29-C28),"-") -> - | Y29: =IF(ISNUMBER(I29),-150.3162+13.4622*SQRT(I29+460)+3861530/(I29+460)^2+0.591123*(1-Bwse/100)*OO-91.9723*Bwse/100+0.0000151761*Bwse/100*(I29+460)^2,"-") -> - | Z29: =IF(ISNUMBER(Y29),864000*Ps_1*Mwe/(I29+460)*P29/Y29,"-") -> - | AA29: =IF(ISNUMBER(Y29),1+0.0057193*(Y29/Ps_1/(IF(ISNUMBER(R29),R29,2.5))*SQRT((I29+460)/Mwe)),"-") -> - | AC29: =IF(ISNUMBER(AF29),0.00013686*Ps_1*Mwe*(AF29)^2/(I29+460)/Cp^2,"-") -> - | AD29: =IF(ISNUMBER(AG29),0.00013686*Ps_1*Mwe*(AG29)^2/(I29+460)/Cp^2,"-") -> - | AE29: =IF(ISNUMBER(P29),3.055775*P29/(Dn)^2,"-") -> - | AF29: =IF(ISNUMBER(AH29),AE29*AH29,"-") -> - | AG29: =IF(ISNUMBER(AI29),AE29*AI29,"-") -> - | AH29: =IF(ISNUMBER(AE29),IF((0.2603*Y29*SQRT(P29))/(AE29)^1.5>0.3072,0.5,(0.2457+SQRT(0.3072-(0.2603*Y29*SQRT(P29))/(AE29)^1.5))),"-") -> - | AI29: =IF(ISNUMBER(AE29),IF((0.4457+SQRT(0.569+(0.2603*Y29*SQRT(P29))/(AE29)^1.5))>1.5,1.5,(0.4457+SQRT(0.569+(0.2603*Y29*SQRT(P29))/(AE29)^1.5))),"-") -> -
B30: 11 | C30: =IF(11>N_1,"-",IF(ISNUMBER(F30),MAX(ROUND(Cp/Cpp*U30/'Pre-Test'!$U$46*Tr_1*4/N_1,0)/4,2)+C29,"-")) -> - | J30: =IF(ISNUMBER(I30),(Qse*(1-Bwse/100)*Ps_1/(I30+460))^2*1.083*(H30+460)*Md*dHa/Pbar_1,"-") -> - | P30: =IF(ISNUMBER(D31),((D31-D30)*Y*(I30+460)/(AVERAGE(G30:H30)+460)*(Pbar_1+K30/13.6)/Ps_1)/(1-Bwse/100)/(C30-C29),"-") -> - | Q30: =IF(ISNUMBER(P30),0.15625*((I30+460)/Mwe/Ps_1)^0.2091*(Y30/P30)^0.7091,"-") -> - | R30: =IF(ISNUMBER(P30),IF(Z30<3162,0.0024302*(Y30/P30)^1.1791*SQRT(1/AA30)*((I30+460)/Ps_1/Mwe)^0.679,0.019723*(Y30/P30)^0.8058*SQRT(1/AA30)*((I30+460)/Ps_1/Mwe)^0.3058),"-") -> - | U30: =IF(ISNUMBER(F30),SQRT(F30),"-") -> - | V30: =IF(ISNUMBER(U30),85.49*Cp*U30*SQRT((I30+460)/Ps_1/Mwe),"-") -> - | W30: =IF(ISNUMBER(D31),Tstd/Pstd*Y*(D31-D30)*(Pbar_1+K30/13.6)/(AVERAGE(G30:H30)+460),"-") -> - | X30: =IF(ISNUMBER(W30),W30/(C30-C29),"-") -> - | Y30: =IF(ISNUMBER(I30),-150.3162+13.4622*SQRT(I30+460)+3861530/(I30+460)^2+0.591123*(1-Bwse/100)*OO-91.9723*Bwse/100+0.0000151761*Bwse/100*(I30+460)^2,"-") -> - | Z30: =IF(ISNUMBER(Y30),864000*Ps_1*Mwe/(I30+460)*P30/Y30,"-") -> - | AA30: =IF(ISNUMBER(Y30),1+0.0057193*(Y30/Ps_1/(IF(ISNUMBER(R30),R30,2.5))*SQRT((I30+460)/Mwe)),"-") -> - | AC30: =IF(ISNUMBER(AF30),0.00013686*Ps_1*Mwe*(AF30)^2/(I30+460)/Cp^2,"-") -> - | AD30: =IF(ISNUMBER(AG30),0.00013686*Ps_1*Mwe*(AG30)^2/(I30+460)/Cp^2,"-") -> - | AE30: =IF(ISNUMBER(P30),3.055775*P30/(Dn)^2,"-") -> - | AF30: =IF(ISNUMBER(AH30),AE30*AH30,"-") -> - | AG30: =IF(ISNUMBER(AI30),AE30*AI30,"-") -> - | AH30: =IF(ISNUMBER(AE30),IF((0.2603*Y30*SQRT(P30))/(AE30)^1.5>0.3072,0.5,(0.2457+SQRT(0.3072-(0.2603*Y30*SQRT(P30))/(AE30)^1.5))),"-") -> - | AI30: =IF(ISNUMBER(AE30),IF((0.4457+SQRT(0.569+(0.2603*Y30*SQRT(P30))/(AE30)^1.5))>1.5,1.5,(0.4457+SQRT(0.569+(0.2603*Y30*SQRT(P30))/(AE30)^1.5))),"-") -> -
B31: 12 | C31: =IF(12>N_1,"-",IF(ISNUMBER(F31),MAX(ROUND(Cp/Cpp*U31/'Pre-Test'!$U$46*Tr_1*4/N_1,0)/4,2)+C30,"-")) -> - | J31: =IF(ISNUMBER(I31),(Qse*(1-Bwse/100)*Ps_1/(I31+460))^2*1.083*(H31+460)*Md*dHa/Pbar_1,"-") -> - | P31: =IF(ISNUMBER(D32),((D32-D31)*Y*(I31+460)/(AVERAGE(G31:H31)+460)*(Pbar_1+K31/13.6)/Ps_1)/(1-Bwse/100)/(C31-C30),"-") -> - | Q31: =IF(ISNUMBER(P31),0.15625*((I31+460)/Mwe/Ps_1)^0.2091*(Y31/P31)^0.7091,"-") -> - | R31: =IF(ISNUMBER(P31),IF(Z31<3162,0.0024302*(Y31/P31)^1.1791*SQRT(1/AA31)*((I31+460)/Ps_1/Mwe)^0.679,0.019723*(Y31/P31)^0.8058*SQRT(1/AA31)*((I31+460)/Ps_1/Mwe)^0.3058),"-") -> - | U31: =IF(ISNUMBER(F31),SQRT(F31),"-") -> - | V31: =IF(ISNUMBER(U31),85.49*Cp*U31*SQRT((I31+460)/Ps_1/Mwe),"-") -> - | W31: =IF(ISNUMBER(D32),Tstd/Pstd*Y*(D32-D31)*(Pbar_1+K31/13.6)/(AVERAGE(G31:H31)+460),"-") -> - | X31: =IF(ISNUMBER(W31),W31/(C31-C30),"-") -> - | Y31: =IF(ISNUMBER(I31),-150.3162+13.4622*SQRT(I31+460)+3861530/(I31+460)^2+0.591123*(1-Bwse/100)*OO-91.9723*Bwse/100+0.0000151761*Bwse/100*(I31+460)^2,"-") -> - | Z31: =IF(ISNUMBER(Y31),864000*Ps_1*Mwe/(I31+460)*P31/Y31,"-") -> - | AA31: =IF(ISNUMBER(Y31),1+0.0057193*(Y31/Ps_1/(IF(ISNUMBER(R31),R31,2.5))*SQRT((I31+460)/Mwe)),"-") -> - | AC31: =IF(ISNUMBER(AF31),0.00013686*Ps_1*Mwe*(AF31)^2/(I31+460)/Cp^2,"-") -> - | AD31: =IF(ISNUMBER(AG31),0.00013686*Ps_1*Mwe*(AG31)^2/(I31+460)/Cp^2,"-") -> - | AE31: =IF(ISNUMBER(P31),3.055775*P31/(Dn)^2,"-") -> - | AF31: =IF(ISNUMBER(AH31),AE31*AH31,"-") -> - | AG31: =IF(ISNUMBER(AI31),AE31*AI31,"-") -> - | AH31: =IF(ISNUMBER(AE31),IF((0.2603*Y31*SQRT(P31))/(AE31)^1.5>0.3072,0.5,(0.2457+SQRT(0.3072-(0.2603*Y31*SQRT(P31))/(AE31)^1.5))),"-") -> - | AI31: =IF(ISNUMBER(AE31),IF((0.4457+SQRT(0.569+(0.2603*Y31*SQRT(P31))/(AE31)^1.5))>1.5,1.5,(0.4457+SQRT(0.569+(0.2603*Y31*SQRT(P31))/(AE31)^1.5))),"-") -> -
B32: 13 | C32: =IF(13>N_1,"-",IF(ISNUMBER(F32),MAX(ROUND(Cp/Cpp*U32/'Pre-Test'!$U$46*Tr_1*4/N_1,0)/4,2)+C31,"-")) -> - | J32: =IF(ISNUMBER(I32),(Qse*(1-Bwse/100)*Ps_1/(I32+460))^2*1.083*(H32+460)*Md*dHa/Pbar_1,"-") -> - | P32: =IF(ISNUMBER(D33),((D33-D32)*Y*(I32+460)/(AVERAGE(G32:H32)+460)*(Pbar_1+K32/13.6)/Ps_1)/(1-Bwse/100)/(C32-C31),"-") -> - | Q32: =IF(ISNUMBER(P32),0.15625*((I32+460)/Mwe/Ps_1)^0.2091*(Y32/P32)^0.7091,"-") -> - | R32: =IF(ISNUMBER(P32),IF(Z32<3162,0.0024302*(Y32/P32)^1.1791*SQRT(1/AA32)*((I32+460)/Ps_1/Mwe)^0.679,0.019723*(Y32/P32)^0.8058*SQRT(1/AA32)*((I32+460)/Ps_1/Mwe)^0.3058),"-") -> - | U32: =IF(ISNUMBER(F32),SQRT(F32),"-") -> - | V32: =IF(ISNUMBER(U32),85.49*Cp*U32*SQRT((I32+460)/Ps_1/Mwe),"-") -> - | W32: =IF(ISNUMBER(D33),Tstd/Pstd*Y*(D33-D32)*(Pbar_1+K32/13.6)/(AVERAGE(G32:H32)+460),"-") -> - | X32: =IF(ISNUMBER(W32),W32/(C32-C31),"-") -> - | Y32: =IF(ISNUMBER(I32),-150.3162+13.4622*SQRT(I32+460)+3861530/(I32+460)^2+0.591123*(1-Bwse/100)*OO-91.9723*Bwse/100+0.0000151761*Bwse/100*(I32+460)^2,"-") -> - | Z32: =IF(ISNUMBER(Y32),864000*Ps_1*Mwe/(I32+460)*P32/Y32,"-") -> - | AA32: =IF(ISNUMBER(Y32),1+0.0057193*(Y32/Ps_1/(IF(ISNUMBER(R32),R32,2.5))*SQRT((I32+460)/Mwe)),"-") -> - | AC32: =IF(ISNUMBER(AF32),0.00013686*Ps_1*Mwe*(AF32)^2/(I32+460)/Cp^2,"-") -> - | AD32: =IF(ISNUMBER(AG32),0.00013686*Ps_1*Mwe*(AG32)^2/(I32+460)/Cp^2,"-") -> - | AE32: =IF(ISNUMBER(P32),3.055775*P32/(Dn)^2,"-") -> - | AF32: =IF(ISNUMBER(AH32),AE32*AH32,"-") -> - | AG32: =IF(ISNUMBER(AI32),AE32*AI32,"-") -> - | AH32: =IF(ISNUMBER(AE32),IF((0.2603*Y32*SQRT(P32))/(AE32)^1.5>0.3072,0.5,(0.2457+SQRT(0.3072-(0.2603*Y32*SQRT(P32))/(AE32)^1.5))),"-") -> - | AI32: =IF(ISNUMBER(AE32),IF((0.4457+SQRT(0.569+(0.2603*Y32*SQRT(P32))/(AE32)^1.5))>1.5,1.5,(0.4457+SQRT(0.569+(0.2603*Y32*SQRT(P32))/(AE32)^1.5))),"-") -> -
B33: 14 | C33: =IF(14>N_1,"-",IF(ISNUMBER(F33),MAX(ROUND(Cp/Cpp*U33/'Pre-Test'!$U$46*Tr_1*4/N_1,0)/4,2)+C32,"-")) -> - | J33: =IF(ISNUMBER(I33),(Qse*(1-Bwse/100)*Ps_1/(I33+460))^2*1.083*(H33+460)*Md*dHa/Pbar_1,"-") -> - | P33: =IF(ISNUMBER(D34),((D34-D33)*Y*(I33+460)/(AVERAGE(G33:H33)+460)*(Pbar_1+K33/13.6)/Ps_1)/(1-Bwse/100)/(C33-C32),"-") -> - | Q33: =IF(ISNUMBER(P33),0.15625*((I33+460)/Mwe/Ps_1)^0.2091*(Y33/P33)^0.7091,"-") -> - | R33: =IF(ISNUMBER(P33),IF(Z33<3162,0.0024302*(Y33/P33)^1.1791*SQRT(1/AA33)*((I33+460)/Ps_1/Mwe)^0.679,0.019723*(Y33/P33)^0.8058*SQRT(1/AA33)*((I33+460)/Ps_1/Mwe)^0.3058),"-") -> - | U33: =IF(ISNUMBER(F33),SQRT(F33),"-") -> - | V33: =IF(ISNUMBER(U33),85.49*Cp*U33*SQRT((I33+460)/Ps_1/Mwe),"-") -> - | W33: =IF(ISNUMBER(D34),Tstd/Pstd*Y*(D34-D33)*(Pbar_1+K33/13.6)/(AVERAGE(G33:H33)+460),"-") -> - | X33: =IF(ISNUMBER(W33),W33/(C33-C32),"-") -> - | Y33: =IF(ISNUMBER(I33),-150.3162+13.4622*SQRT(I33+460)+3861530/(I33+460)^2+0.591123*(1-Bwse/100)*OO-91.9723*Bwse/100+0.0000151761*Bwse/100*(I33+460)^2,"-") -> - | Z33: =IF(ISNUMBER(Y33),864000*Ps_1*Mwe/(I33+460)*P33/Y33,"-") -> - | AA33: =IF(ISNUMBER(Y33),1+0.0057193*(Y33/Ps_1/(IF(ISNUMBER(R33),R33,2.5))*SQRT((I33+460)/Mwe)),"-") -> - | AC33: =IF(ISNUMBER(AF33),0.00013686*Ps_1*Mwe*(AF33)^2/(I33+460)/Cp^2,"-") -> - | AD33: =IF(ISNUMBER(AG33),0.00013686*Ps_1*Mwe*(AG33)^2/(I33+460)/Cp^2,"-") -> - | AE33: =IF(ISNUMBER(P33),3.055775*P33/(Dn)^2,"-") -> - | AF33: =IF(ISNUMBER(AH33),AE33*AH33,"-") -> - | AG33: =IF(ISNUMBER(AI33),AE33*AI33,"-") -> - | AH33: =IF(ISNUMBER(AE33),IF((0.2603*Y33*SQRT(P33))/(AE33)^1.5>0.3072,0.5,(0.2457+SQRT(0.3072-(0.2603*Y33*SQRT(P33))/(AE33)^1.5))),"-") -> - | AI33: =IF(ISNUMBER(AE33),IF((0.4457+SQRT(0.569+(0.2603*Y33*SQRT(P33))/(AE33)^1.5))>1.5,1.5,(0.4457+SQRT(0.569+(0.2603*Y33*SQRT(P33))/(AE33)^1.5))),"-") -> -
B34: 15 | C34: =IF(15>N_1,"-",IF(ISNUMBER(F34),MAX(ROUND(Cp/Cpp*U34/'Pre-Test'!$U$46*Tr_1*4/N_1,0)/4,2)+C33,"-")) -> - | J34: =IF(ISNUMBER(I34),(Qse*(1-Bwse/100)*Ps_1/(I34+460))^2*1.083*(H34+460)*Md*dHa/Pbar_1,"-") -> - | P34: =IF(ISNUMBER(D35),((D35-D34)*Y*(I34+460)/(AVERAGE(G34:H34)+460)*(Pbar_1+K34/13.6)/Ps_1)/(1-Bwse/100)/(C34-C33),"-") -> - | Q34: =IF(ISNUMBER(P34),0.15625*((I34+460)/Mwe/Ps_1)^0.2091*(Y34/P34)^0.7091,"-") -> - | R34: =IF(ISNUMBER(P34),IF(Z34<3162,0.0024302*(Y34/P34)^1.1791*SQRT(1/AA34)*((I34+460)/Ps_1/Mwe)^0.679,0.019723*(Y34/P34)^0.8058*SQRT(1/AA34)*((I34+460)/Ps_1/Mwe)^0.3058),"-") -> - | U34: =IF(ISNUMBER(F34),SQRT(F34),"-") -> - | V34: =IF(ISNUMBER(U34),85.49*Cp*U34*SQRT((I34+460)/Ps_1/Mwe),"-") -> - | W34: =IF(ISNUMBER(D35),Tstd/Pstd*Y*(D35-D34)*(Pbar_1+K34/13.6)/(AVERAGE(G34:H34)+460),"-") -> - | X34: =IF(ISNUMBER(W34),W34/(C34-C33),"-") -> - | Y34: =IF(ISNUMBER(I34),-150.3162+13.4622*SQRT(I34+460)+3861530/(I34+460)^2+0.591123*(1-Bwse/100)*OO-91.9723*Bwse/100+0.0000151761*Bwse/100*(I34+460)^2,"-") -> - | Z34: =IF(ISNUMBER(Y34),864000*Ps_1*Mwe/(I34+460)*P34/Y34,"-") -> - | AA34: =IF(ISNUMBER(Y34),1+0.0057193*(Y34/Ps_1/(IF(ISNUMBER(R34),R34,2.5))*SQRT((I34+460)/Mwe)),"-") -> - | AC34: =IF(ISNUMBER(AF34),0.00013686*Ps_1*Mwe*(AF34)^2/(I34+460)/Cp^2,"-") -> - | AD34: =IF(ISNUMBER(AG34),0.00013686*Ps_1*Mwe*(AG34)^2/(I34+460)/Cp^2,"-") -> - | AE34: =IF(ISNUMBER(P34),3.055775*P34/(Dn)^2,"-") -> - | AF34: =IF(ISNUMBER(AH34),AE34*AH34,"-") -> - | AG34: =IF(ISNUMBER(AI34),AE34*AI34,"-") -> - | AH34: =IF(ISNUMBER(AE34),IF((0.2603*Y34*SQRT(P34))/(AE34)^1.5>0.3072,0.5,(0.2457+SQRT(0.3072-(0.2603*Y34*SQRT(P34))/(AE34)^1.5))),"-") -> - | AI34: =IF(ISNUMBER(AE34),IF((0.4457+SQRT(0.569+(0.2603*Y34*SQRT(P34))/(AE34)^1.5))>1.5,1.5,(0.4457+SQRT(0.569+(0.2603*Y34*SQRT(P34))/(AE34)^1.5))),"-") -> -
B35: 16 | C35: =IF(16>N_1,"-",IF(ISNUMBER(F35),MAX(ROUND(Cp/Cpp*U35/'Pre-Test'!$U$46*Tr_1*4/N_1,0)/4,2)+C34,"-")) -> - | J35: =IF(ISNUMBER(I35),(Qse*(1-Bwse/100)*Ps_1/(I35+460))^2*1.083*(H35+460)*Md*dHa/Pbar_1,"-") -> - | P35: =IF(ISNUMBER(D36),((D36-D35)*Y*(I35+460)/(AVERAGE(G35:H35)+460)*(Pbar_1+K35/13.6)/Ps_1)/(1-Bwse/100)/(C35-C34),"-") -> - | Q35: =IF(ISNUMBER(P35),0.15625*((I35+460)/Mwe/Ps_1)^0.2091*(Y35/P35)^0.7091,"-") -> - | R35: =IF(ISNUMBER(P35),IF(Z35<3162,0.0024302*(Y35/P35)^1.1791*SQRT(1/AA35)*((I35+460)/Ps_1/Mwe)^0.679,0.019723*(Y35/P35)^0.8058*SQRT(1/AA35)*((I35+460)/Ps_1/Mwe)^0.3058),"-") -> - | U35: =IF(ISNUMBER(F35),SQRT(F35),"-") -> - | V35: =IF(ISNUMBER(U35),85.49*Cp*U35*SQRT((I35+460)/Ps_1/Mwe),"-") -> - | W35: =IF(ISNUMBER(D36),Tstd/Pstd*Y*(D36-D35)*(Pbar_1+K35/13.6)/(AVERAGE(G35:H35)+460),"-") -> - | X35: =IF(ISNUMBER(W35),W35/(C35-C34),"-") -> - | Y35: =IF(ISNUMBER(I35),-150.3162+13.4622*SQRT(I35+460)+3861530/(I35+460)^2+0.591123*(1-Bwse/100)*OO-91.9723*Bwse/100+0.0000151761*Bwse/100*(I35+460)^2,"-") -> - | Z35: =IF(ISNUMBER(Y35),864000*Ps_1*Mwe/(I35+460)*P35/Y35,"-") -> - | AA35: =IF(ISNUMBER(Y35),1+0.0057193*(Y35/Ps_1/(IF(ISNUMBER(R35),R35,2.5))*SQRT((I35+460)/Mwe)),"-") -> - | AC35: =IF(ISNUMBER(AF35),0.00013686*Ps_1*Mwe*(AF35)^2/(I35+460)/Cp^2,"-") -> - | AD35: =IF(ISNUMBER(AG35),0.00013686*Ps_1*Mwe*(AG35)^2/(I35+460)/Cp^2,"-") -> - | AE35: =IF(ISNUMBER(P35),3.055775*P35/(Dn)^2,"-") -> - | AF35: =IF(ISNUMBER(AH35),AE35*AH35,"-") -> - | AG35: =IF(ISNUMBER(AI35),AE35*AI35,"-") -> - | AH35: =IF(ISNUMBER(AE35),IF((0.2603*Y35*SQRT(P35))/(AE35)^1.5>0.3072,0.5,(0.2457+SQRT(0.3072-(0.2603*Y35*SQRT(P35))/(AE35)^1.5))),"-") -> - | AI35: =IF(ISNUMBER(AE35),IF((0.4457+SQRT(0.569+(0.2603*Y35*SQRT(P35))/(AE35)^1.5))>1.5,1.5,(0.4457+SQRT(0.569+(0.2603*Y35*SQRT(P35))/(AE35)^1.5))),"-") -> -
B36: 17 | C36: =IF(17>N_1,"-",IF(ISNUMBER(F36),MAX(ROUND(Cp/Cpp*U36/'Pre-Test'!$U$46*Tr_1*4/N_1,0)/4,2)+C35,"-")) -> - | J36: =IF(ISNUMBER(I36),(Qse*(1-Bwse/100)*Ps_1/(I36+460))^2*1.083*(H36+460)*Md*dHa/Pbar_1,"-") -> - | P36: =IF(ISNUMBER(D37),((D37-D36)*Y*(I36+460)/(AVERAGE(G36:H36)+460)*(Pbar_1+K36/13.6)/Ps_1)/(1-Bwse/100)/(C36-C35),"-") -> - | Q36: =IF(ISNUMBER(P36),0.15625*((I36+460)/Mwe/Ps_1)^0.2091*(Y36/P36)^0.7091,"-") -> - | R36: =IF(ISNUMBER(P36),IF(Z36<3162,0.0024302*(Y36/P36)^1.1791*SQRT(1/AA36)*((I36+460)/Ps_1/Mwe)^0.679,0.019723*(Y36/P36)^0.8058*SQRT(1/AA36)*((I36+460)/Ps_1/Mwe)^0.3058),"-") -> - | U36: =IF(ISNUMBER(F36),SQRT(F36),"-") -> - | V36: =IF(ISNUMBER(U36),85.49*Cp*U36*SQRT((I36+460)/Ps_1/Mwe),"-") -> - | W36: =IF(ISNUMBER(D37),Tstd/Pstd*Y*(D37-D36)*(Pbar_1+K36/13.6)/(AVERAGE(G36:H36)+460),"-") -> - | X36: =IF(ISNUMBER(W36),W36/(C36-C35),"-") -> - | Y36: =IF(ISNUMBER(I36),-150.3162+13.4622*SQRT(I36+460)+3861530/(I36+460)^2+0.591123*(1-Bwse/100)*OO-91.9723*Bwse/100+0.0000151761*Bwse/100*(I36+460)^2,"-") -> - | Z36: =IF(ISNUMBER(Y36),864000*Ps_1*Mwe/(I36+460)*P36/Y36,"-") -> - | AA36: =IF(ISNUMBER(Y36),1+0.0057193*(Y36/Ps_1/(IF(ISNUMBER(R36),R36,2.5))*SQRT((I36+460)/Mwe)),"-") -> - | AC36: =IF(ISNUMBER(AF36),0.00013686*Ps_1*Mwe*(AF36)^2/(I36+460)/Cp^2,"-") -> - | AD36: =IF(ISNUMBER(AG36),0.00013686*Ps_1*Mwe*(AG36)^2/(I36+460)/Cp^2,"-") -> - | AE36: =IF(ISNUMBER(P36),3.055775*P36/(Dn)^2,"-") -> - | AF36: =IF(ISNUMBER(AH36),AE36*AH36,"-") -> - | AG36: =IF(ISNUMBER(AI36),AE36*AI36,"-") -> - | AH36: =IF(ISNUMBER(AE36),IF((0.2603*Y36*SQRT(P36))/(AE36)^1.5>0.3072,0.5,(0.2457+SQRT(0.3072-(0.2603*Y36*SQRT(P36))/(AE36)^1.5))),"-") -> - | AI36: =IF(ISNUMBER(AE36),IF((0.4457+SQRT(0.569+(0.2603*Y36*SQRT(P36))/(AE36)^1.5))>1.5,1.5,(0.4457+SQRT(0.569+(0.2603*Y36*SQRT(P36))/(AE36)^1.5))),"-") -> -
B37: 18 | C37: =IF(18>N_1,"-",IF(ISNUMBER(F37),MAX(ROUND(Cp/Cpp*U37/'Pre-Test'!$U$46*Tr_1*4/N_1,0)/4,2)+C36,"-")) -> - | J37: =IF(ISNUMBER(I37),(Qse*(1-Bwse/100)*Ps_1/(I37+460))^2*1.083*(H37+460)*Md*dHa/Pbar_1,"-") -> - | P37: =IF(ISNUMBER(D38),((D38-D37)*Y*(I37+460)/(AVERAGE(G37:H37)+460)*(Pbar_1+K37/13.6)/Ps_1)/(1-Bwse/100)/(C37-C36),"-") -> - | Q37: =IF(ISNUMBER(P37),0.15625*((I37+460)/Mwe/Ps_1)^0.2091*(Y37/P37)^0.7091,"-") -> - | R37: =IF(ISNUMBER(P37),IF(Z37<3162,0.0024302*(Y37/P37)^1.1791*SQRT(1/AA37)*((I37+460)/Ps_1/Mwe)^0.679,0.019723*(Y37/P37)^0.8058*SQRT(1/AA37)*((I37+460)/Ps_1/Mwe)^0.3058),"-") -> - | U37: =IF(ISNUMBER(F37),SQRT(F37),"-") -> - | V37: =IF(ISNUMBER(U37),85.49*Cp*U37*SQRT((I37+460)/Ps_1/Mwe),"-") -> - | W37: =IF(ISNUMBER(D38),Tstd/Pstd*Y*(D38-D37)*(Pbar_1+K37/13.6)/(AVERAGE(G37:H37)+460),"-") -> - | X37: =IF(ISNUMBER(W37),W37/(C37-C36),"-") -> - | Y37: =IF(ISNUMBER(I37),-150.3162+13.4622*SQRT(I37+460)+3861530/(I37+460)^2+0.591123*(1-Bwse/100)*OO-91.9723*Bwse/100+0.0000151761*Bwse/100*(I37+460)^2,"-") -> - | Z37: =IF(ISNUMBER(Y37),864000*Ps_1*Mwe/(I37+460)*P37/Y37,"-") -> - | AA37: =IF(ISNUMBER(Y37),1+0.0057193*(Y37/Ps_1/(IF(ISNUMBER(R37),R37,2.5))*SQRT((I37+460)/Mwe)),"-") -> - | AC37: =IF(ISNUMBER(AF37),0.00013686*Ps_1*Mwe*(AF37)^2/(I37+460)/Cp^2,"-") -> - | AD37: =IF(ISNUMBER(AG37),0.00013686*Ps_1*Mwe*(AG37)^2/(I37+460)/Cp^2,"-") -> - | AE37: =IF(ISNUMBER(P37),3.055775*P37/(Dn)^2,"-") -> - | AF37: =IF(ISNUMBER(AH37),AE37*AH37,"-") -> - | AG37: =IF(ISNUMBER(AI37),AE37*AI37,"-") -> - | AH37: =IF(ISNUMBER(AE37),IF((0.2603*Y37*SQRT(P37))/(AE37)^1.5>0.3072,0.5,(0.2457+SQRT(0.3072-(0.2603*Y37*SQRT(P37))/(AE37)^1.5))),"-") -> - | AI37: =IF(ISNUMBER(AE37),IF((0.4457+SQRT(0.569+(0.2603*Y37*SQRT(P37))/(AE37)^1.5))>1.5,1.5,(0.4457+SQRT(0.569+(0.2603*Y37*SQRT(P37))/(AE37)^1.5))),"-") -> -
B38: 19 | C38: =IF(19>N_1,"-",IF(ISNUMBER(F38),MAX(ROUND(Cp/Cpp*U38/'Pre-Test'!$U$46*Tr_1*4/N_1,0)/4,2)+C37,"-")) -> - | J38: =IF(ISNUMBER(I38),(Qse*(1-Bwse/100)*Ps_1/(I38+460))^2*1.083*(H38+460)*Md*dHa/Pbar_1,"-") -> - | P38: =IF(ISNUMBER(D39),((D39-D38)*Y*(I38+460)/(AVERAGE(G38:H38)+460)*(Pbar_1+K38/13.6)/Ps_1)/(1-Bwse/100)/(C38-C37),"-") -> - | Q38: =IF(ISNUMBER(P38),0.15625*((I38+460)/Mwe/Ps_1)^0.2091*(Y38/P38)^0.7091,"-") -> - | R38: =IF(ISNUMBER(P38),IF(Z38<3162,0.0024302*(Y38/P38)^1.1791*SQRT(1/AA38)*((I38+460)/Ps_1/Mwe)^0.679,0.019723*(Y38/P38)^0.8058*SQRT(1/AA38)*((I38+460)/Ps_1/Mwe)^0.3058),"-") -> - | U38: =IF(ISNUMBER(F38),SQRT(F38),"-") -> - | V38: =IF(ISNUMBER(U38),85.49*Cp*U38*SQRT((I38+460)/Ps_1/Mwe),"-") -> - | W38: =IF(ISNUMBER(D39),Tstd/Pstd*Y*(D39-D38)*(Pbar_1+K38/13.6)/(AVERAGE(G38:H38)+460),"-") -> - | X38: =IF(ISNUMBER(W38),W38/(C38-C37),"-") -> - | Y38: =IF(ISNUMBER(I38),-150.3162+13.4622*SQRT(I38+460)+3861530/(I38+460)^2+0.591123*(1-Bwse/100)*OO-91.9723*Bwse/100+0.0000151761*Bwse/100*(I38+460)^2,"-") -> - | Z38: =IF(ISNUMBER(Y38),864000*Ps_1*Mwe/(I38+460)*P38/Y38,"-") -> - | AA38: =IF(ISNUMBER(Y38),1+0.0057193*(Y38/Ps_1/(IF(ISNUMBER(R38),R38,2.5))*SQRT((I38+460)/Mwe)),"-") -> - | AC38: =IF(ISNUMBER(AF38),0.00013686*Ps_1*Mwe*(AF38)^2/(I38+460)/Cp^2,"-") -> - | AD38: =IF(ISNUMBER(AG38),0.00013686*Ps_1*Mwe*(AG38)^2/(I38+460)/Cp^2,"-") -> - | AE38: =IF(ISNUMBER(P38),3.055775*P38/(Dn)^2,"-") -> - | AF38: =IF(ISNUMBER(AH38),AE38*AH38,"-") -> - | AG38: =IF(ISNUMBER(AI38),AE38*AI38,"-") -> - | AH38: =IF(ISNUMBER(AE38),IF((0.2603*Y38*SQRT(P38))/(AE38)^1.5>0.3072,0.5,(0.2457+SQRT(0.3072-(0.2603*Y38*SQRT(P38))/(AE38)^1.5))),"-") -> - | AI38: =IF(ISNUMBER(AE38),IF((0.4457+SQRT(0.569+(0.2603*Y38*SQRT(P38))/(AE38)^1.5))>1.5,1.5,(0.4457+SQRT(0.569+(0.2603*Y38*SQRT(P38))/(AE38)^1.5))),"-") -> -
B39: 20 | C39: =IF(20>N_1,"-",IF(ISNUMBER(F39),MAX(ROUND(Cp/Cpp*U39/'Pre-Test'!$U$46*Tr_1*4/N_1,0)/4,2)+C38,"-")) -> - | J39: =IF(ISNUMBER(I39),(Qse*(1-Bwse/100)*Ps_1/(I39+460))^2*1.083*(H39+460)*Md*dHa/Pbar_1,"-") -> - | P39: =IF(ISNUMBER(D40),((D40-D39)*Y*(I39+460)/(AVERAGE(G39:H39)+460)*(Pbar_1+K39/13.6)/Ps_1)/(1-Bwse/100)/(C39-C38),"-") -> - | Q39: =IF(ISNUMBER(P39),0.15625*((I39+460)/Mwe/Ps_1)^0.2091*(Y39/P39)^0.7091,"-") -> - | R39: =IF(ISNUMBER(P39),IF(Z39<3162,0.0024302*(Y39/P39)^1.1791*SQRT(1/AA39)*((I39+460)/Ps_1/Mwe)^0.679,0.019723*(Y39/P39)^0.8058*SQRT(1/AA39)*((I39+460)/Ps_1/Mwe)^0.3058),"-") -> - | U39: =IF(ISNUMBER(F39),SQRT(F39),"-") -> - | V39: =IF(ISNUMBER(U39),85.49*Cp*U39*SQRT((I39+460)/Ps_1/Mwe),"-") -> - | W39: =IF(ISNUMBER(D40),Tstd/Pstd*Y*(D40-D39)*(Pbar_1+K39/13.6)/(AVERAGE(G39:H39)+460),"-") -> - | X39: =IF(ISNUMBER(W39),W39/(C39-C38),"-") -> - | Y39: =IF(ISNUMBER(I39),-150.3162+13.4622*SQRT(I39+460)+3861530/(I39+460)^2+0.591123*(1-Bwse/100)*OO-91.9723*Bwse/100+0.0000151761*Bwse/100*(I39+460)^2,"-") -> - | Z39: =IF(ISNUMBER(Y39),864000*Ps_1*Mwe/(I39+460)*P39/Y39,"-") -> - | AA39: =IF(ISNUMBER(Y39),1+0.0057193*(Y39/Ps_1/(IF(ISNUMBER(R39),R39,2.5))*SQRT((I39+460)/Mwe)),"-") -> - | AC39: =IF(ISNUMBER(AF39),0.00013686*Ps_1*Mwe*(AF39)^2/(I39+460)/Cp^2,"-") -> - | AD39: =IF(ISNUMBER(AG39),0.00013686*Ps_1*Mwe*(AG39)^2/(I39+460)/Cp^2,"-") -> - | AE39: =IF(ISNUMBER(P39),3.055775*P39/(Dn)^2,"-") -> - | AF39: =IF(ISNUMBER(AH39),AE39*AH39,"-") -> - | AG39: =IF(ISNUMBER(AI39),AE39*AI39,"-") -> - | AH39: =IF(ISNUMBER(AE39),IF((0.2603*Y39*SQRT(P39))/(AE39)^1.5>0.3072,0.5,(0.2457+SQRT(0.3072-(0.2603*Y39*SQRT(P39))/(AE39)^1.5))),"-") -> - | AI39: =IF(ISNUMBER(AE39),IF((0.4457+SQRT(0.569+(0.2603*Y39*SQRT(P39))/(AE39)^1.5))>1.5,1.5,(0.4457+SQRT(0.569+(0.2603*Y39*SQRT(P39))/(AE39)^1.5))),"-") -> -
