Workbook
Name _1W_一: #REF!,#REF!,#REF!,#REF!
Name _1W_一: #REF!,#REF!,#REF!,#REF!
Name \z: #REF!
Name \z: #REF!
Name A: #REF!
Name A: #REF!
Name Cl2入力: [1]Cl2!$C$8:$C$9,[1]Cl2!$F$9:$F$14,[1]Cl2!$H$9:$H$14,[1]Cl2!$C$7
Name d: #REF!
Name d: #REF!
Name FLOW: #REF!
Name FLOW: #REF!
Name HCl入力: [1]HCl!$C$8:$C$9,[1]HCl!$F$9:$F$14,[1]HCl!$H$9:$H$14,[1]HCl!$C$7
Name Limit: #REF!
Name Limit: #REF!
Name ly: #REF!
Name NH3入力: [2]NH3!$C$8:$C$9,[2]NH3!$F$9:$F$14,[2]NH3!$H$9:$H$14,[2]NH3!$C$7
Name Pa: #REF!
Name Pa: #REF!
Name PDS入力: [1]PDS!$C$8:$C$9,[1]PDS!$F$9:$F$14,[1]PDS!$H$9:$H$14,[1]PDS!$C$7
Name Po: #REF!
Name Po: #REF!
Name Print_Area: '1.Hợp đồng'!$A$1:$J$165
Name Print_Area: '2.Báo giá'!$A$1:$J$41
Name Print_Area: '3.Nhiệm thu'!$A$1:$J$53
Name Print_Area: '4.yêu cầu thanh toán'!$A$1:$J$55
Name Print_Area_MI: #REF!
Name Print_Area_MI: #REF!
Name Ps: #REF!
Name Ps: #REF!
Name Ｐv: #REF!
Name Ｐv: #REF!
Name Request: #REF!
Name Request: #REF!
Name S0x50入力: '[1]SOx 50'!$C$8:$C$9,'[1]SOx 50'!$C$12,'[1]SOx 50'!$F$9:$F$14,'[1]SOx 50'!$H$9:$H$14,'[1]SOx 50'!$C$7
Name SOx入力: '[1]SOx 10'!$C$8:$C$9,'[1]SOx 10'!$C$12,'[1]SOx 10'!$F$9:$F$14,'[1]SOx 10'!$H$9:$H$14,'[1]SOx 10'!$C$7
Name ｔ: #REF!
Name ｔ: #REF!
Name To: #REF!
Name To: #REF!
Name Xw: #REF!
Name Xw: #REF!
Name Zn入力: '[1]Zn NEDA'!$C$8:$C$9,'[1]Zn NEDA'!$F$9:$F$14,'[1]Zn NEDA'!$H$9:$H$14,'[1]Zn NEDA'!$C$7
Name γ: #REF!
Name γ: #REF!
Name γ0: #REF!
Name γ0: #REF!
Name θm: #REF!
Name θm: #REF!
Name θs: #REF!
Name θs: #REF!
Name あ: #REF!,#REF!,#REF!,#REF!
Name あ: #REF!,#REF!,#REF!,#REF!
Name あいう: [3]受注予算書（入力用）!$AE$79
Name 一般入寮: [4]証明!$M$2:$M$9,[4]証明!$N$11:$N$13,[4]証明!$I$25:$I$31,[4]証明!$M$1
Name 一般入力: #REF!,#REF!,#REF!,#REF!
Name 一般入力: #REF!,#REF!,#REF!,#REF!
Name 技師: #REF!
Name 技師: #REF!
Name 技師Ａ: #REF!
Name 技師Ａ: #REF!

Sheet 1.Hợp đồng
A1: CÔNG TY TNHH CHUGAI TECHNOS VIỆT NAM | G1: CỘNG HÒA XÃ HỘI CHỦ NGHĨA VIỆT NAM
G2: ĐỘC LẬP - TỰ DO - HẠNH PHÚC
A5: HỢP ĐỒNG DỊCH VỤ
D8: SỐ: | E8: CCTVN-DCEM-201612-02
A10: -Căn cứ bộ Luật dân sự số 33/2005/QH11 được Quốc hội nước Cộng Hòa Xã Hội Chủ Nghĩa Việt Nam thông qua ngày 14/06/2005. -Căn cứ Luật thương mại số 36/2005 /QH11 ban hành ngày 14/06/2005 của Quốc Hội nước Cộng Hoà Xã Hội Chủ Nghĩa Việt Nam.
A15: Căn cứ vào nhu cầu và khả năng của hai bên.
A17: ="Hợp đồng này được ký ngày 6/12/2016 bởi các bên như sau：" -> Hợp đồng này được ký ngày 6/12/2016 bởi các bên như sau：
A19: Bên A | C19: ： | D19: TRUNG TÂM QUAN TRẮC VÀ KỸ THUẬT MÔI TRƯỜNG
A20: Đại diện bởi | C20: ： | D20: Bà Lê Thị Thanh Thủy
A21: Chức vụ | C21: ： | D21: Giám Đốc
A22: Địa chỉ | C22: ： | D22: Số 520, đường Đồng Khởi, phường Tân Hiệp, Tp. Biên Hòa, tỉnh Đồng Nai.
A23: Điện thoại | C23: ： | D23: 061.3895672-3
A24: Fax | C24: ： | D24: 061.3895669
A25: Mã số thuế | C25: ： | D25: 3600508577
A27: Sau đây được gọi tắt là bên A.
A29: Bên B | C29: ： | D29: CÔNG TY TNHH CHUGAI TECHNOS VIỆT NAM
A30: Đại diện bởi | C30: ： | D30: Ông Masami Oue
A31: Chức vụ | C31: ： | D31: Tổng giám đốc
A32: Địa chỉ | C32: ： | D32: 66 Cao Triều Phát, Khu phố Hưng Gia 4, Phường Tân Phong, Quận 7, TP.HCM
A33: Điện thoại | C33: ： | D33: +84-8-5410-9111
A34: Fax | C34: ： | D34: +84-8-5410-9222
A35: Mã số thuế | C35: ： | D35: 0312737198
A36: Chủ tài khoản | C36: : | D36: CHUGAI TECHNOS VIETNAM COMPANY LIMITED
A37: Số tài khoản | D37: 10065702 | E37: VND
A38: Ngân hàng | D38: Ngân hàng Sumitomo Mitsui chi nhánh Hồ Chí Minh
A40: Sau đây được gọi tắt là bên B.
A43: Hai bên đồng ý ký kết hợp đồng cung cấp dịch vụ với các điều khoản như sau:
A45: Điều I ： THÔNG TIN DỊCH VỤ
A47: 1．1 | B47: Bên B đồng ý cung cấp cho bên A các dịch vụ có nội dung như sau:
B48: Tên dịch vụ | D48: ： | E48: Đo đạc khí thải
B49: Tên nhà máy cần đo | D49: ： | E49: Nhà máy Hóa chất Đồng Nai - Công ty Cổ phần Hóa chất Cơ bản
B50: Địa chỉ | D50: ： | E50: KCN Biên Hòa 1, phường An Bình, Tp. Biên Hòa, tỉnh Đồng Nai
B51: Tại nước | D51: ： | E51: Việt Nam
B52: Ngày đo | D52: ： | E52: 42718
B54: Sản phẩm hợp đồng là 03 (ba) bộ kết quả (hoặc báo cáo phân tích) / 01 mẫu phân tích chất lượng mẫu khí thải.
A56: 1．2 | B56: Tất cả các dịch vụ bên B cung cấp cho bên A được nêu đầy đủ trong báo giá đính kèm dưới đây. Báo giá này cũng là một phần của hợp đồng này.
B58: Báo giá số: | D58: QCTVN201612-02
A60: Điều II: GIÁ TRỊ HỢP ĐỒNG
A62: 2．1 | B62: Toàn bộ giá trị hợp đồng này là 13,970,000 VNĐ
B63: (Bằng chữ: mười ba triệu chín trăm bảy mươi ngàn Việt Nam đồng chẵn)
...

Sheet 2.Báo giá
B2: BÁO GIÁ CHI TIẾT
I3: QCTVN201612-02
I4: 6-12-2016
B5: Tới: TRUNG TÂM QUAN TRẮC VÀ KỸ THUẬT MÔI TRƯỜNG
G6: CHUGAI TECHNOS VIETNAM CO.,LTD
B7: Dịch vụ: | C7: ='1.Hợp đồng'!E48 -> Đo đạc khí thải | G7: =I13 -> Ông．MASAMI OUE
B9: Kính gửi quý công ty, chúng tôi xin thông báo báo giá của công ty chúng tôi： | H9: Số 66 Cao Triều Phát, Khu phố Hưng Gia 4, phường Tân Phong, quận 7, tp.Hồ Chí Minh
G11: TEL +84-8-5410-9111 FAX +84-8-5410-9222 | M11: B．Overtime Money
B12: Địa điểm： | C12: ='[5]3.Sales Contraction'!E51 -> Vietnam | S12: Currency：JPY
B13: Hiệu lực： | C13: 30 ngày | G13: Trách nhiệm báo giá： | I13: ='[5]3.Sales Contraction'!D31 -> Ông．MASAMI OUE | M13: Total salary | N13: Basic unit price(A) | O13: Weekday | Q13: Holiday(Sat and Sun） | S13: Public holiday
O14: Day | P14: Midnight | Q14: Day | R14: Midnight | S14: Day | T14: Midnight
B15: Mục | E15: Nội dung | G15: số lượng | H15: Đơn vị | I15: Đơn giá(VNĐ) | J15: Price | M15: 35000 | N15: =M15/22/8 -> 198.86364 | O15: =N15*1.5 -> 298.29545 | P15: =N15*1.5+N15*0.3+N15*0.2 -> 397.72727 | Q15: =N15*2 -> 397.72727 | R15: =N15*2+N15*0.3+N15*2*0.2 -> 536.93182 | S15: =N15*3 -> 596.59091 | T15: =N15*3+N15*0.3+N15*3*0.2 -> 775.56818
B16: 1． | C16: Chi phí lấy mẫu hiện trường | M16: 45000 | N16: =M16/22/8 -> 255.68182 | O16: =N16*1.5 -> 383.52273 | P16: =N16*1.5+N16*0.3+N16*0.2 -> 511.36364 | Q16: =N16*2 -> 511.36364 | R16: =N16*2+N16*0.3+N16*2*0.2 -> 690.34091 | S16: =N16*3 -> 767.04545 | T16: =N16*3+N16*0.3+N16*3*0.2 -> 997.15909
C17: (1) | D17: HCl | G17: 1 | H17: Mẫu | I17: 500000 | J17: =G17*I17 -> 500000 | M17: ※Ａ＝Basic Salary／22days／8 hours
C18: (2) | D18: NH3 | G18: 3 | H18: Mẫu | I18: 500000 | J18: =G18*I18 -> 1500000 | M18: Midnight Overtime is between p.m 21:00 and a.m 5:00
B19: 2． | C19: Chi phí phân tích
C20: (1) | D20: HCl | G20: 1 | H20: Mẫu | I20: 300000 | J20: =G20*I20 -> 300000
C21: (2) | D21: NH3 | G21: 3 | H21: Mẫu | I21: 300000 | J21: =G21*I21 -> 900000
B22: 3. | C22: Chi phí nhân công | G22: 2 | H22: Người | I22: 2000000 | J22: =G22*I22 -> 4000000
B23: 3.1 | C23: Chi phí chuẩn bị thiết bị | G23: 0.5 | H23: Người | I23: 2000000 | J23: =G23*I23 -> 1000000
B24: 3.2 | C24: Chi phí viết báo cáo | G24: 0.5 | H24: Người | I24: 2000000 | J24: =G24*I24 -> 1000000
B25: 4 | C25: Chi phí thiết bị, tiêu thụ phẩm | G25: 1 | H25: Bộ | I25: 1500000 | J25: =G25*I25 -> 1500000 | M25: ※Accommodation fee is actual cost includind breakfast.
C26: ống lấy mẫu,thiết bị đo lưu lượng, bơm | M26: ※Daily allowance is from depature day to arrival day.
C27: thiết bị đo nhiệt độ, áp suất, ống hấp thụ
C28: Giấy lấy bụi, dung dịch hấp thụ……..
B30: 5. | C30: Chi phí vận chuyển thiết bị | G30: 1 | I30: 2000000 | J30: =I30 -> 2000000 | M30: ※Immunization shoud be charged an actual cost price including man-hour spent
C39: Tổng giá trị thực hiện | J39: =SUM(J17:J30) -> 12700000
C40: VAT | G40: =O40 -> 10 | H40: ％ | J40: =J39*10% -> 1270000 | N40: VAT= | O40: 10 | P40: %
B41: Tổng giá | J41: =J39+J40 -> 13970000 | N41: VAT need in Vietnam

Sheet 3.Nhiệm thu
D2: CÔNG TY TNHH CHUGAI TECHNOS VIỆT NAM
E3: Số 66 Cao Triều Phát, Khu phố Hưng Gia 4, phường Tân Phong, quận 7, thành phố Hồ Chí Minh
E6: Số điện thoại：08-5410-9111 ； Fax：08-5410-9222
F8: Website：http://www.chugai-tec.co.jp/
A9: BIÊN BẢN NGHIỆM THU
A13: Ngày: | B13: 20/12/2016
A15: Gửi đến： | B15: ='1.Hợp đồng'!D19 -> TRUNG TÂM QUAN TRẮC VÀ KỸ THUẬT MÔI TRƯỜNG
A17: Địa chỉ： | B17: ='1.Hợp đồng'!D22 -> Số 520, đường Đồng Khởi, phường Tân Hiệp, Tp. Biên Hòa, tỉnh Đồng Nai.
A18: MST: | C18: ='1.Hợp đồng'!D25 -> 3600508577
A19: Điện thoại ： | C19: ='1.Hợp đồng'!D23 -> 061.3895672-3
A20: Fax： | C20: ='1.Hợp đồng'!D24 -> 061.3895669
A22: Kính gửi quý trung tâm,
A23: Chúng tôi đã hoàn thành dịch vụ của mình theo hợp đồng đã ký kết, dưới đây là những hạng mục báo cáo
A24: mà chúng tôi đã hoàn thành, xin hãy xác nhận bằng chữ ký vào biên bản này.
A25: Nếu quý công ty có bất kì phản hồi nào, xin hãy liên hệ với chúng tôi
A26: Chúng tôi luôn hoan nghênh mọi sự góp ý từ phía quý công ty.
A28: Nội dung:
A29: Nội dung dịch vụ | D29: ='1.Hợp đồng'!E48 -> Đo đạc khí thải
D30: Ngày đo | E30: 14/12/2016
D31: Báo caó phân tích: | F31: 3 bản
A34: Điều kiện:
A35: Ngày hoàn thành | D35: 42724
A36: Địa điểm | D36: ='1.Hợp đồng'!E49 -> Nhà máy Hóa chất Đồng Nai - Công ty Cổ phần Hóa chất Cơ bản
A37: Quốc gia | D37: Việt Nam
A38: Ghi chú | D38: Căn cứ | E38: Hợp đồng số | H38: ='1.Hợp đồng'!E8 -> CCTVN-DCEM-201612-02
E39: Báo giá/ đơn đặt hàng số | H39: ='1.Hợp đồng'!D58 -> QCTVN201612-02
A44: XÁC NHẬN CỦA KHÁCH HÀNG | F44: =D2 -> CÔNG TY TNHH CHUGAI TECHNOS VIỆT NAM
A46: Ngày: | F46: Ngày:
B53: Chữ ký và con dấu công ty | G53: Chữ ký và con dấu công ty

Sheet 4.yêu cầu thanh toán
D2: CÔNG TY TNHH CHUGAI TECHNOS VIỆT NAM
E3: Số 66 Cao Triều Phát, Khu phố Hưng Gia 4, phường Tân Phong, quận 7, thành phố Hồ Chí Minh
E6: Số điện thoại：08-5410-9111 ； Fax：08-5410-9222
F8: Website：http://www.chugai-tec.co.jp/
A9: YÊU CẦU THANH TOÁN
A13: Ngày: | B13: ='3.Nhiệm thu'!B13 -> 20/12/2016
A15: Gửi đến: | B15: ='3.Nhiệm thu'!B15 -> TRUNG TÂM QUAN TRẮC VÀ KỸ THUẬT MÔI TRƯỜNG
A17: Địa chỉ: | B17: ='3.Nhiệm thu'!B17 -> Số 520, đường Đồng Khởi, phường Tân Hiệp, Tp. Biên Hòa, tỉnh Đồng Nai.
A18: MST: | C18: ='3.Nhiệm thu'!C18 -> 3600508577
A19: Điện thoại: | C19: ='3.Nhiệm thu'!C19 -> 061.3895672-3
A20: Fax： | C20: ='3.Nhiệm thu'!C20 -> 061.3895669
A22: Kính gửi quý công ty
A23: Căn cứ vào hợp đồng kinh tế số: CCTVN-DCEM-201612-02 được lập ngày 6/12/2016 giữa CÔNG TY TNHH CHUGAI TECHNOS VIỆT NAM và TRUNG TÂM QUAN TRẮC VÀ KỸ THUẬT MÔI TRƯỜNG , xin hãy tiến hành thanh toán cho chúng tôi những khoản có giá trị như sau：
A27: Giá trị hợp đồng | C27: ： | D27: ='2.Báo giá'!J41 -> 13970000 | E27: VNĐ
A29: Giá trị cần thanh toán | C29: ： | D29: =D27 -> 13970000 | E29: VND
A31: Bằng chữ: | B31: =_xll.VND(D27) -> Mười ba triệu chín trăm bảy mươi nghìn đồng chẵn.
A33: Xin hãy thanh toán cho chúng tôi bằng hình thức chuyển khoản vào tài khoản của Công ty TNHH Chugai Technos Việt Nam:
A36: Tên tài khoản | C36: ： | D36: ='1.Hợp đồng'!D36 -> CHUGAI TECHNOS VIETNAM COMPANY LIMITED
A37: Số tài khoản | C37: ： | D37: ='1.Hợp đồng'!D37 -> 10065702
A38: Ngân hàng | C38: ： | D38: ='[6]3.Sales Contraction'!D38 -> Ngân hàng Mitsu Sumitomo- CN Hồ Chí Minh
A41: Rất cảm ơn sự hợp tác của quý công ty
A42: Trân trọng!
A46: =D36 -> CHUGAI TECHNOS VIETNAM COMPANY LIMITED
A55: ='[6]3.Sales Contraction'!D29 -> Ông MASAMI OUE
