Workbook

Sheet Phuong phap
A1: TỔNG HỢP CÁC PHƯƠNG PHÁP SỬ DỤNG CHO HOẠT ĐỘNG QUAN TRẮC TRẦM TÍCH
A2: Số TT | B2: Thông số quan trắc | C2: Phương pháp sử dụng
A3: A | B3: C
A4: A | B4: HOẠT ĐỘNG QUAN TRẮC VÀ PHÂN TÍCH MÔI TRƯỜNG TRẦM TÍCH
A5: 1 | B5: pH (H2O, KCl) | C5: TCVN 5979: 2007
A6: 2 | B6: Tổng các bon hữu cơ | C6: TCVN 6644:2000
A7: 3 | B7: Dầu mỡ | C7: US EPA 9071
A8: 4 | B8: Cyanua (CN-) | C8: US EPA 9010
A9: 5 | B9: Tổng N | C9: TCVN 6498: 1999
A10: 6 | B10: Tổng P | C10: TCVN 8940 : 2011
A11: 7 | B11: Phenol | C11: US EPA 3550C + SMEWW 5530C: 2012
A12: 8 | B12: KLN (Pb, Cd) | C12: TCVN 6649: 2000 + TCVN 6496: 2009
A13: 9 | B13: KLN (Hg, As) | C13: TCVN 8467: 2010 + TCVN 6649:2000
A14: 10 | B14: KLN (Ni, Cu, Zn, Cr, Mn) | C14: TCVN 6496:2009 +TCVN 6649:2000
A15: 11 | B15: Tổng K2O | C15: TCVN 8660: 2011
A16: 12 | B16: Thuốc BVTV nhóm Clo hữu cơ (Aldrin+Dieldrin, BHC, DDT, Heptachlor &Heptachlorepoxide) | C16: US EPA 3550C +US EPA 8270D
... A21: 17 | B21: Phân tích đồng thời kim loại | C21: TCVN 8246: 2009

Sheet DGl
A1: ĐƠN GIÁ TIỀN LƯƠNG LAO ĐỘNG KỸ THUẬT
A2: - Hệ số lương theo Nghị định số 204/2004/NĐ-CP ngày 14 tháng 12 năm 2004 của Chính phủ về chế độ tiền lương đối với cán bộ công chức, viên chức và lực lượng vũ trang và chế độ phụ cấp lương trong các công ty nhà nước; - Mức đóng các khoản bảo hiểm (BHXH, BHYT, BHTN) theo quy định tại Luật Bảo hiểm xã hội năm 2006; - Mức lương tối thiểu theo Nghị định số 99/2015/QH13 ngày 11 tháng 11 năm 2015 của Quốc hội khóa 13 quy định mức lương tối thiểu chung là 1.300.000 đồng /tháng; - Số ngày công trong 1 tháng là: 26 ngày
K3: 26 | L3: 1300000
A4: Số TT | B4: Mã hiệu | C4: Chức danh | D4: Hệ số lương | E4: Lương cấp bậc | F4: Lương phụ 11% | G4: Phụ cấp Lưu động (0,4) | H4: Phụ cấp Độc hại (0,1) | I4: Phụ cấp tổ trưởng 0,2/5 | J4: Tổng lương | K4: BHXH, YT, TN, KPCĐ | L4: Tổng cộng lương tháng | M4: Đơn giá tiền lương
A6: (1) | C6: (2) | D6: (3) | E6: (4) | F6: (5) = 11%*(4) | G6: (6) | H6: (7) | I6: (8) | J6: (9)=4+5+6+7+8 | K6: (10) = 23.5%*(9) | L6: (11)=9+10 | M6: (12)=(11)/26
A7: I | C7: NGOẠI NGHIỆP | F7: 0.11 | G7: 0.4 | H7: 0.1 | K7: 0.235
A8: 1 | B8: 1QTVTNMT hạng IV.2 | C8: Quan trắc viên tài nguyên môi trường hạng IV bậc 2 | D8: 2.41 | E8: =$L$3*D8 -> 3133000 | F8: =E8*$F$7 -> 344630 | G8: =$L$3*$G$7 -> 520000 | H8: =$L$3*$H$7 -> 130000 | I8: =$L$3*0.2/5 -> 52000 | J8: =SUM(E8:I8) -> 4179630 | K8: =E8*$K$7 -> 736255 | L8: =K8+J8 -> 4915885 | M8: =L8/$K$3 -> 189072.5
A9: 2 | B9: 1QTVTNMT hạng IV.3 | C9: Quan trắc viên tài nguyên môi trường hạng IV bậc 3 | D9: 2.72 | E9: =$L$3*D9 -> 3536000 | F9: =E9*$F$7 -> 388960 | G9: =$L$3*$G$7 -> 520000 | H9: =$L$3*$H$7 -> 130000 | I9: =$L$3*0.2/5 -> 52000 | J9: =SUM(E9:I9) -> 4626960 | K9: =E9*$K$7 -> 830960 | L9: =K9+J9 -> 5457920 | M9: =L9/$K$3 -> 209920
A10: 3 | B10: 1QTVTNMT hạng III.1 | C10: Quan trắc viên tài nguyên môi trường hạng III bậc 1 | D10: 2.34 | E10: =$L$3*D10 -> 3042000 | F10: =E10*$F$7 -> 334620 | G10: =$L$3*$G$7 -> 520000 | H10: =$L$3*$H$7 -> 130000 | I10: =$L$3*0.2/5 -> 52000 | J10: =SUM(E10:I10) -> 4078620 | K10: =E10*$K$7 -> 714870 | L10: =K10+J10 -> 4793490 | M10: =L10/$K$3 -> 184365
A11: 4 | B11: 1QTVTNMT hạng III.2 | C11: Quan trắc viên tài nguyên môi trường hạng III bậc 2 | D11: 2.67 | E11: =$L$3*D11 -> 3471000 | F11: =E11*$F$7 -> 381810 | G11: =$L$3*$G$7 -> 520000 | H11: =$L$3*$H$7 -> 130000 | I11: =$L$3*0.2/5 -> 52000 | J11: =SUM(E11:I11) -> 4554810 | K11: =E11*$K$7 -> 815685 | L11: =K11+J11 -> 5370495 | M11: =L11/$K$3 -> 206557.5
A12: II | C12: NỘI NGHIỆP
A13: 1 | B13: 1QTVTNMT hạng IV.2 | C13: Quan trắc viên tài nguyên môi trường hạng IV bậc 2 | D13: 2.41 | E13: =$L$3*D13 -> 3133000 | F13: =E13*$F$7 -> 344630 | G13: =0*$L$3 -> 0 | H13: =$L$3*$H$7 -> 130000 | I13: =($L$3*0.2)/5 -> 52000 | J13: =SUM(E13:I13) -> 3659630 | K13: =E13*$K$7 -> 736255 | L13: =K13+J13 -> 4395885 | M13: =L13/$K$3 -> 169072.5
A14: 2 | B14: 1QTVTNMT hạng III.1 | C14: Quan trắc viên tài nguyên môi trường hạng III bậc 1 | D14: 2.34 | E14: =$L$3*D14 -> 3042000 | F14: =E14*$F$7 -> 334620 | G14: 0 | H14: =$L$3*$H$7 -> 130000 | I14: =($L$3*0.2)/5 -> 52000 | J14: =SUM(E14:I14) -> 3558620 | K14: =E14*$K$7 -> 714870 | L14: =K14+J14 -> 4273490 | M14: =L14/$K$3 -> 164365
A15: 3 | B15: 1QTVTNMT hạng III.2 | C15: Quan trắc viên tài nguyên môi trường hạng III bậc 2 | D15: 2.67 | E15: =$L$3*D15 -> 3471000 | F15: =E15*$F$7 -> 381810 | G15: =0*$L$3 -> 0 | H15: =$L$3*$H$7 -> 130000 | I15: =($L$3*0.2)/5 -> 52000 | J15: =SUM(E15:I15) -> 4034810 | K15: =E15*$K$7 -> 815685 | L15: =K15+J15 -> 4850495 | M15: =L15/$K$3 -> 186557.5
A16: 4 | B16: 1QTVTNMT hạng III.3 | C16: Quan trắc viên tài nguyên môi trường hạng III bậc 3 | D16: 3 | E16: =$L$3*D16 -> 3900000 | F16: =E16*$F$7 -> 429000 | G16: =0*$L$3 -> 0 | H16: =$L$3*$H$7 -> 130000 | I16: =($L$3*0.2)/5 -> 52000 | J16: =SUM(E16:I16) -> 4511000 | K16: =E16*$K$7 -> 916500 | L16: =K16+J16 -> 5427500 | M16: =L16/$K$3 -> 208750

Sheet LDKT
A1: CHI PHÍ NHÂN CÔNG (Hoạt động quan trắc môi trường trầm tích)
F2: Đơn vị tính: đồng
A3: STT | B3: Mã hiệu | C3: Chỉ tiêu quan trắc | D3: Định biên | E3: Định mức | F3: Đơn giá lương ngày | G3: Thành tiền
A5: A | B5: HOẠT ĐỘNG QUAN TRẮC VÀ PHÂN TÍCH MÔI TRƯỜNG TRẦM TÍCH
A6: A1 | B6: Công tác quan trắc môi trường trầm tích tại hiện trường (TT) | F6: 1.2
A7: 1 | B7: 1TT1 | C7: pH (H2O, KCl) | D7: 1QTVTNMT hạng III.1 | E7: 0.4 | F7: =VLOOKUP(D7,DGl!$B$8:$M$199,12,0) -> 184365 | G7: =E7*F7*$F$6 -> 88495.2
A8: 2 | B8: 1TT2 | C8: Tổng các bon hữu cơ | D8: 1QTVTNMT hạng III.1 | E8: 0.4 | F8: =VLOOKUP(D8,DGl!$B$8:$M$199,12,0) -> 184365 | G8: =E8*F8*$F$6 -> 88495.2
A9: 3 | B9: 1TT3 | C9: Dầu mỡ | D9: 1QTVTNMT hạng III.2 | E9: 0.35 | F9: =VLOOKUP(D9,DGl!$B$8:$M$199,12,0) -> 206557.5 | G9: =E9*F9*$F$6 -> 86754.15
A10: 4 | B10: 1TT4 | C10: Cyanua (CN-) | D10: 1QTVTNMT hạng III.2 | E10: 0.35 | F10: =VLOOKUP(D10,DGl!$B$8:$M$199,12,0) -> 206557.5 | G10: =E10*F10*$F$6 -> 86754.15
A11: 5 | B11: 1TT5a | C11: Tổng N | D11: 1QTVTNMT hạng III.2 | E11: 0.35 | F11: =VLOOKUP(D11,DGl!$B$8:$M$199,12,0) -> 206557.5 | G11: =E11*F11*$F$6 -> 86754.15
A12: 6 | B12: 1TT5b | C12: Tổng P | D12: 1QTVTNMT hạng III.2 | E12: 0.35 | F12: =VLOOKUP(D12,DGl!$B$8:$M$199,12,0) -> 206557.5 | G12: =E12*F12*$F$6 -> 86754.15
A13: 7 | B13: 1TT5c | C13: Phenol | D13: 1QTVTNMT hạng III.2 | E13: 0.35 | F13: =VLOOKUP(D13,DGl!$B$8:$M$199,12,0) -> 206557.5 | G13: =E13*F13*$F$6 -> 86754.15
A14: 8 | B14: 1TT5d1 | C14: KLN (Pb) | D14: 1QTVTNMT hạng III.2 | E14: 0.35 | F14: =VLOOKUP(D14,DGl!$B$8:$M$199,12,0) -> 206557.5 | G14: =E14*F14*$F$6 -> 86754.15
A15: 9 | B15: 1TT5d2 | C15: KLN (Cd) | D15: 1QTVTNMT hạng III.2 | E15: 0.35 | F15: =VLOOKUP(D15,DGl!$B$8:$M$199,12,0) -> 206557.5 | G15: =E15*F15*$F$6 -> 86754.15
A16: 10 | B16: 1TT5đ1 | C16: KLN ( As) | D16: 1QTVTNMT hạng III.2 | E16: 0.35 | F16: =VLOOKUP(D16,DGl!$B$8:$M$199,12,0) -> 206557.5 | G16: =E16*F16*$F$6 -> 86754.15
A17: 11 | B17: 1TT5đ2 | C17: KLN (Hg) | D17: 1QTVTNMT hạng III.2 | E17: 0.35 | F17: =VLOOKUP(D17,DGl!$B$8:$M$199,12,0) -> 206557.5 | G17: =E17*F17*$F$6 -> 86754.15
A18: 12 | B18: 1TT5e1 | C18: KLN (Zn) | D18: 1QTVTNMT hạng III.2 | E18: 0.35 | F18: =VLOOKUP(D18,DGl!$B$8:$M$199,12,0) -> 206557.5 | G18: =E18*F18*$F$6 -> 86754.15
... A29: 23 | B29: 1TT7 | C29: Phân tích đồng thời KL | D29: 1QTVTNMT hạng III.2 | E29: 0.35 | F29: =VLOOKUP(D29,DGl!$B$8:$M$199,12,0) -> 206557.5 | G29: =E29*F29*$F$6 -> 86754.15
A30: A2 | B30: Công tác phân tích môi trường trầm tích trong phòng thí nghiệm (2TT) | E30: 1
A31: 1 | B31: 2TT1 | C31: pH (H2O, KCl) | D31: 1QTVTNMT hạng III.1 | E31: 0.6 | F31: =VLOOKUP(D31,DGl!$B$8:$M$199,12,0) -> 184365 | G31: =F31*E31 -> 110619
A32: 2 | B32: 2TT2 | C32: Tổng các bon hữu cơ | D32: 1QTVTNMT hạng III.3 | E32: 0.6 | F32: =VLOOKUP(D32,DGl!$B$8:$M$199,12,0) -> 208750 | G32: =E32*F32 -> 125250
A33: 3 | B33: 2TT3 | C33: Dầu mỡ | D33: 1QTVTNMT hạng III.2 | E33: 1 | F33: =VLOOKUP(D33,DGl!$B$8:$M$199,12,0) -> 206557.5 | G33: =E33*F33 -> 206557.5
A34: 4 | B34: 2TT4 | C34: Cyanua (CN-) | D34: 1QTVTNMT hạng III.2 | E34: 1 | F34: =VLOOKUP(D34,DGl!$B$8:$M$199,12,0) -> 206557.5 | G34: =E34*F34 -> 206557.5
A35: 5 | B35: 2TT5a | C35: Tổng N | D35: 1QTVTNMT hạng III.2 | E35: 0.75 | F35: =VLOOKUP(D35,DGl!$B$8:$M$199,12,0) -> 206557.5 | G35: =E35*F35 -> 154918.12
A36: 6 | B36: 2TT5b | C36: Tổng P | D36: 1QTVTNMT hạng III.2 | E36: 0.75 | F36: =VLOOKUP(D36,DGl!$B$8:$M$199,12,0) -> 206557.5 | G36: =E36*F36 -> 154918.12
A37: 7 | B37: 2TT5c | C37: Phenol | D37: 1QTVTNMT hạng III.3 | E37: 1 | F37: =VLOOKUP(D37,DGl!$B$8:$M$199,12,0) -> 208750 | G37: =E37*F37 -> 208750
A38: 8 | B38: 2TT5d1 | C38: KLN (Pb) | D38: 1QTVTNMT hạng III.3 | E38: 0.8 | F38: =VLOOKUP(D38,DGl!$B$8:$M$199,12,0) -> 208750 | G38: =E38*F38 -> 167000
A39: 9 | B39: 2TT5d2 | C39: KLN (Cd) | D39: 1QTVTNMT hạng III.3 | E39: 0.8 | F39: =VLOOKUP(D39,DGl!$B$8:$M$199,12,0) -> 208750 | G39: =E39*F39 -> 167000
A40: 10 | B40: 2TT5đ1 | C40: KLN ( As) | D40: 1QTVTNMT hạng III.3 | E40: 1 | F40: =VLOOKUP(D40,DGl!$B$8:$M$199,12,0) -> 208750 | G40: =E40*F40 -> 208750
A41: 11 | B41: 2TT5đ2 | C41: KLN (Hg) | D41: 1QTVTNMT hạng III.3 | E41: 1 | F41: =VLOOKUP(D41,DGl!$B$8:$M$199,12,0) -> 208750 | G41: =E41*F41 -> 208750
A42: 12 | B42: 2TT5e1 | C42: KL (Zn) | D42: 1QTVTNMT hạng III.2 | E42: 0.8 | F42: =VLOOKUP(D42,DGl!$B$8:$M$199,12,0) -> 206557.5 | G42: =E42*F42 -> 165246
A43: 13 | B43: 2TT5e2 | C43: KL (Cu) | D43: 1QTVTNMT hạng III.2 | E43: 0.8 | F43: =VLOOKUP(D43,DGl!$B$8:$M$199,12,0) -> 206557.5 | G43: =E43*F43 -> 165246
... A53: 23 | B53: 2TT7 | C53: Phân tích đồng thời Kim loại | D53: 1QTVTNMT hạng III.3 | E53: 1.1 | F53: =VLOOKUP(D53,DGl!$B$8:$M$199,12,0) -> 208750 | G53: =E53*F53 -> 229625

Sheet Dcu
A1: CHI PHÍ CÔNG CỤ, DỤNG CỤ (Hoạt động quan trắc môi trường nước thải)
F2: ĐVT: Đồng
A3: TT | B3: Mã hiệu | C3: Danh mục dụng cụ | D3: Đơn vị tính | E3: Thời hạn | F3: Định mức | G3: Ðơn giá (đồng) | H3: Thành tiền (đồng)
A4: A | B4: HOẠT ĐỘNG QUAN TRẮC VÀ PHÂN TÍCH MÔI TRƯỜNG TRẦM TÍCH
A5: A1 | B5: Công tác quan trắc môi trường trầm tích tại hiện trường (1TT)
A6: 1 | B6: 1TT1 | C6: pH (H2O, KCl) | H6: =SUM(H7:H14)*1.1 -> 5923.0769
B7: 1 | C7: Thùng đựng và bảo quản mẫu | D7: Cái | E7: =VLOOKUP(C7,[1]Dcu!$B$3:$D$510,3,0) -> 5 | F7: 0.2 | G7: =VLOOKUP(C7,[1]Dcu!$B$3:$E$510,4,0) -> 800000 | H7: =G7/(E7*26)*F7 -> 1230.7692
B8: 2 | C8: Hộp đựng mẫu | D8: chiếc | E8: =VLOOKUP(C8,[1]Dcu!$B$3:$D$510,3,0) -> 1 | F8: 0.25 | G8: =VLOOKUP(C8,[1]Dcu!$B$3:$E$510,4,0) -> 300000 | H8: =G8/(E8*26)*F8 -> 2884.6154
B9: 3 | C9: Quần áo BHLĐ | D9: bộ | E9: =VLOOKUP(C9,[1]Dcu!$B$3:$D$510,3,0) -> 6 | F9: 0.25 | G9: =VLOOKUP(C9,[1]Dcu!$B$3:$E$510,4,0) -> 50000 | H9: =G9/(E9*26)*F9 -> 80.128205
B10: 4 | C10: Giầy BHLĐ | D10: Đôi | E10: =VLOOKUP(C10,[1]Dcu!$B$3:$D$510,3,0) -> 12 | F10: 0.25 | G10: =VLOOKUP(C10,[1]Dcu!$B$3:$E$510,4,0) -> 55000 | H10: =G10/(E10*26)*F10 -> 44.070513
B11: 5 | C11: Tất sợi | D11: Đôi | E11: =VLOOKUP(C11,[1]Dcu!$B$3:$D$510,3,0) -> 6 | F11: 0.25 | G11: =VLOOKUP(C11,[1]Dcu!$B$3:$E$510,4,0) -> 7000 | H11: =G11/(E11*26)*F11 -> 11.217949
B12: 6 | C12: Mũ cứng | D12: Cái | E12: =VLOOKUP(C12,[1]Dcu!$B$3:$D$510,3,0) -> 3 | F12: 0.25 | G12: =VLOOKUP(C12,[1]Dcu!$B$3:$E$510,4,0) -> 20000 | H12: =G12/(E12*26)*F12 -> 64.102564
B13: 7 | C13: Ô che mưa, che nắng | D13: Cái | E13: =VLOOKUP(C13,[1]Dcu!$B$3:$D$510,3,0) -> 24 | F13: 0.25 | G13: =VLOOKUP(C13,[1]Dcu!$B$3:$E$510,4,0) -> 110000 | H13: =G13/(E13*26)*F13 -> 44.070513
B14: 8 | C14: Găng tay y tế | D14: hộp | E14: =VLOOKUP(C14,[1]Dcu!$B$3:$D$510,3,0) -> 0.3 | F14: 0.02 | G14: =VLOOKUP(C14,[1]Dcu!$B$3:$E$510,4,0) -> 400000 | H14: =G14/(E14*26)*F14 -> 1025.641
A15: 2 | B15: 1TT2 | C15: Tổng các bon hữu cơ | H15: =SUM(H16:H23)*1.1 -> 5923.0769
B16: 1 | C16: Thùng đựng và bảo quản mẫu | D16: Cái | E16: =VLOOKUP(C16,[1]Dcu!$B$3:$D$510,3,0) -> 5 | F16: 0.2 | G16: =VLOOKUP(C16,[1]Dcu!$B$3:$E$510,4,0) -> 800000 | H16: =G16/(E16*26)*F16 -> 1230.7692
B17: 2 | C17: Hộp đựng mẫu | D17: chiếc | E17: =VLOOKUP(C17,[1]Dcu!$B$3:$D$510,3,0) -> 1 | F17: 0.25 | G17: =VLOOKUP(C17,[1]Dcu!$B$3:$E$510,4,0) -> 300000 | H17: =G17/(E17*26)*F17 -> 2884.6154
B18: 3 | C18: Quần áo BHLĐ | D18: bộ | E18: =VLOOKUP(C18,[1]Dcu!$B$3:$D$510,3,0) -> 6 | F18: 0.25 | G18: =VLOOKUP(C18,[1]Dcu!$B$3:$E$510,4,0) -> 50000 | H18: =G18/(E18*26)*F18 -> 80.128205
B19: 4 | C19: Giầy BHLĐ | D19: Đôi | E19: =VLOOKUP(C19,[1]Dcu!$B$3:$D$510,3,0) -> 12 | F19: 0.25 | G19: =VLOOKUP(C19,[1]Dcu!$B$3:$E$510,4,0) -> 55000 | H19: =G19/(E19*26)*F19 -> 44.070513
B20: 5 | C20: Tất sợi | D20: Đôi | E20: =VLOOKUP(C20,[1]Dcu!$B$3:$D$510,3,0) -> 6 | F20: 0.25 | G20: =VLOOKUP(C20,[1]Dcu!$B$3:$E$510,4,0) -> 7000 | H20: =G20/(E20*26)*F20 -> 11.217949
B21: 6 | C21: Mũ cứng | D21: Cái | E21: =VLOOKUP(C21,[1]Dcu!$B$3:$D$510,3,0) -> 3 | F21: 0.25 | G21: =VLOOKUP(C21,[1]Dcu!$B$3:$E$510,4,0) -> 20000 | H21: =G21/(E21*26)*F21 -> 64.102564
B22: 7 | C22: Ô che mưa, che nắng | D22: Cái | E22: =VLOOKUP(C22,[1]Dcu!$B$3:$D$510,3,0) -> 24 | F22: 0.25 | G22: =VLOOKUP(C22,[1]Dcu!$B$3:$E$510,4,0) -> 110000 | H22: =G22/(E22*26)*F22 -> 44.070513
B23: 8 | C23: Găng tay y tế | D23: hộp | E23: =VLOOKUP(C23,[1]Dcu!$B$3:$D$510,3,0) -> 0.3 | F23: 0.02 | G23: =VLOOKUP(C23,[1]Dcu!$B$3:$E$510,4,0) -> 400000 | H23: =G23/(E23*26)*F23 -> 1025.641
A24: 3 | B24: 1TT3 | C24: Dầu mỡ | H24: =SUM(H25:H32)*1.1 -> 5923.0769
B25: 1 | C25: Thùng đựng và bảo quản mẫu | D25: Cái | E25: =VLOOKUP(C25,[1]Dcu!$B$3:$D$510,3,0) -> 5 | F25: 0.2 | G25: =VLOOKUP(C25,[1]Dcu!$B$3:$E$510,4,0) -> 800000 | H25: =G25/(E25*26)*F25 -> 1230.7692
B26: 2 | C26: Hộp đựng mẫu | D26: chiếc | E26: =VLOOKUP(C26,[1]Dcu!$B$3:$D$510,3,0) -> 1 | F26: 0.25 | G26: =VLOOKUP(C26,[1]Dcu!$B$3:$E$510,4,0) -> 300000 | H26: =G26/(E26*26)*F26 -> 2884.6154
B27: 3 | C27: Quần áo BHLĐ | D27: bộ | E27: =VLOOKUP(C27,[1]Dcu!$B$3:$D$510,3,0) -> 6 | F27: 0.25 | G27: =VLOOKUP(C27,[1]Dcu!$B$3:$E$510,4,0) -> 50000 | H27: =G27/(E27*26)*F27 -> 80.128205
B28: 4 | C28: Giầy BHLĐ | D28: Đôi | E28: =VLOOKUP(C28,[1]Dcu!$B$3:$D$510,3,0) -> 12 | F28: 0.25 | G28: =VLOOKUP(C28,[1]Dcu!$B$3:$E$510,4,0) -> 55000 | H28: =G28/(E28*26)*F28 -> 44.070513
B29: 5 | C29: Tất sợi | D29: Đôi | E29: =VLOOKUP(C29,[1]Dcu!$B$3:$D$510,3,0) -> 6 | F29: 0.25 | G29: =VLOOKUP(C29,[1]Dcu!$B$3:$E$510,4,0) -> 7000 | H29: =G29/(E29*26)*F29 -> 11.217949
B30: 6 | C30: Mũ cứng | D30: Cái | E30: =VLOOKUP(C30,[1]Dcu!$B$3:$D$510,3,0) -> 3 | F30: 0.25 | G30: =VLOOKUP(C30,[1]Dcu!$B$3:$E$510,4,0) -> 20000 | H30: =G30/(E30*26)*F30 -> 64.102564
B31: 7 | C31: Ô che mưa, che nắng | D31: Cái | E31: =VLOOKUP(C31,[1]Dcu!$B$3:$D$510,3,0) -> 24 | F31: 0.25 | G31: =VLOOKUP(C31,[1]Dcu!$B$3:$E$510,4,0) -> 110000 | H31: =G31/(E31*26)*F31 -> 44.070513
B32: 8 | C32: Găng tay y tế | D32: hộp | E32: =VLOOKUP(C32,[1]Dcu!$B$3:$D$510,3,0) -> 0.3 | F32: 0.02 | G32: =VLOOKUP(C32,[1]Dcu!$B$3:$E$510,4,0) -> 400000 | H32: =G32/(E32*26)*F32 -> 1025.641
A33: 4 | B33: 1TT4 | C33: Xyanua (CN-) | H33: =SUM(H34:H41)*1.1 -> 5923.0769
B34: 1 | C34: Thùng đựng và bảo quản mẫu | D34: Cái | E34: =VLOOKUP(C34,[1]Dcu!$B$3:$D$510,3,0) -> 5 | F34: 0.2 | G34: =VLOOKUP(C34,[1]Dcu!$B$3:$E$510,4,0) -> 800000 | H34: =G34/(E34*26)*F34 -> 1230.7692
B35: 2 | C35: Hộp đựng mẫu | D35: chiếc | E35: =VLOOKUP(C35,[1]Dcu!$B$3:$D$510,3,0) -> 1 | F35: 0.25 | G35: =VLOOKUP(C35,[1]Dcu!$B$3:$E$510,4,0) -> 300000 | H35: =G35/(E35*26)*F35 -> 2884.6154
B36: 3 | C36: Quần áo BHLĐ | D36: bộ | E36: =VLOOKUP(C36,[1]Dcu!$B$3:$D$510,3,0) -> 6 | F36: 0.25 | G36: =VLOOKUP(C36,[1]Dcu!$B$3:$E$510,4,0) -> 50000 | H36: =G36/(E36*26)*F36 -> 80.128205
B37: 4 | C37: Giầy BHLĐ | D37: Đôi | E37: =VLOOKUP(C37,[1]Dcu!$B$3:$D$510,3,0) -> 12 | F37: 0.25 | G37: =VLOOKUP(C37,[1]Dcu!$B$3:$E$510,4,0) -> 55000 | H37: =G37/(E37*26)*F37 -> 44.070513
B38: 5 | C38: Tất sợi | D38: Đôi | E38: =VLOOKUP(C38,[1]Dcu!$B$3:$D$510,3,0) -> 6 | F38: 0.25 | G38: =VLOOKUP(C38,[1]Dcu!$B$3:$E$510,4,0) -> 7000 | H38: =G38/(E38*26)*F38 -> 11.217949
B39: 6 | C39: Mũ cứng | D39: Cái | E39: =VLOOKUP(C39,[1]Dcu!$B$3:$D$510,3,0) -> 3 | F39: 0.25 | G39: =VLOOKUP(C39,[1]Dcu!$B$3:$E$510,4,0) -> 20000 | H39: =G39/(E39*26)*F39 -> 64.102564
B40: 7 | C40: Ô che mưa, che nắng | D40: Cái | E40: =VLOOKUP(C40,[1]Dcu!$B$3:$D$510,3,0) -> 24 | F40: 0.25 | G40: =VLOOKUP(C40,[1]Dcu!$B$3:$E$510,4,0) -> 110000 | H40: =G40/(E40*26)*F40 -> 44.070513
...

Sheet VL
A1: CHI PHÍ VẬT LIỆU (Hoạt động quan trắc môi trường không khí xung quanh và nước mặt lục địa)
F2: ĐVT: Đồng
A3: TT | B3: Mã hiệu | C3: Danh mục vật tư | D3: Đơn vị tính | E3: Định mức | F3: Đơn giá | G3: Thành tiền
A4: A | B4: HOẠT ĐỘNG QUAN TRẮC VÀ PHÂN TÍCH MÔI TRƯỜNG TRẦM TÍCH
A5: A1 | B5: Công tác quan trắc môi trường trầm tích tại hiện trường (TT)
A6: 1 | B6: 1TT1 | C6: pH (H2O, KCl) | G6: =SUM(G7:G13)*1.08 -> 10832.4
B7: 1 | C7: Nước rửa dụng cụ | D7: Lít | E7: 2 | F7: =VLOOKUP(C7,[1]VL!$B$3:$D$523,3,0) -> 3500 | G7: =F7*E7 -> 7000
B8: 2 | C8: Sổ công tác | D8: cuốn | E8: 0.005 | F8: =VLOOKUP(C8,[1]VL!$B$3:$D$523,3,0) -> 10000 | G8: =F8*E8 -> 50
B9: 3 | C9: Giấy lau | D9: Hộp | E9: 0.01 | F9: =VLOOKUP(C9,[1]VL!$B$3:$D$523,3,0) -> 80000 | G9: =F9*E9 -> 800
B10: 4 | C10: Gim kẹp giấy | D10: Hộp | E10: 0.02 | F10: =VLOOKUP(C10,[1]VL!$B$3:$D$523,3,0) -> 2000 | G10: =F10*E10 -> 40
B11: 5 | C11: Gim bấm | D11: Hộp | E11: 0.02 | F11: =VLOOKUP(C11,[1]VL!$B$3:$D$523,3,0) -> 2000 | G11: =F11*E11 -> 40
B12: 6 | C12: Cồn lau dụng cụ | D12: ml | E12: 20 | F12: =VLOOKUP(C12,[1]VL!$B$3:$D$523,3,0) -> 35 | G12: =F12*E12 -> 700
B13: 7 | C13: Bản đồ địa hình | D13: tờ | E13: 0.02 | F13: =VLOOKUP(C13,[1]VL!$B$3:$D$523,3,0) -> 70000 | G13: =F13*E13 -> 1400
A14: 2 | B14: 1TT2 | C14: Tổng các bon hữu cơ | G14: =SUM(G15:G21)*1.08 -> 10832.4
B15: 2 | C15: Nước rửa dụng cụ | D15: Lít | E15: 2 | F15: =VLOOKUP(C15,[1]VL!$B$3:$D$523,3,0) -> 3500 | G15: =F15*E15 -> 7000
B16: 3 | C16: Sổ công tác | D16: cuốn | E16: 0.005 | F16: =VLOOKUP(C16,[1]VL!$B$3:$D$523,3,0) -> 10000 | G16: =F16*E16 -> 50
B17: 4 | C17: Giấy lau | D17: Hộp | E17: 0.01 | F17: =VLOOKUP(C17,[1]VL!$B$3:$D$523,3,0) -> 80000 | G17: =F17*E17 -> 800
B18: 5 | C18: Gim kẹp giấy | D18: Hộp | E18: 0.02 | F18: =VLOOKUP(C18,[1]VL!$B$3:$D$523,3,0) -> 2000 | G18: =F18*E18 -> 40
B19: 6 | C19: Gim bấm | D19: Hộp | E19: 0.02 | F19: =VLOOKUP(C19,[1]VL!$B$3:$D$523,3,0) -> 2000 | G19: =F19*E19 -> 40
B20: 7 | C20: Cồn lau dụng cụ | D20: ml | E20: 20 | F20: =VLOOKUP(C20,[1]VL!$B$3:$D$523,3,0) -> 35 | G20: =F20*E20 -> 700
B21: 8 | C21: Bản đồ địa hình | D21: tờ | E21: 0.02 | F21: =VLOOKUP(C21,[1]VL!$B$3:$D$523,3,0) -> 70000 | G21: =F21*E21 -> 1400
A22: 3 | B22: 1TT3 | C22: Xyanua (CN-) | G22: =SUM(G23:G29)*1.08 -> 10832.4
B23: 2 | C23: Nước rửa dụng cụ | D23: Lít | E23: 2 | F23: =VLOOKUP(C23,[1]VL!$B$3:$D$523,3,0) -> 3500 | G23: =F23*E23 -> 7000
B24: 3 | C24: Sổ công tác | D24: cuốn | E24: 0.005 | F24: =VLOOKUP(C24,[1]VL!$B$3:$D$523,3,0) -> 10000 | G24: =F24*E24 -> 50
B25: 4 | C25: Giấy lau | D25: Hộp | E25: 0.01 | F25: =VLOOKUP(C25,[1]VL!$B$3:$D$523,3,0) -> 80000 | G25: =F25*E25 -> 800
B26: 5 | C26: Gim kẹp giấy | D26: Hộp | E26: 0.02 | F26: =VLOOKUP(C26,[1]VL!$B$3:$D$523,3,0) -> 2000 | G26: =F26*E26 -> 40
B27: 6 | C27: Gim bấm | D27: Hộp | E27: 0.02 | F27: =VLOOKUP(C27,[1]VL!$B$3:$D$523,3,0) -> 2000 | G27: =F27*E27 -> 40
B28: 7 | C28: Cồn lau dụng cụ | D28: ml | E28: 20 | F28: =VLOOKUP(C28,[1]VL!$B$3:$D$523,3,0) -> 35 | G28: =F28*E28 -> 700
B29: 8 | C29: Bản đồ địa hình | D29: tờ | E29: 0.02 | F29: =VLOOKUP(C29,[1]VL!$B$3:$D$523,3,0) -> 70000 | G29: =F29*E29 -> 1400
A30: 4 | B30: 1TT4 | C30: Dầu mỡ | G30: =SUM(G31:G37)*1.08 -> 10832.4
B31: 2 | C31: Nước rửa dụng cụ | D31: Lít | E31: 2 | F31: =VLOOKUP(C31,[1]VL!$B$3:$D$523,3,0) -> 3500 | G31: =F31*E31 -> 7000
B32: 3 | C32: Sổ công tác | D32: cuốn | E32: 0.005 | F32: =VLOOKUP(C32,[1]VL!$B$3:$D$523,3,0) -> 10000 | G32: =F32*E32 -> 50
B33: 4 | C33: Giấy lau | D33: Hộp | E33: 0.01 | F33: =VLOOKUP(C33,[1]VL!$B$3:$D$523,3,0) -> 80000 | G33: =F33*E33 -> 800
B34: 5 | C34: Gim kẹp giấy | D34: Hộp | E34: 0.02 | F34: =VLOOKUP(C34,[1]VL!$B$3:$D$523,3,0) -> 2000 | G34: =F34*E34 -> 40
B35: 6 | C35: Gim bấm | D35: Hộp | E35: 0.02 | F35: =VLOOKUP(C35,[1]VL!$B$3:$D$523,3,0) -> 2000 | G35: =F35*E35 -> 40
B36: 7 | C36: Cồn lau dụng cụ | D36: ml | E36: 20 | F36: =VLOOKUP(C36,[1]VL!$B$3:$D$523,3,0) -> 35 | G36: =F36*E36 -> 700
B37: 8 | C37: Bản đồ địa hình | D37: tờ | E37: 0.02 | F37: =VLOOKUP(C37,[1]VL!$B$3:$D$523,3,0) -> 70000 | G37: =F37*E37 -> 1400
A38: 5 | B38: 1TT5a | C38: Tổng P | G38: =SUM(G39:G46)*1.08 -> 11372.4
B39: 2 | C39: Túi PE | D39: chiếc | E39: 1 | F39: =VLOOKUP(C39,[1]VL!$B$3:$D$523,3,0) -> 500 | G39: =F39*E39 -> 500
B40: 3 | C40: Nước rửa dụng cụ | D40: Lít | E40: 2 | F40: =VLOOKUP(C40,[1]VL!$B$3:$D$523,3,0) -> 3500 | G40: =F40*E40 -> 7000
...

Sheet TB
A1: CHI PHÍ THIẾT BỊ (Hoạt động quan trắc môi trường trầm tích)
G2: ĐVT: Đồng
A3: TT | B3: Mã hiệu | C3: Danh mục thiết bị | D3: Đơn vị tính | E3: Công suất (Kw) | F3: Ca | G3: Mức KH/ca | H3: Nguyên giá (đồng) | I3: Thành tiền (đồng)
A4: A | B4: HOẠT ĐỘNG QUAN TRẮC VÀ PHÂN TÍCH MÔI TRƯỜNG TRẦM TÍCH ĐÁY
A5: A1 | B5: Công tác quan trắc môi trường trầm tích đáy tại hiện trường (TT) | J5: 250
A6: 1 | B6: 1TT1 | C6: pH (H2O, KCl) | I6: =SUM(I7:I8) -> 3370.4
B7: 1 | C7: Thiết bị lấy mẫu | D7: Cái | E7: 1 | F7: 0.12 | G7: =H7/(J7*$J$5) -> 25300 | H7: =VLOOKUP(C7,[1]TB!$B$3:$D$503,3,0) -> 50600000 | I7: =F7*G7 -> 3036 | J7: 8
B8: 2 | C8: Máy định vị GPS cầm tay | D8: Cái | E8: Pin khô | F8: 0.08 | G8: =H8/(J8*$J$5) -> 4180 | H8: =VLOOKUP(C8,[1]TB!$B$3:$D$503,3,0) -> 10450000 | I8: =F8*G8 -> 334.4 | J8: 10
A9: 2 | B9: 1TT2 | C9: Tổng các bon hữu cơ | I9: =SUM(I10:I11) -> 3370.4
B10: 1 | C10: Thiết bị lấy mẫu | D10: Cái | E10: 1 | F10: 0.12 | G10: =H10/(J10*$J$5) -> 25300 | H10: =VLOOKUP(C10,[1]TB!$B$3:$D$503,3,0) -> 50600000 | I10: =F10*G10 -> 3036 | J10: =VLOOKUP(C10,'[2]Ng.gia thiêtbi'!$B$3:$E$202,4,0) -> 8
B11: 2 | C11: Máy định vị GPS cầm tay | D11: Cái | E11: Pin khô | F11: 0.08 | G11: =H11/(J11*$J$5) -> 4180 | H11: =VLOOKUP(C11,[1]TB!$B$3:$D$503,3,0) -> 10450000 | I11: =F11*G11 -> 334.4 | J11: =VLOOKUP(C11,'[2]Ng.gia thiêtbi'!$B$3:$E$202,4,0) -> 10
A12: 3 | B12: 1TT3 | C12: Dầu mỡ | I12: =SUM(I13:I14) -> 3370.4
B13: 1 | C13: Thiết bị lấy mẫu | D13: Cái | E13: 1 | F13: 0.12 | G13: =H13/(J13*$J$5) -> 25300 | H13: =VLOOKUP(C13,[1]TB!$B$3:$D$503,3,0) -> 50600000 | I13: =F13*G13 -> 3036 | J13: =VLOOKUP(C13,'[2]Ng.gia thiêtbi'!$B$3:$E$202,4,0) -> 8
B14: 2 | C14: Máy định vị GPS cầm tay | D14: Cái | E14: Pin khô | F14: 0.08 | G14: =H14/(J14*$J$5) -> 4180 | H14: =VLOOKUP(C14,[1]TB!$B$3:$D$503,3,0) -> 10450000 | I14: =F14*G14 -> 334.4 | J14: =VLOOKUP(C14,'[2]Ng.gia thiêtbi'!$B$3:$E$202,4,0) -> 10
A15: 4 | B15: 1TT4 | C15: Xyanua (CN-) | I15: =SUM(I16:I17) -> 3370.4
B16: 1 | C16: Thiết bị lấy mẫu | D16: Cái | E16: 1 | F16: 0.12 | G16: =H16/(J16*$J$5) -> 25300 | H16: =VLOOKUP(C16,[1]TB!$B$3:$D$503,3,0) -> 50600000 | I16: =F16*G16 -> 3036 | J16: =VLOOKUP(C16,'[2]Ng.gia thiêtbi'!$B$3:$E$202,4,0) -> 8
B17: 2 | C17: Máy định vị GPS cầm tay | D17: Cái | E17: Pin khô | F17: 0.08 | G17: =H17/(J17*$J$5) -> 4180 | H17: =VLOOKUP(C17,[1]TB!$B$3:$D$503,3,0) -> 10450000 | I17: =F17*G17 -> 334.4 | J17: =VLOOKUP(C17,'[2]Ng.gia thiêtbi'!$B$3:$E$202,4,0) -> 10
A18: 5 | B18: 1TT5a | C18: Tổng N | I18: =SUM(I19:I20) -> 3370.4
B19: 1 | C19: Thiết bị lấy mẫu | D19: Cái | E19: 1 | F19: 0.12 | G19: =H19/(J19*$J$5) -> 25300 | H19: =VLOOKUP(C19,[1]TB!$B$3:$D$503,3,0) -> 50600000 | I19: =F19*G19 -> 3036 | J19: =VLOOKUP(C19,'[2]Ng.gia thiêtbi'!$B$3:$E$202,4,0) -> 8
B20: 2 | C20: Máy định vị GPS cầm tay | D20: Cái | E20: Pin khô | F20: 0.08 | G20: =H20/(J20*$J$5) -> 4180 | H20: =VLOOKUP(C20,[1]TB!$B$3:$D$503,3,0) -> 10450000 | I20: =F20*G20 -> 334.4 | J20: =VLOOKUP(C20,'[2]Ng.gia thiêtbi'!$B$3:$E$202,4,0) -> 10
A21: 6 | B21: 1TT5b | C21: Tổng P | F21: Như mục 1TT5a | I21: =I18 -> 3370.4
A22: 7 | B22: 1TT5c | C22: Phenol | F22: Như mục 1TT5a | I22: =I18 -> 3370.4
A23: 8 | B23: 1TT5d1 | C23: Kim Loại nặng (Pb) | F23: Như mục 1TT5a | I23: =I18 -> 3370.4
A24: 9 | B24: 1TT5d2 | C24: Kim loại nặng (Cd) | F24: Như mục 1TT5a | I24: =I23 -> 3370.4
A25: 10 | B25: 1TT5đ1 | C25: Kim loại nặng ( As) | F25: Như mục 1TT5a | I25: =I18 -> 3370.4
A26: 11 | B26: 1TT5đ2 | C26: Kim loại nặng(Hg) | F26: Như mục 1TT5a | I26: =I23 -> 3370.4
A27: 12 | B27: 1TT5e1 | C27: Kim loại (Zn) | F27: Như mục 1TT5a | I27: =I18 -> 3370.4
A28: 13 | B28: 1TT5e2 | C28: Kim loại (Cu) | F28: Như mục 1TT5a | I28: =I23 -> 3370.4
A29: 14 | B29: 1TT5e3 | C29: Kim loại (Cr) | F29: Như mục 1TT5a | I29: =I23 -> 3370.4
A30: 15 | B30: 1TT5e4 | C30: Kim loại (Mn) | F30: Như mục 1TT5a | I30: =I23 -> 3370.4
A31: 16 | B31: 1TT5e5 | C31: Kim loại (Ni) | F31: Như mục 1TT5a | I31: =I23 -> 3370.4
A32: 17 | B32: 1TT5f | C32: Tổng K2O | F32: Như mục 1TT5a | I32: =I18 -> 3370.4
A33: 18 | B33: 1TT6a | C33: Thuốc BVTV nhóm Clo hữu cơ | I33: =SUM(I34:I35) -> 3370.4
B34: 1 | C34: Thiết bị lấy mẫu | D34: Cái | E34: 1 | F34: 0.12 | G34: =H34/(J34*$J$5) -> 25300 | H34: =VLOOKUP(C34,[1]TB!$B$3:$D$503,3,0) -> 50600000 | I34: =F34*G34 -> 3036 | J34: =VLOOKUP(C34,'[2]Ng.gia thiêtbi'!$B$3:$E$202,4,0) -> 8
B35: 2 | C35: Máy định vị GPS cầm tay | D35: Cái | E35: Pin khô | F35: 0.08 | G35: =H35/(J35*$J$5) -> 4180 | H35: =VLOOKUP(C35,[1]TB!$B$3:$D$503,3,0) -> 10450000 | I35: =F35*G35 -> 334.4 | J35: =VLOOKUP(C35,'[2]Ng.gia thiêtbi'!$B$3:$E$202,4,0) -> 10
A36: 19 | B36: 1TT6b | C36: Thuốc BVTV nhóm phốt pho hữu cơ | F36: Như mục 1TT6a | I36: =I33 -> 3370.4
A37: 20 | B37: 1TT6c | C37: Thuốc BVTV nhóm Pyrethroid | F37: Như mục 1TT6a | I37: =I33 -> 3370.4
A38: 21 | B38: 1TT6d | C38: Polycyclic aromatic hydrocarbon (PAHs) | F38: Như mục 1TT6a | I38: =I33 -> 3370.4
A39: 22 | B39: 1TT6đ | C39: PCBs | F39: Như mục 1TT6a | I39: =I33 -> 3370.4
B40: Công tác phân tích các thông số môi trường nước thải trong phòng thí nghiệm (2NT) | J40: 500
...

Sheet Don gia TH
A1: PHỤ LỤC 10
A2: TỔNG HỢP ĐƠN GIÁ SẢN PHẨM QUAN TRẮC MÔI TRƯỜNG TRẦM TÍCH
J3: Đơn vị tính: đồng/thông số
A4: Số TT | B4: Mã hiệu | C4: Thông số quan trắc | D4: Chi phí LĐKT | E4: Chi phí CCDC | F4: Chi phí vật liệu | G4: CP năng lượng | H4: Chi phí khấu hao | I4: Chi phí trực tiếp | J4: Chi phí chung (20%) | K4: Đơn giá ( không VAT) | L4: Đơn giá theo ĐM cũ | M4: Chênh lệch | N4: Đơn gia thực tế | O4: Chêch lệch
A5: A | B5: B | C5: C | D5: 1 | E5: 2 | F5: 3 | G5: 4 | H5: 5 | I5: 5=1+2+3+4 | J5: 6=5*20% | K5: 7=6+5 | L5: 9 | M5: 10=8-9
A6: A | B6: HOẠT ĐỘNG QUAN TRẮC VÀ PHÂN TÍCH MÔI TRƯỜNG TRẦM TÍCH
A7: A1 | B7: Công tác quan trắc môi trường trầm tích tại hiện trường (2TT)
A8: 1 | B8: 1TT1 | C8: pH (H2O, KCl) | D8: =VLOOKUP(B8,LDKT!$B$5:$G$214,6,0) -> 88495.2 | E8: =VLOOKUP(B8,Dcu!$B$6:$H$919,7,0) -> 5923.0769 | F8: =VLOOKUP(B8,VL!$B$5:$G$915,6,0) -> 10832.4 | G8: 0 | H8: =VLOOKUP(B8,TB!$B$4:$I$2022,8,0) -> 3370.4 | I8: =D8+E8+F8+G8 -> 105250.68 | J8: =I8*20% -> 21050.135 | K8: =ROUND((I8+J8),-2) -> 126300 | N8: 181900 | O8: =K8-N8 -> -55600
A9: 2 | B9: 1TT2 | C9: Tổng các chất hữu cơ | D9: =VLOOKUP(B9,LDKT!$B$5:$G$214,6,0) -> 88495.2 | E9: =VLOOKUP(B9,Dcu!$B$6:$H$919,7,0) -> 5923.0769 | F9: =VLOOKUP(B9,VL!$B$5:$G$915,6,0) -> 10832.4 | G9: 0 | H9: =VLOOKUP(B9,TB!$B$4:$I$2022,8,0) -> 3370.4 | I9: =D9+E9+F9+G9 -> 105250.68 | J9: =I9*20% -> 21050.135 | K9: =ROUND((I9+J9),-2) -> 126300 | N9: 84200 | O9: =K9-N9 -> 42100
A10: 3 | B10: 1TT3 | C10: Dầu mỡ | D10: =VLOOKUP(B10,LDKT!$B$5:$G$214,6,0) -> 86754.15 | E10: =VLOOKUP(B10,Dcu!$B$6:$H$919,7,0) -> 5923.0769 | F10: =VLOOKUP(B10,VL!$B$5:$G$915,6,0) -> 10832.4 | G10: 0 | H10: =VLOOKUP(B10,TB!$B$4:$I$2022,8,0) -> 3370.4 | I10: =D10+E10+F10+G10 -> 103509.63 | J10: =I10*20% -> 20701.925 | K10: =ROUND((I10+J10),-2) -> 124200 | N10: 84200 | O10: =K10-N10 -> 40000
A11: 4 | B11: 1TT4 | C11: Cyanua (CN-) | D11: =VLOOKUP(B11,LDKT!$B$5:$G$214,6,0) -> 86754.15 | E11: =VLOOKUP(B11,Dcu!$B$6:$H$919,7,0) -> 5923.0769 | F11: =VLOOKUP(B11,VL!$B$5:$G$915,6,0) -> 10832.4 | G11: 0 | H11: =VLOOKUP(B11,TB!$B$4:$I$2022,8,0) -> 3370.4 | I11: =D11+E11+F11+G11 -> 103509.63 | J11: =I11*20% -> 20701.925 | K11: =ROUND((I11+J11),-2) -> 124200 | N11: 107900 | O11: =K11-N11 -> 16300
A12: 5 | B12: 1TT5a | C12: Tổng N | D12: =VLOOKUP(B12,LDKT!$B$5:$G$214,6,0) -> 86754.15 | E12: =VLOOKUP(B12,Dcu!$B$6:$H$919,7,0) -> 5923.0769 | F12: =VLOOKUP(B12,VL!$B$5:$G$915,6,0) -> 11372.4 | G12: 0 | H12: =VLOOKUP(B12,TB!$B$4:$I$2022,8,0) -> 3370.4 | I12: =D12+E12+F12+G12 -> 104049.63 | J12: =I12*20% -> 20809.925 | K12: =ROUND((I12+J12),-2) -> 124900 | N12: 120900 | O12: =K12-N12 -> 4000
A13: 6 | B13: 1TT5b | C13: Tổng P | D13: =VLOOKUP(B13,LDKT!$B$5:$G$214,6,0) -> 86754.15 | E13: =VLOOKUP(B13,Dcu!$B$6:$H$919,7,0) -> 5923.0769 | F13: =VLOOKUP(B13,VL!$B$5:$G$915,6,0) -> 11372.4 | G13: 0 | H13: =VLOOKUP(B13,TB!$B$4:$I$2022,8,0) -> 3370.4 | I13: =D13+E13+F13+G13 -> 104049.63 | J13: =I13*20% -> 20809.925 | K13: =ROUND((I13+J13),-2) -> 124900 | N13: 120900 | O13: =K13-N13 -> 4000
A14: 7 | B14: 1TT5c | C14: Phenol | D14: =VLOOKUP(B14,LDKT!$B$5:$G$214,6,0) -> 86754.15 | E14: =VLOOKUP(B14,Dcu!$B$6:$H$919,7,0) -> 5923.0769 | F14: =VLOOKUP(B14,VL!$B$5:$G$915,6,0) -> 11372.4 | G14: 0 | H14: =VLOOKUP(B14,TB!$B$4:$I$2022,8,0) -> 3370.4 | I14: =D14+E14+F14+G14 -> 104049.63 | J14: =I14*20% -> 20809.925 | K14: =ROUND((I14+J14),-2) -> 124900 | N14: 107900 | O14: =K14-N14 -> 17000
A15: 8 | B15: 1TT5d1 | C15: Kim Loại nặng (Pb) | D15: =VLOOKUP(B15,LDKT!$B$5:$G$214,6,0) -> 86754.15 | E15: =VLOOKUP(B15,Dcu!$B$6:$H$919,7,0) -> 5923.0769 | F15: =VLOOKUP(B15,VL!$B$5:$G$915,6,0) -> 11372.4 | G15: 0 | H15: =VLOOKUP(B15,TB!$B$4:$I$2022,8,0) -> 3370.4 | I15: =D15+E15+F15+G15 -> 104049.63 | J15: =I15*20% -> 20809.925 | K15: =ROUND((I15+J15),-2) -> 124900 | N15: 84200 | O15: =K15-N15 -> 40700
A16: 9 | B16: 1TT5d2 | C16: Kim loại nặng (Cd) | D16: =VLOOKUP(B16,LDKT!$B$5:$G$214,6,0) -> 86754.15 | E16: =VLOOKUP(B16,Dcu!$B$6:$H$919,7,0) -> 5923.0769 | F16: =VLOOKUP(B16,VL!$B$5:$G$915,6,0) -> 11372.4 | G16: 0 | H16: =VLOOKUP(B16,TB!$B$4:$I$2022,8,0) -> 3370.4 | I16: =D16+E16+F16+G16 -> 104049.63 | J16: =I16*20% -> 20809.925 | K16: =ROUND((I16+J16),-2) -> 124900 | N16: 84200 | O16: =K16-N16 -> 40700
A17: 10 | B17: 1TT5đ1 | C17: Kim loại nặng ( As) | D17: =VLOOKUP(B17,LDKT!$B$5:$G$214,6,0) -> 86754.15 | E17: =VLOOKUP(B17,Dcu!$B$6:$H$919,7,0) -> 5923.0769 | F17: =VLOOKUP(B17,VL!$B$5:$G$915,6,0) -> 11372.4 | G17: 0 | H17: =VLOOKUP(B17,TB!$B$4:$I$2022,8,0) -> 3370.4 | I17: =D17+E17+F17+G17 -> 104049.63 | J17: =I17*20% -> 20809.925 | K17: =ROUND((I17+J17),-2) -> 124900 | N17: 84200 | O17: =K17-N17 -> 40700
A18: 11 | B18: 1TT5đ2 | C18: Kim loại nặng(Hg) | D18: =VLOOKUP(B18,LDKT!$B$5:$G$214,6,0) -> 86754.15 | E18: =VLOOKUP(B18,Dcu!$B$6:$H$919,7,0) -> 5923.0769 | F18: =VLOOKUP(B18,VL!$B$5:$G$915,6,0) -> 11372.4 | G18: 0 | H18: =VLOOKUP(B18,TB!$B$4:$I$2022,8,0) -> 3370.4 | I18: =D18+E18+F18+G18 -> 104049.63 | J18: =I18*20% -> 20809.925 | K18: =ROUND((I18+J18),-2) -> 124900 | N18: 84200 | O18: =K18-N18 -> 40700
A19: 12 | B19: 1TT5e1 | C19: Kim loại (Zn) | D19: =VLOOKUP(B19,LDKT!$B$5:$G$214,6,0) -> 86754.15 | E19: =VLOOKUP(B19,Dcu!$B$6:$H$919,7,0) -> 5923.0769 | F19: =VLOOKUP(B19,VL!$B$5:$G$915,6,0) -> 11372.4 | G19: 0 | H19: =VLOOKUP(B19,TB!$B$4:$I$2022,8,0) -> 3370.4 | I19: =D19+E19+F19+G19 -> 104049.63 | J19: =I19*20% -> 20809.925 | K19: =ROUND((I19+J19),-2) -> 124900 | N19: 84200 | O19: =K19-N19 -> 40700
... A29: 22 | B29: 1TT6đ | C29: PCBs | D29: =VLOOKUP(B29,LDKT!$B$5:$G$214,6,0) -> 86754.15 | E29: =VLOOKUP(B29,Dcu!$B$6:$H$919,7,0) -> 5923.0769 | F29: =VLOOKUP(B29,VL!$B$5:$G$915,6,0) -> 10994.4 | G29: 0 | H29: =VLOOKUP(B29,TB!$B$4:$I$2022,8,0) -> 3370.4 | I29: =D29+E29+F29+G29 -> 103671.63 | J29: =I29*20% -> 20734.325 | K29: =ROUND((I29+J29),-2) -> 124400 | N29: 104900 | O29: =K29-N29 -> 19500
A30: II | B30: Hoạt động phân tích mẫu trầm tích trong phòng thí nghiệm
A31: 1 | B31: 2TT1 | C31: pH (H2O, KCl) | D31: =VLOOKUP(B31,LDKT!$B$5:$G$214,6,0) -> 110619 | E31: =VLOOKUP(B31,Dcu!$B$6:$H$919,7,0) -> 30247.233 | F31: =VLOOKUP(B31,VL!$B$5:$G$915,6,0) -> 110261.95 | G31: =TB!I48 -> 7057.92 | H31: =TB!I41 -> 11930.44 | I31: =D31+E31+F31+G31 -> 258186.1 | J31: =I31*20% -> 51637.221 | K31: =ROUND((I31+J31),-2) -> 309800 | L31: ='[4]Don gia 1050'!$R$32 -> 619198.03 | M31: =K31-L31 -> -309398.03 | N31: 181900 | O31: =K31-N31 -> 127900
A32: 2 | B32: 2TT2 | C32: Tổng các bon hữu cơ | D32: =VLOOKUP(B32,LDKT!$B$5:$G$214,6,0) -> 125250 | E32: =VLOOKUP(B32,Dcu!$B$6:$H$919,7,0) -> 15060.463 | F32: =VLOOKUP(B32,VL!$B$5:$G$915,6,0) -> 231300.9 | G32: =TB!I55 -> 25437.92 | H32: =TB!I49 -> 11435.8 | I32: =D32+E32+F32+G32 -> 397049.28 | J32: =I32*20% -> 79409.857 | K32: =ROUND((I32+J32),-2) -> 476500 | L32: 649250 | M32: =K32-L32 -> -172750 | N32: 463200 | O32: =K32-N32 -> 13300
A33: 3 | B33: 2TT3 | C33: Dầu mỡ | D33: =VLOOKUP(B33,LDKT!$B$5:$G$214,6,0) -> 206557.5 | E33: =VLOOKUP(B33,Dcu!$B$6:$H$919,7,0) -> 17182.899 | F33: =VLOOKUP(B33,VL!$B$5:$G$915,6,0) -> 279858.24 | G33: =TB!I64 -> 50085.5 | H33: =TB!I56 -> 36153.48 | I33: =D33+E33+F33+G33 -> 553684.14 | J33: =I33*20% -> 110736.83 | K33: =ROUND((I33+J33),-2) -> 664400 | L33: 649250 | M33: =K33-L33 -> 15150 | N33: 842300 | O33: =K33-N33 -> -177900
A34: 4 | B34: 2TT4 | C34: Cyanua (CN-) | D34: =VLOOKUP(B34,LDKT!$B$5:$G$214,6,0) -> 206557.5 | E34: =VLOOKUP(B34,Dcu!$B$6:$H$919,7,0) -> 31941.233 | F34: =VLOOKUP(B34,VL!$B$5:$G$915,6,0) -> 183866.76 | G34: =TB!I73 -> 15200.26 | H34: =TB!I65 -> 37475.8 | I34: =D34+E34+F34+G34 -> 437565.75 | J34: =I34*20% -> 87513.151 | K34: =ROUND((I34+J34),-2) -> 525100 | L34: 643210 | M34: =K34-L34 -> -118110 | N34: 484900 | O34: =K34-N34 -> 40200
A35: 5 | B35: 2TT5a | C35: Tổng N | D35: =VLOOKUP(B35,LDKT!$B$5:$G$214,6,0) -> 154918.12 | E35: =VLOOKUP(B35,Dcu!$B$6:$H$919,7,0) -> 51963.771 | F35: =VLOOKUP(B35,VL!$B$5:$G$915,6,0) -> 68002.2 | G35: =TB!I82 -> 19280.62 | H35: =TB!I74 -> 70369.8 | I35: =D35+E35+F35+G35 -> 294164.72 | J35: =I35*20% -> 58832.943 | K35: =ROUND((I35+J35),-2) -> 353000 | N35: 350800 | O35: =K35-N35 -> 2200
A36: 6 | B36: 2TT5b | C36: Tổng P | D36: =VLOOKUP(B36,LDKT!$B$5:$G$214,6,0) -> 154918.12 | E36: =VLOOKUP(B36,Dcu!$B$6:$H$919,7,0) -> 51620.331 | F36: =VLOOKUP(B36,VL!$B$5:$G$915,6,0) -> 57294 | G36: =TB!I82 -> 19280.62 | H36: =TB!I74 -> 70369.8 | I36: =D36+E36+F36+G36 -> 283113.08 | J36: =I36*20% -> 56622.615 | K36: =ROUND((I36+J36),-2) -> 339700 | N36: 302200 | O36: =K36-N36 -> 37500
A37: 7 | B37: 2TT5c | C37: Phenol | D37: =VLOOKUP(B37,LDKT!$B$5:$G$214,6,0) -> 208750 | E37: =VLOOKUP(B37,Dcu!$B$6:$H$919,7,0) -> 100801.26 | F37: =VLOOKUP(B37,VL!$B$5:$G$915,6,0) -> 365897.52 | G37: =TB!I93 -> 31705.5 | H37: =TB!I84 -> 42608.8 | I37: =D37+E37+F37+G37 -> 707154.28 | J37: =I37*20% -> 141430.86 | K37: =ROUND((I37+J37),-2) -> 848600 | N37: 700000 | O37: =K37-N37 -> 148600
A38: 8 | B38: 2TT5d1 | C38: Kim Loại nặng (Pb) | D38: =VLOOKUP(B38,LDKT!$B$5:$G$214,6,0) -> 167000 | E38: =VLOOKUP(B38,Dcu!$B$6:$H$919,7,0) -> 135641.78 | F38: =VLOOKUP(B38,VL!$B$5:$G$915,6,0) -> 95796 | G38: =TB!I103 -> 55323.8 | H38: =TB!I94 -> 128521 | I38: =D38+E38+F38+G38 -> 453761.58 | J38: =I38*20% -> 90752.316 | K38: =ROUND((I38+J38),-2) -> 544500 | N38: 529500 | O38: =K38-N38 -> 15000
A39: 9 | B39: 2TT5d2 | C39: Kim loại nặng (Cd) | D39: =VLOOKUP(B39,LDKT!$B$5:$G$214,6,0) -> 167000 | E39: =VLOOKUP(B39,Dcu!$B$6:$H$919,7,0) -> 135641.78 | F39: =VLOOKUP(B39,VL!$B$5:$G$915,6,0) -> 95796 | G39: =G38 -> 55323.8 | H39: =TB!I95 -> 11592 | I39: =D39+E39+F39+G39 -> 453761.58 | J39: =I39*20% -> 90752.316 | K39: =ROUND((I39+J39),-2) -> 544500 | N39: 529500 | O39: =K39-N39 -> 15000
A40: 10 | B40: 2TT5đ1 | C40: Kim loại nặng ( As) | D40: =VLOOKUP(B40,LDKT!$B$5:$G$214,6,0) -> 208750 | E40: =VLOOKUP(B40,Dcu!$B$6:$H$919,7,0) -> 188094.13 | F40: =VLOOKUP(B40,VL!$B$5:$G$915,6,0) -> 97794 | G40: =TB!I115 -> 71976.08 | H40: =TB!I96 -> 2483.2 | I40: =D40+E40+F40+G40 -> 566614.21 | J40: =I40*20% -> 113322.84 | K40: =ROUND((I40+J40),-2) -> 679900 | N40: 591600 | O40: =K40-N40 -> 88300
A41: 11 | B41: 2TT5đ2 | C41: Kim loại nặng(Hg) | D41: =VLOOKUP(B41,LDKT!$B$5:$G$214,6,0) -> 208750 | E41: =VLOOKUP(B41,Dcu!$B$6:$H$919,7,0) -> 188094.13 | F41: =VLOOKUP(B41,VL!$B$5:$G$915,6,0) -> 97794 | G41: =G40 -> 71976.08 | H41: =TB!I97 -> 25379.2 | I41: =D41+E41+F41+G41 -> 566614.21 | J41: =I41*20% -> 113322.84 | K41: =ROUND((I41+J41),-2) -> 679900 | N41: 602600 | O41: =K41-N41 -> 77300
A42: 12 | B42: 2TT5e1 | C42: Kim loại (Zn) | D42: =VLOOKUP(B42,LDKT!$B$5:$G$214,6,0) -> 165246 | E42: =VLOOKUP(B42,Dcu!$B$6:$H$919,7,0) -> 60285.424 | F42: =VLOOKUP(B42,VL!$B$5:$G$915,6,0) -> 81432 | G42: =TB!I126 -> 49368.68 | H42: =TB!I98 -> 2268 | I42: =D42+E42+F42+G42 -> 356332.1 | J42: =I42*20% -> 71266.421 | K42: =ROUND((I42+J42),-2) -> 427600 | N42: 426500 | O42: =K42-N42 -> 1100
A43: 13 | B43: 2TT5e2 | C43: Kim loại (Cu) | D43: =VLOOKUP(B43,LDKT!$B$5:$G$214,6,0) -> 165246 | E43: =VLOOKUP(B43,Dcu!$B$6:$H$919,7,0) -> 60285.424 | F43: =VLOOKUP(B43,VL!$B$5:$G$915,6,0) -> 81432 | G43: =G42 -> 49368.68 | H43: =TB!I99 -> 2400 | I43: =D43+E43+F43+G43 -> 356332.1 | J43: =I43*20% -> 71266.421 | K43: =ROUND((I43+J43),-2) -> 427600 | N43: 426500 | O43: =K43-N43 -> 1100
A44: 14 | B44: 2TT5e3 | C44: Kim loại (Cr) | D44: =VLOOKUP(B44,LDKT!$B$5:$G$214,6,0) -> 165246 | E44: =VLOOKUP(B44,Dcu!$B$6:$H$919,7,0) -> 60285.424 | F44: =VLOOKUP(B44,VL!$B$5:$G$915,6,0) -> 81432 | G44: =G42 -> 49368.68 | H44: =TB!I100 -> 63480 | I44: =D44+E44+F44+G44 -> 356332.1 | J44: =I44*20% -> 71266.421 | K44: =ROUND((I44+J44),-2) -> 427600 | N44: 426500 | O44: =K44-N44 -> 1100
A45: 15 | B45: 2TT5e4 | C45: Kim loại (Mn) | D45: =VLOOKUP(B45,LDKT!$B$5:$G$214,6,0) -> 165246 | E45: =VLOOKUP(B45,Dcu!$B$6:$H$919,7,0) -> 60285.424 | F45: =VLOOKUP(B45,VL!$B$5:$G$915,6,0) -> 81432 | G45: =G42 -> 49368.68 | H45: =TB!I101 -> 20664 | I45: =D45+E45+F45+G45 -> 356332.1 | J45: =I45*20% -> 71266.421 | K45: =ROUND((I45+J45),-2) -> 427600 | N45: 426500 | O45: =K45-N45 -> 1100
A46: 16 | B46: 2TT5e5 | C46: Kim loại (Ni) | D46: =VLOOKUP(B46,LDKT!$B$5:$G$214,6,0) -> 165246 | E46: =VLOOKUP(B46,Dcu!$B$6:$H$919,7,0) -> 60285.424 | F46: =VLOOKUP(B46,VL!$B$5:$G$915,6,0) -> 81432 | G46: =G43 -> 49368.68 | H46: =TB!I102 -> 254.6 | I46: =D46+E46+F46+G46 -> 356332.1 | J46: =I46*20% -> 71266.421 | K46: =ROUND((I46+J46),-2) -> 427600 | N46: 426500 | O46: =K46-N46 -> 1100
A47: 17 | B47: 2TT5f | C47: Tổng K2O | D47: =VLOOKUP(B47,LDKT!$B$5:$G$214,6,0) -> 92182.5 | E47: =VLOOKUP(B47,Dcu!$B$6:$H$919,7,0) -> 32213.694 | F47: =VLOOKUP(B47,VL!$B$5:$G$915,6,0) -> 78451.2 | G47: =TB!I138 -> 23305.84 | H47: =TB!I131 -> 91549.8 | I47: =D47+E47+F47+G47 -> 226153.23 | J47: =I47*20% -> 45230.647 | K47: =ROUND((I47+J47),-2) -> 271400 | N47: 297600 | O47: =K47-N47 -> -26200
A48: 18 | B48: 2TT6a | C48: Thuốc BVTV nhóm Clo hữu cơ | D48: =VLOOKUP(B48,LDKT!$B$5:$G$214,6,0) -> 250500 | E48: =VLOOKUP(B48,Dcu!$B$6:$H$919,7,0) -> 230197.58 | F48: =VLOOKUP(B48,VL!$B$5:$G$915,6,0) -> 1129356 | G48: =TB!I150 -> 166302.24 | H48: =TB!I139 -> 162301.4 | I48: =D48+E48+F48+G48 -> 1776355.8 | J48: =I48*20% -> 355271.16 | K48: =ROUND((I48+J48),-2) -> 2131600 | N48: 2362000 | O48: =K48-N48 -> -230400
A49: 19 | B49: 2TT6b | C49: Thuốc BVTV nhóm phốt pho hữu cơ | D49: =VLOOKUP(B49,LDKT!$B$5:$G$214,6,0) -> 250500 | E49: =VLOOKUP(B49,Dcu!$B$6:$H$919,7,0) -> 230197.58 | F49: =VLOOKUP(B49,VL!$B$5:$G$915,6,0) -> 1129356 | G49: =G48 -> 166302.24 | H49: =TB!I139 -> 162301.4 | I49: =D49+E49+F49+G49 -> 1776355.8 | J49: =I49*20% -> 355271.16 | K49: =ROUND((I49+J49),-2) -> 2131600 | N49: 2570700 | O49: =K49-N49 -> -439100
...
